[2021-10-27 18:18:46,666] {taskinstance.py:826} INFO - Dependencies all met for <TaskInstance: scrapper.spider_star 2021-10-27T18:18:43.061732+00:00 [queued]>
[2021-10-27 18:18:46,693] {taskinstance.py:826} INFO - Dependencies all met for <TaskInstance: scrapper.spider_star 2021-10-27T18:18:43.061732+00:00 [queued]>
[2021-10-27 18:18:46,695] {taskinstance.py:1017} INFO - 
--------------------------------------------------------------------------------
[2021-10-27 18:18:46,696] {taskinstance.py:1018} INFO - Starting attempt 1 of 2
[2021-10-27 18:18:46,697] {taskinstance.py:1019} INFO - 
--------------------------------------------------------------------------------
[2021-10-27 18:18:46,774] {taskinstance.py:1038} INFO - Executing <Task(BashOperator): spider_star> on 2021-10-27T18:18:43.061732+00:00
[2021-10-27 18:18:46,781] {standard_task_runner.py:51} INFO - Started process 180 to run task
[2021-10-27 18:18:46,794] {standard_task_runner.py:75} INFO - Running: ['airflow', 'tasks', 'run', 'scrapper', 'spider_star', '2021-10-27T18:18:43.061732+00:00', '--job-id', '3', '--pool', 'default_pool', '--raw', '--subdir', 'DAGS_FOLDER/my_dag.py', '--cfg-path', '/tmp/tmp5c8d4o39']
[2021-10-27 18:18:46,796] {standard_task_runner.py:76} INFO - Job 3: Subtask spider_star
[2021-10-27 18:18:46,943] {logging_mixin.py:103} INFO - Running <TaskInstance: scrapper.spider_star 2021-10-27T18:18:43.061732+00:00 [running]> on host 124db322365f
[2021-10-27 18:18:47,054] {taskinstance.py:1230} INFO - Exporting the following env vars:
AIRFLOW_CTX_DAG_EMAIL=octadelsueldo@gmail.com
AIRFLOW_CTX_DAG_OWNER=Octavio
AIRFLOW_CTX_DAG_ID=scrapper
AIRFLOW_CTX_TASK_ID=spider_star
AIRFLOW_CTX_EXECUTION_DATE=2021-10-27T18:18:43.061732+00:00
AIRFLOW_CTX_DAG_RUN_ID=manual__2021-10-27T18:18:43.061732+00:00
[2021-10-27 18:18:47,056] {bash.py:135} INFO - Tmp dir root location: 
 /tmp
[2021-10-27 18:18:47,058] {bash.py:158} INFO - Running command: cd /opt/airflow/dags/web_scrap;scrapy crawl quotes
[2021-10-27 18:18:47,072] {bash.py:169} INFO - Output:
[2021-10-27 18:18:47,086] {bash.py:173} INFO - bash: scrapy: command not found
[2021-10-27 18:18:47,088] {bash.py:177} INFO - Command exited with return code 127
[2021-10-27 18:18:47,109] {taskinstance.py:1396} ERROR - Bash command failed. The command returned a non-zero exit code.
Traceback (most recent call last):
  File "/home/airflow/.local/lib/python3.8/site-packages/airflow/models/taskinstance.py", line 1086, in _run_raw_task
    self._prepare_and_execute_task_with_callbacks(context, task)
  File "/home/airflow/.local/lib/python3.8/site-packages/airflow/models/taskinstance.py", line 1260, in _prepare_and_execute_task_with_callbacks
    result = self._execute_task(context, task_copy)
  File "/home/airflow/.local/lib/python3.8/site-packages/airflow/models/taskinstance.py", line 1300, in _execute_task
    result = task_copy.execute(context=context)
  File "/home/airflow/.local/lib/python3.8/site-packages/airflow/operators/bash.py", line 180, in execute
    raise AirflowException('Bash command failed. The command returned a non-zero exit code.')
airflow.exceptions.AirflowException: Bash command failed. The command returned a non-zero exit code.
[2021-10-27 18:18:47,112] {taskinstance.py:1433} INFO - Marking task as UP_FOR_RETRY. dag_id=scrapper, task_id=spider_star, execution_date=20211027T181843, start_date=20211027T181846, end_date=20211027T181847
[2021-10-27 18:18:47,137] {configuration.py:344} WARNING - section/key [smtp/smtp_user] not found in config
[2021-10-27 18:18:47,138] {email.py:184} INFO - Email alerting: attempt 1
[2021-10-27 18:18:47,141] {configuration.py:344} WARNING - section/key [smtp/smtp_user] not found in config
[2021-10-27 18:18:47,142] {email.py:184} INFO - Email alerting: attempt 1
[2021-10-27 18:18:47,143] {taskinstance.py:1446} ERROR - Failed to send email to: ['octadelsueldo@gmail.com']
[2021-10-27 18:18:47,144] {taskinstance.py:1447} ERROR - [Errno 99] Cannot assign requested address
Traceback (most recent call last):
  File "/home/airflow/.local/lib/python3.8/site-packages/airflow/models/taskinstance.py", line 1086, in _run_raw_task
    self._prepare_and_execute_task_with_callbacks(context, task)
  File "/home/airflow/.local/lib/python3.8/site-packages/airflow/models/taskinstance.py", line 1260, in _prepare_and_execute_task_with_callbacks
    result = self._execute_task(context, task_copy)
  File "/home/airflow/.local/lib/python3.8/site-packages/airflow/models/taskinstance.py", line 1300, in _execute_task
    result = task_copy.execute(context=context)
  File "/home/airflow/.local/lib/python3.8/site-packages/airflow/operators/bash.py", line 180, in execute
    raise AirflowException('Bash command failed. The command returned a non-zero exit code.')
airflow.exceptions.AirflowException: Bash command failed. The command returned a non-zero exit code.

During handling of the above exception, another exception occurred:

Traceback (most recent call last):
  File "/home/airflow/.local/lib/python3.8/site-packages/airflow/models/taskinstance.py", line 1786, in email_alert
    send_email(self.task.email, subject, html_content)
  File "/home/airflow/.local/lib/python3.8/site-packages/airflow/utils/email.py", line 52, in send_email
    return backend(
  File "/home/airflow/.local/lib/python3.8/site-packages/airflow/utils/email.py", line 97, in send_email_smtp
    send_mime_email(e_from=smtp_mail_from, e_to=recipients, mime_msg=msg, dryrun=dryrun)
  File "/home/airflow/.local/lib/python3.8/site-packages/airflow/utils/email.py", line 186, in send_mime_email
    conn = _get_smtp_connection(smtp_host, smtp_port, smtp_timeout, smtp_ssl)
  File "/home/airflow/.local/lib/python3.8/site-packages/airflow/utils/email.py", line 220, in _get_smtp_connection
    else smtplib.SMTP(host=host, port=port, timeout=timeout)
  File "/usr/local/lib/python3.8/smtplib.py", line 253, in __init__
    (code, msg) = self.connect(host, port)
  File "/usr/local/lib/python3.8/smtplib.py", line 339, in connect
    self.sock = self._get_socket(host, port, self.timeout)
  File "/usr/local/lib/python3.8/smtplib.py", line 308, in _get_socket
    return socket.create_connection((host, port), timeout,
  File "/usr/local/lib/python3.8/socket.py", line 808, in create_connection
    raise err
  File "/usr/local/lib/python3.8/socket.py", line 796, in create_connection
    sock.connect(sa)
OSError: [Errno 99] Cannot assign requested address

During handling of the above exception, another exception occurred:

Traceback (most recent call last):
  File "/home/airflow/.local/lib/python3.8/site-packages/airflow/models/taskinstance.py", line 1444, in handle_failure
    self.email_alert(error)
  File "/home/airflow/.local/lib/python3.8/site-packages/airflow/models/taskinstance.py", line 1788, in email_alert
    send_email(self.task.email, subject, html_content_err)
  File "/home/airflow/.local/lib/python3.8/site-packages/airflow/utils/email.py", line 52, in send_email
    return backend(
  File "/home/airflow/.local/lib/python3.8/site-packages/airflow/utils/email.py", line 97, in send_email_smtp
    send_mime_email(e_from=smtp_mail_from, e_to=recipients, mime_msg=msg, dryrun=dryrun)
  File "/home/airflow/.local/lib/python3.8/site-packages/airflow/utils/email.py", line 186, in send_mime_email
    conn = _get_smtp_connection(smtp_host, smtp_port, smtp_timeout, smtp_ssl)
  File "/home/airflow/.local/lib/python3.8/site-packages/airflow/utils/email.py", line 220, in _get_smtp_connection
    else smtplib.SMTP(host=host, port=port, timeout=timeout)
  File "/usr/local/lib/python3.8/smtplib.py", line 253, in __init__
    (code, msg) = self.connect(host, port)
  File "/usr/local/lib/python3.8/smtplib.py", line 339, in connect
    self.sock = self._get_socket(host, port, self.timeout)
  File "/usr/local/lib/python3.8/smtplib.py", line 308, in _get_socket
    return socket.create_connection((host, port), timeout,
  File "/usr/local/lib/python3.8/socket.py", line 808, in create_connection
    raise err
  File "/usr/local/lib/python3.8/socket.py", line 796, in create_connection
    sock.connect(sa)
OSError: [Errno 99] Cannot assign requested address
[2021-10-27 18:18:47,255] {local_task_job.py:118} INFO - Task exited with return code 1
