[2021-10-26 00:00:01,991] {taskinstance.py:1035} INFO - Dependencies all met for <TaskInstance: scrapper.spider_star scheduled__2021-10-25T00:00:00+00:00 [queued]>
[2021-10-26 00:00:02,127] {taskinstance.py:1035} INFO - Dependencies all met for <TaskInstance: scrapper.spider_star scheduled__2021-10-25T00:00:00+00:00 [queued]>
[2021-10-26 00:00:02,130] {taskinstance.py:1241} INFO - 
--------------------------------------------------------------------------------
[2021-10-26 00:00:02,132] {taskinstance.py:1242} INFO - Starting attempt 1 of 2
[2021-10-26 00:00:02,136] {taskinstance.py:1243} INFO - 
--------------------------------------------------------------------------------
[2021-10-26 00:00:02,219] {taskinstance.py:1262} INFO - Executing <Task(BashOperator): spider_star> on 2021-10-25 00:00:00+00:00
[2021-10-26 00:00:02,245] {standard_task_runner.py:52} INFO - Started process 6765 to run task
[2021-10-26 00:00:02,275] {standard_task_runner.py:76} INFO - Running: ['***', 'tasks', 'run', 'scrapper', 'spider_star', 'scheduled__2021-10-25T00:00:00+00:00', '--job-id', '15', '--raw', '--subdir', 'DAGS_FOLDER/my_dag.py', '--cfg-path', '/tmp/tmpzyx28eey', '--error-file', '/tmp/tmpwenrqt_z']
[2021-10-26 00:00:02,286] {standard_task_runner.py:77} INFO - Job 15: Subtask spider_star
[2021-10-26 00:00:02,407] {logging_mixin.py:109} INFO - Running <TaskInstance: scrapper.spider_star scheduled__2021-10-25T00:00:00+00:00 [running]> on host ebc91b274482
[2021-10-26 00:00:02,686] {taskinstance.py:1414} INFO - Exporting the following env vars:
AIRFLOW_CTX_DAG_EMAIL=octadelsueldo@gmail.com
AIRFLOW_CTX_DAG_OWNER=Octavio
AIRFLOW_CTX_DAG_ID=scrapper
AIRFLOW_CTX_TASK_ID=spider_star
AIRFLOW_CTX_EXECUTION_DATE=2021-10-25T00:00:00+00:00
AIRFLOW_CTX_DAG_RUN_ID=scheduled__2021-10-25T00:00:00+00:00
[2021-10-26 00:00:02,693] {subprocess.py:62} INFO - Tmp dir root location: 
 /tmp
[2021-10-26 00:00:02,699] {subprocess.py:74} INFO - Running command: ['bash', '-c', './opt/***/dags/script/run_spider.sh ']
[2021-10-26 00:00:02,757] {subprocess.py:85} INFO - Output:
[2021-10-26 00:00:02,770] {subprocess.py:89} INFO - bash: ./opt/***/dags/script/run_spider.sh: No such file or directory
[2021-10-26 00:00:02,778] {subprocess.py:93} INFO - Command exited with return code 127
[2021-10-26 00:00:02,790] {taskinstance.py:1686} ERROR - Task failed with exception
Traceback (most recent call last):
  File "/home/airflow/.local/lib/python3.6/site-packages/airflow/models/taskinstance.py", line 1324, in _run_raw_task
    self._execute_task_with_callbacks(context)
  File "/home/airflow/.local/lib/python3.6/site-packages/airflow/models/taskinstance.py", line 1443, in _execute_task_with_callbacks
    result = self._execute_task(context, self.task)
  File "/home/airflow/.local/lib/python3.6/site-packages/airflow/models/taskinstance.py", line 1499, in _execute_task
    result = execute_callable(context=context)
  File "/home/airflow/.local/lib/python3.6/site-packages/airflow/operators/bash.py", line 188, in execute
    f'Bash command failed. The command returned a non-zero exit code {result.exit_code}.'
airflow.exceptions.AirflowException: Bash command failed. The command returned a non-zero exit code 127.
[2021-10-26 00:00:02,852] {taskinstance.py:1280} INFO - Marking task as UP_FOR_RETRY. dag_id=scrapper, task_id=spider_star, execution_date=20211025T000000, start_date=20211026T000002, end_date=20211026T000002
[2021-10-26 00:00:02,951] {warnings.py:99} WARNING - /home/***/.local/lib/python3.6/site-packages/***/utils/email.py:102: PendingDeprecationWarning: Fetching SMTP credentials from configuration variables will be deprecated in a future release. Please set credentials using a connection instead.
  send_mime_email(e_from=smtp_mail_from, e_to=recipients, mime_msg=msg, conn_id=conn_id, dryrun=dryrun)

[2021-10-26 00:00:02,954] {configuration.py:381} WARNING - section/key [smtp/smtp_user] not found in config
[2021-10-26 00:00:02,956] {email.py:208} INFO - Email alerting: attempt 1
[2021-10-26 00:00:03,006] {configuration.py:381} WARNING - section/key [smtp/smtp_user] not found in config
[2021-10-26 00:00:03,009] {email.py:208} INFO - Email alerting: attempt 1
[2021-10-26 00:00:03,012] {taskinstance.py:1739} ERROR - Failed to send email to: ['octadelsueldo@gmail.com']
Traceback (most recent call last):
  File "/home/airflow/.local/lib/python3.6/site-packages/airflow/models/taskinstance.py", line 1324, in _run_raw_task
    self._execute_task_with_callbacks(context)
  File "/home/airflow/.local/lib/python3.6/site-packages/airflow/models/taskinstance.py", line 1443, in _execute_task_with_callbacks
    result = self._execute_task(context, self.task)
  File "/home/airflow/.local/lib/python3.6/site-packages/airflow/models/taskinstance.py", line 1499, in _execute_task
    result = execute_callable(context=context)
  File "/home/airflow/.local/lib/python3.6/site-packages/airflow/operators/bash.py", line 188, in execute
    f'Bash command failed. The command returned a non-zero exit code {result.exit_code}.'
airflow.exceptions.AirflowException: Bash command failed. The command returned a non-zero exit code 127.

During handling of the above exception, another exception occurred:

Traceback (most recent call last):
  File "/home/airflow/.local/lib/python3.6/site-packages/airflow/models/taskinstance.py", line 2189, in email_alert
    send_email(self.task.email, subject, html_content)
  File "/home/airflow/.local/lib/python3.6/site-packages/airflow/utils/email.py", line 66, in send_email
    **kwargs,
  File "/home/airflow/.local/lib/python3.6/site-packages/airflow/utils/email.py", line 102, in send_email_smtp
    send_mime_email(e_from=smtp_mail_from, e_to=recipients, mime_msg=msg, conn_id=conn_id, dryrun=dryrun)
  File "/home/airflow/.local/lib/python3.6/site-packages/airflow/utils/email.py", line 210, in send_mime_email
    conn = _get_smtp_connection(smtp_host, smtp_port, smtp_timeout, smtp_ssl)
  File "/home/airflow/.local/lib/python3.6/site-packages/airflow/utils/email.py", line 244, in _get_smtp_connection
    else smtplib.SMTP(host=host, port=port, timeout=timeout)
  File "/usr/local/lib/python3.6/smtplib.py", line 251, in __init__
    (code, msg) = self.connect(host, port)
  File "/usr/local/lib/python3.6/smtplib.py", line 336, in connect
    self.sock = self._get_socket(host, port, self.timeout)
  File "/usr/local/lib/python3.6/smtplib.py", line 307, in _get_socket
    self.source_address)
  File "/usr/local/lib/python3.6/socket.py", line 724, in create_connection
    raise err
  File "/usr/local/lib/python3.6/socket.py", line 713, in create_connection
    sock.connect(sa)
OSError: [Errno 99] Cannot assign requested address

During handling of the above exception, another exception occurred:

Traceback (most recent call last):
  File "/home/airflow/.local/lib/python3.6/site-packages/airflow/models/taskinstance.py", line 1737, in handle_failure
    self.email_alert(error)
  File "/home/airflow/.local/lib/python3.6/site-packages/airflow/models/taskinstance.py", line 2191, in email_alert
    send_email(self.task.email, subject, html_content_err)
  File "/home/airflow/.local/lib/python3.6/site-packages/airflow/utils/email.py", line 66, in send_email
    **kwargs,
  File "/home/airflow/.local/lib/python3.6/site-packages/airflow/utils/email.py", line 102, in send_email_smtp
    send_mime_email(e_from=smtp_mail_from, e_to=recipients, mime_msg=msg, conn_id=conn_id, dryrun=dryrun)
  File "/home/airflow/.local/lib/python3.6/site-packages/airflow/utils/email.py", line 210, in send_mime_email
    conn = _get_smtp_connection(smtp_host, smtp_port, smtp_timeout, smtp_ssl)
  File "/home/airflow/.local/lib/python3.6/site-packages/airflow/utils/email.py", line 244, in _get_smtp_connection
    else smtplib.SMTP(host=host, port=port, timeout=timeout)
  File "/usr/local/lib/python3.6/smtplib.py", line 251, in __init__
    (code, msg) = self.connect(host, port)
  File "/usr/local/lib/python3.6/smtplib.py", line 336, in connect
    self.sock = self._get_socket(host, port, self.timeout)
  File "/usr/local/lib/python3.6/smtplib.py", line 307, in _get_socket
    self.source_address)
  File "/usr/local/lib/python3.6/socket.py", line 724, in create_connection
    raise err
  File "/usr/local/lib/python3.6/socket.py", line 713, in create_connection
    sock.connect(sa)
OSError: [Errno 99] Cannot assign requested address
[2021-10-26 00:00:03,085] {standard_task_runner.py:91} ERROR - Failed to execute job 15 for task spider_star
Traceback (most recent call last):
  File "/home/airflow/.local/lib/python3.6/site-packages/airflow/task/task_runner/standard_task_runner.py", line 85, in _start_by_fork
    args.func(args, dag=self.dag)
  File "/home/airflow/.local/lib/python3.6/site-packages/airflow/cli/cli_parser.py", line 48, in command
    return func(*args, **kwargs)
  File "/home/airflow/.local/lib/python3.6/site-packages/airflow/utils/cli.py", line 92, in wrapper
    return f(*args, **kwargs)
  File "/home/airflow/.local/lib/python3.6/site-packages/airflow/cli/commands/task_command.py", line 292, in task_run
    _run_task_by_selected_method(args, dag, ti)
  File "/home/airflow/.local/lib/python3.6/site-packages/airflow/cli/commands/task_command.py", line 107, in _run_task_by_selected_method
    _run_raw_task(args, ti)
  File "/home/airflow/.local/lib/python3.6/site-packages/airflow/cli/commands/task_command.py", line 184, in _run_raw_task
    error_file=args.error_file,
  File "/home/airflow/.local/lib/python3.6/site-packages/airflow/utils/session.py", line 70, in wrapper
    return func(*args, session=session, **kwargs)
  File "/home/airflow/.local/lib/python3.6/site-packages/airflow/models/taskinstance.py", line 1324, in _run_raw_task
    self._execute_task_with_callbacks(context)
  File "/home/airflow/.local/lib/python3.6/site-packages/airflow/models/taskinstance.py", line 1443, in _execute_task_with_callbacks
    result = self._execute_task(context, self.task)
  File "/home/airflow/.local/lib/python3.6/site-packages/airflow/models/taskinstance.py", line 1499, in _execute_task
    result = execute_callable(context=context)
  File "/home/airflow/.local/lib/python3.6/site-packages/airflow/operators/bash.py", line 188, in execute
    f'Bash command failed. The command returned a non-zero exit code {result.exit_code}.'
airflow.exceptions.AirflowException: Bash command failed. The command returned a non-zero exit code 127.
[2021-10-26 00:00:03,164] {local_task_job.py:154} INFO - Task exited with return code 1
[2021-10-26 00:00:03,332] {local_task_job.py:264} INFO - 0 downstream tasks scheduled from follow-on schedule check
[2021-10-26 17:23:43,341] {taskinstance.py:1035} INFO - Dependencies all met for <TaskInstance: scrapper.spider_star manual__2021-10-26T17:23:39.166007+00:00 [queued]>
[2021-10-26 17:23:43,389] {taskinstance.py:1035} INFO - Dependencies all met for <TaskInstance: scrapper.spider_star manual__2021-10-26T17:23:39.166007+00:00 [queued]>
[2021-10-26 17:23:43,393] {taskinstance.py:1241} INFO - 
--------------------------------------------------------------------------------
[2021-10-26 17:23:43,395] {taskinstance.py:1242} INFO - Starting attempt 1 of 2
[2021-10-26 17:23:43,396] {taskinstance.py:1243} INFO - 
--------------------------------------------------------------------------------
[2021-10-26 17:23:43,434] {taskinstance.py:1262} INFO - Executing <Task(BashOperator): spider_star> on 2021-10-26 17:23:39.166007+00:00
[2021-10-26 17:23:43,465] {standard_task_runner.py:76} INFO - Running: ['***', 'tasks', 'run', 'scrapper', 'spider_star', 'manual__2021-10-26T17:23:39.166007+00:00', '--job-id', '17', '--raw', '--subdir', 'DAGS_FOLDER/my_dag.py', '--cfg-path', '/tmp/tmpqpk6g65i', '--error-file', '/tmp/tmpcitxli7o']
[2021-10-26 17:23:43,474] {standard_task_runner.py:77} INFO - Job 17: Subtask spider_star
[2021-10-26 17:23:43,449] {standard_task_runner.py:52} INFO - Started process 13120 to run task
[2021-10-26 17:23:43,609] {logging_mixin.py:109} INFO - Running <TaskInstance: scrapper.spider_star manual__2021-10-26T17:23:39.166007+00:00 [running]> on host ebc91b274482
[2021-10-26 17:23:43,748] {taskinstance.py:1414} INFO - Exporting the following env vars:
AIRFLOW_CTX_DAG_EMAIL=octadelsueldo@gmail.com
AIRFLOW_CTX_DAG_OWNER=Octavio
AIRFLOW_CTX_DAG_ID=scrapper
AIRFLOW_CTX_TASK_ID=spider_star
AIRFLOW_CTX_EXECUTION_DATE=2021-10-26T17:23:39.166007+00:00
AIRFLOW_CTX_DAG_RUN_ID=manual__2021-10-26T17:23:39.166007+00:00
[2021-10-26 17:23:43,752] {subprocess.py:62} INFO - Tmp dir root location: 
 /tmp
[2021-10-26 17:23:43,754] {subprocess.py:74} INFO - Running command: ['bash', '-c', './opt/***/dags/script/run_spider.sh ']
[2021-10-26 17:23:43,795] {subprocess.py:85} INFO - Output:
[2021-10-26 17:23:43,801] {subprocess.py:89} INFO - bash: ./opt/***/dags/script/run_spider.sh: No such file or directory
[2021-10-26 17:23:43,805] {subprocess.py:93} INFO - Command exited with return code 127
[2021-10-26 17:23:43,815] {taskinstance.py:1686} ERROR - Task failed with exception
Traceback (most recent call last):
  File "/home/airflow/.local/lib/python3.6/site-packages/airflow/models/taskinstance.py", line 1324, in _run_raw_task
    self._execute_task_with_callbacks(context)
  File "/home/airflow/.local/lib/python3.6/site-packages/airflow/models/taskinstance.py", line 1443, in _execute_task_with_callbacks
    result = self._execute_task(context, self.task)
  File "/home/airflow/.local/lib/python3.6/site-packages/airflow/models/taskinstance.py", line 1499, in _execute_task
    result = execute_callable(context=context)
  File "/home/airflow/.local/lib/python3.6/site-packages/airflow/operators/bash.py", line 188, in execute
    f'Bash command failed. The command returned a non-zero exit code {result.exit_code}.'
airflow.exceptions.AirflowException: Bash command failed. The command returned a non-zero exit code 127.
[2021-10-26 17:23:43,839] {taskinstance.py:1280} INFO - Marking task as UP_FOR_RETRY. dag_id=scrapper, task_id=spider_star, execution_date=20211026T172339, start_date=20211026T172343, end_date=20211026T172343
[2021-10-26 17:23:43,888] {warnings.py:99} WARNING - /home/***/.local/lib/python3.6/site-packages/***/utils/email.py:102: PendingDeprecationWarning: Fetching SMTP credentials from configuration variables will be deprecated in a future release. Please set credentials using a connection instead.
  send_mime_email(e_from=smtp_mail_from, e_to=recipients, mime_msg=msg, conn_id=conn_id, dryrun=dryrun)

[2021-10-26 17:23:43,891] {configuration.py:381} WARNING - section/key [smtp/smtp_user] not found in config
[2021-10-26 17:23:43,892] {email.py:208} INFO - Email alerting: attempt 1
[2021-10-26 17:23:43,907] {configuration.py:381} WARNING - section/key [smtp/smtp_user] not found in config
[2021-10-26 17:23:43,917] {email.py:208} INFO - Email alerting: attempt 1
[2021-10-26 17:23:43,921] {taskinstance.py:1739} ERROR - Failed to send email to: ['octadelsueldo@gmail.com']
Traceback (most recent call last):
  File "/home/airflow/.local/lib/python3.6/site-packages/airflow/models/taskinstance.py", line 1324, in _run_raw_task
    self._execute_task_with_callbacks(context)
  File "/home/airflow/.local/lib/python3.6/site-packages/airflow/models/taskinstance.py", line 1443, in _execute_task_with_callbacks
    result = self._execute_task(context, self.task)
  File "/home/airflow/.local/lib/python3.6/site-packages/airflow/models/taskinstance.py", line 1499, in _execute_task
    result = execute_callable(context=context)
  File "/home/airflow/.local/lib/python3.6/site-packages/airflow/operators/bash.py", line 188, in execute
    f'Bash command failed. The command returned a non-zero exit code {result.exit_code}.'
airflow.exceptions.AirflowException: Bash command failed. The command returned a non-zero exit code 127.

During handling of the above exception, another exception occurred:

Traceback (most recent call last):
  File "/home/airflow/.local/lib/python3.6/site-packages/airflow/models/taskinstance.py", line 2189, in email_alert
    send_email(self.task.email, subject, html_content)
  File "/home/airflow/.local/lib/python3.6/site-packages/airflow/utils/email.py", line 66, in send_email
    **kwargs,
  File "/home/airflow/.local/lib/python3.6/site-packages/airflow/utils/email.py", line 102, in send_email_smtp
    send_mime_email(e_from=smtp_mail_from, e_to=recipients, mime_msg=msg, conn_id=conn_id, dryrun=dryrun)
  File "/home/airflow/.local/lib/python3.6/site-packages/airflow/utils/email.py", line 210, in send_mime_email
    conn = _get_smtp_connection(smtp_host, smtp_port, smtp_timeout, smtp_ssl)
  File "/home/airflow/.local/lib/python3.6/site-packages/airflow/utils/email.py", line 244, in _get_smtp_connection
    else smtplib.SMTP(host=host, port=port, timeout=timeout)
  File "/usr/local/lib/python3.6/smtplib.py", line 251, in __init__
    (code, msg) = self.connect(host, port)
  File "/usr/local/lib/python3.6/smtplib.py", line 336, in connect
    self.sock = self._get_socket(host, port, self.timeout)
  File "/usr/local/lib/python3.6/smtplib.py", line 307, in _get_socket
    self.source_address)
  File "/usr/local/lib/python3.6/socket.py", line 724, in create_connection
    raise err
  File "/usr/local/lib/python3.6/socket.py", line 713, in create_connection
    sock.connect(sa)
OSError: [Errno 99] Cannot assign requested address

During handling of the above exception, another exception occurred:

Traceback (most recent call last):
  File "/home/airflow/.local/lib/python3.6/site-packages/airflow/models/taskinstance.py", line 1737, in handle_failure
    self.email_alert(error)
  File "/home/airflow/.local/lib/python3.6/site-packages/airflow/models/taskinstance.py", line 2191, in email_alert
    send_email(self.task.email, subject, html_content_err)
  File "/home/airflow/.local/lib/python3.6/site-packages/airflow/utils/email.py", line 66, in send_email
    **kwargs,
  File "/home/airflow/.local/lib/python3.6/site-packages/airflow/utils/email.py", line 102, in send_email_smtp
    send_mime_email(e_from=smtp_mail_from, e_to=recipients, mime_msg=msg, conn_id=conn_id, dryrun=dryrun)
  File "/home/airflow/.local/lib/python3.6/site-packages/airflow/utils/email.py", line 210, in send_mime_email
    conn = _get_smtp_connection(smtp_host, smtp_port, smtp_timeout, smtp_ssl)
  File "/home/airflow/.local/lib/python3.6/site-packages/airflow/utils/email.py", line 244, in _get_smtp_connection
    else smtplib.SMTP(host=host, port=port, timeout=timeout)
  File "/usr/local/lib/python3.6/smtplib.py", line 251, in __init__
    (code, msg) = self.connect(host, port)
  File "/usr/local/lib/python3.6/smtplib.py", line 336, in connect
    self.sock = self._get_socket(host, port, self.timeout)
  File "/usr/local/lib/python3.6/smtplib.py", line 307, in _get_socket
    self.source_address)
  File "/usr/local/lib/python3.6/socket.py", line 724, in create_connection
    raise err
  File "/usr/local/lib/python3.6/socket.py", line 713, in create_connection
    sock.connect(sa)
OSError: [Errno 99] Cannot assign requested address
[2021-10-26 17:23:43,976] {standard_task_runner.py:91} ERROR - Failed to execute job 17 for task spider_star
Traceback (most recent call last):
  File "/home/airflow/.local/lib/python3.6/site-packages/airflow/task/task_runner/standard_task_runner.py", line 85, in _start_by_fork
    args.func(args, dag=self.dag)
  File "/home/airflow/.local/lib/python3.6/site-packages/airflow/cli/cli_parser.py", line 48, in command
    return func(*args, **kwargs)
  File "/home/airflow/.local/lib/python3.6/site-packages/airflow/utils/cli.py", line 92, in wrapper
    return f(*args, **kwargs)
  File "/home/airflow/.local/lib/python3.6/site-packages/airflow/cli/commands/task_command.py", line 292, in task_run
    _run_task_by_selected_method(args, dag, ti)
  File "/home/airflow/.local/lib/python3.6/site-packages/airflow/cli/commands/task_command.py", line 107, in _run_task_by_selected_method
    _run_raw_task(args, ti)
  File "/home/airflow/.local/lib/python3.6/site-packages/airflow/cli/commands/task_command.py", line 184, in _run_raw_task
    error_file=args.error_file,
  File "/home/airflow/.local/lib/python3.6/site-packages/airflow/utils/session.py", line 70, in wrapper
    return func(*args, session=session, **kwargs)
  File "/home/airflow/.local/lib/python3.6/site-packages/airflow/models/taskinstance.py", line 1324, in _run_raw_task
    self._execute_task_with_callbacks(context)
  File "/home/airflow/.local/lib/python3.6/site-packages/airflow/models/taskinstance.py", line 1443, in _execute_task_with_callbacks
    result = self._execute_task(context, self.task)
  File "/home/airflow/.local/lib/python3.6/site-packages/airflow/models/taskinstance.py", line 1499, in _execute_task
    result = execute_callable(context=context)
  File "/home/airflow/.local/lib/python3.6/site-packages/airflow/operators/bash.py", line 188, in execute
    f'Bash command failed. The command returned a non-zero exit code {result.exit_code}.'
airflow.exceptions.AirflowException: Bash command failed. The command returned a non-zero exit code 127.
[2021-10-26 17:23:44,097] {local_task_job.py:154} INFO - Task exited with return code 1
[2021-10-26 17:23:44,204] {local_task_job.py:264} INFO - 0 downstream tasks scheduled from follow-on schedule check
[2021-10-26 17:26:36,431] {taskinstance.py:1035} INFO - Dependencies all met for <TaskInstance: scrapper.spider_star manual__2021-10-26T17:26:33.849951+00:00 [queued]>
[2021-10-26 17:26:36,468] {taskinstance.py:1035} INFO - Dependencies all met for <TaskInstance: scrapper.spider_star manual__2021-10-26T17:26:33.849951+00:00 [queued]>
[2021-10-26 17:26:36,470] {taskinstance.py:1241} INFO - 
--------------------------------------------------------------------------------
[2021-10-26 17:26:36,472] {taskinstance.py:1242} INFO - Starting attempt 1 of 2
[2021-10-26 17:26:36,473] {taskinstance.py:1243} INFO - 
--------------------------------------------------------------------------------
[2021-10-26 17:26:36,494] {taskinstance.py:1262} INFO - Executing <Task(BashOperator): spider_star> on 2021-10-26 17:26:33.849951+00:00
[2021-10-26 17:26:36,510] {standard_task_runner.py:76} INFO - Running: ['***', 'tasks', 'run', 'scrapper', 'spider_star', 'manual__2021-10-26T17:26:33.849951+00:00', '--job-id', '18', '--raw', '--subdir', 'DAGS_FOLDER/my_dag.py', '--cfg-path', '/tmp/tmp849l1vvi', '--error-file', '/tmp/tmpqf5fxv8s']
[2021-10-26 17:26:36,511] {standard_task_runner.py:77} INFO - Job 18: Subtask spider_star
[2021-10-26 17:26:36,506] {standard_task_runner.py:52} INFO - Started process 13241 to run task
[2021-10-26 17:26:36,590] {logging_mixin.py:109} INFO - Running <TaskInstance: scrapper.spider_star manual__2021-10-26T17:26:33.849951+00:00 [running]> on host ebc91b274482
[2021-10-26 17:26:36,699] {taskinstance.py:1414} INFO - Exporting the following env vars:
AIRFLOW_CTX_DAG_EMAIL=octadelsueldo@gmail.com
AIRFLOW_CTX_DAG_OWNER=Octavio
AIRFLOW_CTX_DAG_ID=scrapper
AIRFLOW_CTX_TASK_ID=spider_star
AIRFLOW_CTX_EXECUTION_DATE=2021-10-26T17:26:33.849951+00:00
AIRFLOW_CTX_DAG_RUN_ID=manual__2021-10-26T17:26:33.849951+00:00
[2021-10-26 17:26:36,705] {subprocess.py:62} INFO - Tmp dir root location: 
 /tmp
[2021-10-26 17:26:36,710] {subprocess.py:74} INFO - Running command: ['bash', '-c', 'cd ./opt/***/dags/script/run_spider.sh ']
[2021-10-26 17:26:36,744] {subprocess.py:85} INFO - Output:
[2021-10-26 17:26:36,752] {subprocess.py:89} INFO - bash: line 0: cd: ./opt/***/dags/script/run_spider.sh: No such file or directory
[2021-10-26 17:26:36,755] {subprocess.py:93} INFO - Command exited with return code 1
[2021-10-26 17:26:36,788] {taskinstance.py:1686} ERROR - Task failed with exception
Traceback (most recent call last):
  File "/home/airflow/.local/lib/python3.6/site-packages/airflow/models/taskinstance.py", line 1324, in _run_raw_task
    self._execute_task_with_callbacks(context)
  File "/home/airflow/.local/lib/python3.6/site-packages/airflow/models/taskinstance.py", line 1443, in _execute_task_with_callbacks
    result = self._execute_task(context, self.task)
  File "/home/airflow/.local/lib/python3.6/site-packages/airflow/models/taskinstance.py", line 1499, in _execute_task
    result = execute_callable(context=context)
  File "/home/airflow/.local/lib/python3.6/site-packages/airflow/operators/bash.py", line 188, in execute
    f'Bash command failed. The command returned a non-zero exit code {result.exit_code}.'
airflow.exceptions.AirflowException: Bash command failed. The command returned a non-zero exit code 1.
[2021-10-26 17:26:36,833] {taskinstance.py:1280} INFO - Marking task as UP_FOR_RETRY. dag_id=scrapper, task_id=spider_star, execution_date=20211026T172633, start_date=20211026T172636, end_date=20211026T172636
[2021-10-26 17:26:36,879] {warnings.py:99} WARNING - /home/***/.local/lib/python3.6/site-packages/***/utils/email.py:102: PendingDeprecationWarning: Fetching SMTP credentials from configuration variables will be deprecated in a future release. Please set credentials using a connection instead.
  send_mime_email(e_from=smtp_mail_from, e_to=recipients, mime_msg=msg, conn_id=conn_id, dryrun=dryrun)

[2021-10-26 17:26:36,881] {configuration.py:381} WARNING - section/key [smtp/smtp_user] not found in config
[2021-10-26 17:26:36,882] {email.py:208} INFO - Email alerting: attempt 1
[2021-10-26 17:26:36,900] {configuration.py:381} WARNING - section/key [smtp/smtp_user] not found in config
[2021-10-26 17:26:36,902] {email.py:208} INFO - Email alerting: attempt 1
[2021-10-26 17:26:36,904] {taskinstance.py:1739} ERROR - Failed to send email to: ['octadelsueldo@gmail.com']
Traceback (most recent call last):
  File "/home/airflow/.local/lib/python3.6/site-packages/airflow/models/taskinstance.py", line 1324, in _run_raw_task
    self._execute_task_with_callbacks(context)
  File "/home/airflow/.local/lib/python3.6/site-packages/airflow/models/taskinstance.py", line 1443, in _execute_task_with_callbacks
    result = self._execute_task(context, self.task)
  File "/home/airflow/.local/lib/python3.6/site-packages/airflow/models/taskinstance.py", line 1499, in _execute_task
    result = execute_callable(context=context)
  File "/home/airflow/.local/lib/python3.6/site-packages/airflow/operators/bash.py", line 188, in execute
    f'Bash command failed. The command returned a non-zero exit code {result.exit_code}.'
airflow.exceptions.AirflowException: Bash command failed. The command returned a non-zero exit code 1.

During handling of the above exception, another exception occurred:

Traceback (most recent call last):
  File "/home/airflow/.local/lib/python3.6/site-packages/airflow/models/taskinstance.py", line 2189, in email_alert
    send_email(self.task.email, subject, html_content)
  File "/home/airflow/.local/lib/python3.6/site-packages/airflow/utils/email.py", line 66, in send_email
    **kwargs,
  File "/home/airflow/.local/lib/python3.6/site-packages/airflow/utils/email.py", line 102, in send_email_smtp
    send_mime_email(e_from=smtp_mail_from, e_to=recipients, mime_msg=msg, conn_id=conn_id, dryrun=dryrun)
  File "/home/airflow/.local/lib/python3.6/site-packages/airflow/utils/email.py", line 210, in send_mime_email
    conn = _get_smtp_connection(smtp_host, smtp_port, smtp_timeout, smtp_ssl)
  File "/home/airflow/.local/lib/python3.6/site-packages/airflow/utils/email.py", line 244, in _get_smtp_connection
    else smtplib.SMTP(host=host, port=port, timeout=timeout)
  File "/usr/local/lib/python3.6/smtplib.py", line 251, in __init__
    (code, msg) = self.connect(host, port)
  File "/usr/local/lib/python3.6/smtplib.py", line 336, in connect
    self.sock = self._get_socket(host, port, self.timeout)
  File "/usr/local/lib/python3.6/smtplib.py", line 307, in _get_socket
    self.source_address)
  File "/usr/local/lib/python3.6/socket.py", line 724, in create_connection
    raise err
  File "/usr/local/lib/python3.6/socket.py", line 713, in create_connection
    sock.connect(sa)
OSError: [Errno 99] Cannot assign requested address

During handling of the above exception, another exception occurred:

Traceback (most recent call last):
  File "/home/airflow/.local/lib/python3.6/site-packages/airflow/models/taskinstance.py", line 1737, in handle_failure
    self.email_alert(error)
  File "/home/airflow/.local/lib/python3.6/site-packages/airflow/models/taskinstance.py", line 2191, in email_alert
    send_email(self.task.email, subject, html_content_err)
  File "/home/airflow/.local/lib/python3.6/site-packages/airflow/utils/email.py", line 66, in send_email
    **kwargs,
  File "/home/airflow/.local/lib/python3.6/site-packages/airflow/utils/email.py", line 102, in send_email_smtp
    send_mime_email(e_from=smtp_mail_from, e_to=recipients, mime_msg=msg, conn_id=conn_id, dryrun=dryrun)
  File "/home/airflow/.local/lib/python3.6/site-packages/airflow/utils/email.py", line 210, in send_mime_email
    conn = _get_smtp_connection(smtp_host, smtp_port, smtp_timeout, smtp_ssl)
  File "/home/airflow/.local/lib/python3.6/site-packages/airflow/utils/email.py", line 244, in _get_smtp_connection
    else smtplib.SMTP(host=host, port=port, timeout=timeout)
  File "/usr/local/lib/python3.6/smtplib.py", line 251, in __init__
    (code, msg) = self.connect(host, port)
  File "/usr/local/lib/python3.6/smtplib.py", line 336, in connect
    self.sock = self._get_socket(host, port, self.timeout)
  File "/usr/local/lib/python3.6/smtplib.py", line 307, in _get_socket
    self.source_address)
  File "/usr/local/lib/python3.6/socket.py", line 724, in create_connection
    raise err
  File "/usr/local/lib/python3.6/socket.py", line 713, in create_connection
    sock.connect(sa)
OSError: [Errno 99] Cannot assign requested address
[2021-10-26 17:26:36,932] {standard_task_runner.py:91} ERROR - Failed to execute job 18 for task spider_star
Traceback (most recent call last):
  File "/home/airflow/.local/lib/python3.6/site-packages/airflow/task/task_runner/standard_task_runner.py", line 85, in _start_by_fork
    args.func(args, dag=self.dag)
  File "/home/airflow/.local/lib/python3.6/site-packages/airflow/cli/cli_parser.py", line 48, in command
    return func(*args, **kwargs)
  File "/home/airflow/.local/lib/python3.6/site-packages/airflow/utils/cli.py", line 92, in wrapper
    return f(*args, **kwargs)
  File "/home/airflow/.local/lib/python3.6/site-packages/airflow/cli/commands/task_command.py", line 292, in task_run
    _run_task_by_selected_method(args, dag, ti)
  File "/home/airflow/.local/lib/python3.6/site-packages/airflow/cli/commands/task_command.py", line 107, in _run_task_by_selected_method
    _run_raw_task(args, ti)
  File "/home/airflow/.local/lib/python3.6/site-packages/airflow/cli/commands/task_command.py", line 184, in _run_raw_task
    error_file=args.error_file,
  File "/home/airflow/.local/lib/python3.6/site-packages/airflow/utils/session.py", line 70, in wrapper
    return func(*args, session=session, **kwargs)
  File "/home/airflow/.local/lib/python3.6/site-packages/airflow/models/taskinstance.py", line 1324, in _run_raw_task
    self._execute_task_with_callbacks(context)
  File "/home/airflow/.local/lib/python3.6/site-packages/airflow/models/taskinstance.py", line 1443, in _execute_task_with_callbacks
    result = self._execute_task(context, self.task)
  File "/home/airflow/.local/lib/python3.6/site-packages/airflow/models/taskinstance.py", line 1499, in _execute_task
    result = execute_callable(context=context)
  File "/home/airflow/.local/lib/python3.6/site-packages/airflow/operators/bash.py", line 188, in execute
    f'Bash command failed. The command returned a non-zero exit code {result.exit_code}.'
airflow.exceptions.AirflowException: Bash command failed. The command returned a non-zero exit code 1.
[2021-10-26 17:26:36,958] {local_task_job.py:154} INFO - Task exited with return code 1
[2021-10-26 17:26:37,025] {local_task_job.py:264} INFO - 0 downstream tasks scheduled from follow-on schedule check
[2021-10-26 17:28:22,010] {taskinstance.py:1035} INFO - Dependencies all met for <TaskInstance: scrapper.spider_star manual__2021-10-26T17:28:18.961756+00:00 [queued]>
[2021-10-26 17:28:22,055] {taskinstance.py:1035} INFO - Dependencies all met for <TaskInstance: scrapper.spider_star manual__2021-10-26T17:28:18.961756+00:00 [queued]>
[2021-10-26 17:28:22,056] {taskinstance.py:1241} INFO - 
--------------------------------------------------------------------------------
[2021-10-26 17:28:22,057] {taskinstance.py:1242} INFO - Starting attempt 1 of 2
[2021-10-26 17:28:22,059] {taskinstance.py:1243} INFO - 
--------------------------------------------------------------------------------
[2021-10-26 17:28:22,079] {taskinstance.py:1262} INFO - Executing <Task(BashOperator): spider_star> on 2021-10-26 17:28:18.961756+00:00
[2021-10-26 17:28:22,094] {standard_task_runner.py:76} INFO - Running: ['***', 'tasks', 'run', 'scrapper', 'spider_star', 'manual__2021-10-26T17:28:18.961756+00:00', '--job-id', '19', '--raw', '--subdir', 'DAGS_FOLDER/my_dag.py', '--cfg-path', '/tmp/tmpvhmq1b8r', '--error-file', '/tmp/tmpwta2a1ah']
[2021-10-26 17:28:22,105] {standard_task_runner.py:77} INFO - Job 19: Subtask spider_star
[2021-10-26 17:28:22,085] {standard_task_runner.py:52} INFO - Started process 13322 to run task
[2021-10-26 17:28:22,259] {logging_mixin.py:109} INFO - Running <TaskInstance: scrapper.spider_star manual__2021-10-26T17:28:18.961756+00:00 [running]> on host ebc91b274482
[2021-10-26 17:28:22,370] {taskinstance.py:1414} INFO - Exporting the following env vars:
AIRFLOW_CTX_DAG_EMAIL=octadelsueldo@gmail.com
AIRFLOW_CTX_DAG_OWNER=Octavio
AIRFLOW_CTX_DAG_ID=scrapper
AIRFLOW_CTX_TASK_ID=spider_star
AIRFLOW_CTX_EXECUTION_DATE=2021-10-26T17:28:18.961756+00:00
AIRFLOW_CTX_DAG_RUN_ID=manual__2021-10-26T17:28:18.961756+00:00
[2021-10-26 17:28:22,373] {subprocess.py:62} INFO - Tmp dir root location: 
 /tmp
[2021-10-26 17:28:22,375] {subprocess.py:74} INFO - Running command: ['bash', '-c', 'cd ./***/dags/script/run_spider.sh ']
[2021-10-26 17:28:22,408] {subprocess.py:85} INFO - Output:
[2021-10-26 17:28:22,415] {subprocess.py:89} INFO - bash: line 0: cd: ./***/dags/script/run_spider.sh: No such file or directory
[2021-10-26 17:28:22,418] {subprocess.py:93} INFO - Command exited with return code 1
[2021-10-26 17:28:22,423] {taskinstance.py:1686} ERROR - Task failed with exception
Traceback (most recent call last):
  File "/home/airflow/.local/lib/python3.6/site-packages/airflow/models/taskinstance.py", line 1324, in _run_raw_task
    self._execute_task_with_callbacks(context)
  File "/home/airflow/.local/lib/python3.6/site-packages/airflow/models/taskinstance.py", line 1443, in _execute_task_with_callbacks
    result = self._execute_task(context, self.task)
  File "/home/airflow/.local/lib/python3.6/site-packages/airflow/models/taskinstance.py", line 1499, in _execute_task
    result = execute_callable(context=context)
  File "/home/airflow/.local/lib/python3.6/site-packages/airflow/operators/bash.py", line 188, in execute
    f'Bash command failed. The command returned a non-zero exit code {result.exit_code}.'
airflow.exceptions.AirflowException: Bash command failed. The command returned a non-zero exit code 1.
[2021-10-26 17:28:22,467] {taskinstance.py:1280} INFO - Marking task as UP_FOR_RETRY. dag_id=scrapper, task_id=spider_star, execution_date=20211026T172818, start_date=20211026T172822, end_date=20211026T172822
[2021-10-26 17:28:22,515] {warnings.py:99} WARNING - /home/***/.local/lib/python3.6/site-packages/***/utils/email.py:102: PendingDeprecationWarning: Fetching SMTP credentials from configuration variables will be deprecated in a future release. Please set credentials using a connection instead.
  send_mime_email(e_from=smtp_mail_from, e_to=recipients, mime_msg=msg, conn_id=conn_id, dryrun=dryrun)

[2021-10-26 17:28:22,516] {configuration.py:381} WARNING - section/key [smtp/smtp_user] not found in config
[2021-10-26 17:28:22,518] {email.py:208} INFO - Email alerting: attempt 1
[2021-10-26 17:28:22,545] {configuration.py:381} WARNING - section/key [smtp/smtp_user] not found in config
[2021-10-26 17:28:22,546] {email.py:208} INFO - Email alerting: attempt 1
[2021-10-26 17:28:22,550] {taskinstance.py:1739} ERROR - Failed to send email to: ['octadelsueldo@gmail.com']
Traceback (most recent call last):
  File "/home/airflow/.local/lib/python3.6/site-packages/airflow/models/taskinstance.py", line 1324, in _run_raw_task
    self._execute_task_with_callbacks(context)
  File "/home/airflow/.local/lib/python3.6/site-packages/airflow/models/taskinstance.py", line 1443, in _execute_task_with_callbacks
    result = self._execute_task(context, self.task)
  File "/home/airflow/.local/lib/python3.6/site-packages/airflow/models/taskinstance.py", line 1499, in _execute_task
    result = execute_callable(context=context)
  File "/home/airflow/.local/lib/python3.6/site-packages/airflow/operators/bash.py", line 188, in execute
    f'Bash command failed. The command returned a non-zero exit code {result.exit_code}.'
airflow.exceptions.AirflowException: Bash command failed. The command returned a non-zero exit code 1.

During handling of the above exception, another exception occurred:

Traceback (most recent call last):
  File "/home/airflow/.local/lib/python3.6/site-packages/airflow/models/taskinstance.py", line 2189, in email_alert
    send_email(self.task.email, subject, html_content)
  File "/home/airflow/.local/lib/python3.6/site-packages/airflow/utils/email.py", line 66, in send_email
    **kwargs,
  File "/home/airflow/.local/lib/python3.6/site-packages/airflow/utils/email.py", line 102, in send_email_smtp
    send_mime_email(e_from=smtp_mail_from, e_to=recipients, mime_msg=msg, conn_id=conn_id, dryrun=dryrun)
  File "/home/airflow/.local/lib/python3.6/site-packages/airflow/utils/email.py", line 210, in send_mime_email
    conn = _get_smtp_connection(smtp_host, smtp_port, smtp_timeout, smtp_ssl)
  File "/home/airflow/.local/lib/python3.6/site-packages/airflow/utils/email.py", line 244, in _get_smtp_connection
    else smtplib.SMTP(host=host, port=port, timeout=timeout)
  File "/usr/local/lib/python3.6/smtplib.py", line 251, in __init__
    (code, msg) = self.connect(host, port)
  File "/usr/local/lib/python3.6/smtplib.py", line 336, in connect
    self.sock = self._get_socket(host, port, self.timeout)
  File "/usr/local/lib/python3.6/smtplib.py", line 307, in _get_socket
    self.source_address)
  File "/usr/local/lib/python3.6/socket.py", line 724, in create_connection
    raise err
  File "/usr/local/lib/python3.6/socket.py", line 713, in create_connection
    sock.connect(sa)
OSError: [Errno 99] Cannot assign requested address

During handling of the above exception, another exception occurred:

Traceback (most recent call last):
  File "/home/airflow/.local/lib/python3.6/site-packages/airflow/models/taskinstance.py", line 1737, in handle_failure
    self.email_alert(error)
  File "/home/airflow/.local/lib/python3.6/site-packages/airflow/models/taskinstance.py", line 2191, in email_alert
    send_email(self.task.email, subject, html_content_err)
  File "/home/airflow/.local/lib/python3.6/site-packages/airflow/utils/email.py", line 66, in send_email
    **kwargs,
  File "/home/airflow/.local/lib/python3.6/site-packages/airflow/utils/email.py", line 102, in send_email_smtp
    send_mime_email(e_from=smtp_mail_from, e_to=recipients, mime_msg=msg, conn_id=conn_id, dryrun=dryrun)
  File "/home/airflow/.local/lib/python3.6/site-packages/airflow/utils/email.py", line 210, in send_mime_email
    conn = _get_smtp_connection(smtp_host, smtp_port, smtp_timeout, smtp_ssl)
  File "/home/airflow/.local/lib/python3.6/site-packages/airflow/utils/email.py", line 244, in _get_smtp_connection
    else smtplib.SMTP(host=host, port=port, timeout=timeout)
  File "/usr/local/lib/python3.6/smtplib.py", line 251, in __init__
    (code, msg) = self.connect(host, port)
  File "/usr/local/lib/python3.6/smtplib.py", line 336, in connect
    self.sock = self._get_socket(host, port, self.timeout)
  File "/usr/local/lib/python3.6/smtplib.py", line 307, in _get_socket
    self.source_address)
  File "/usr/local/lib/python3.6/socket.py", line 724, in create_connection
    raise err
  File "/usr/local/lib/python3.6/socket.py", line 713, in create_connection
    sock.connect(sa)
OSError: [Errno 99] Cannot assign requested address
[2021-10-26 17:28:22,600] {standard_task_runner.py:91} ERROR - Failed to execute job 19 for task spider_star
Traceback (most recent call last):
  File "/home/airflow/.local/lib/python3.6/site-packages/airflow/task/task_runner/standard_task_runner.py", line 85, in _start_by_fork
    args.func(args, dag=self.dag)
  File "/home/airflow/.local/lib/python3.6/site-packages/airflow/cli/cli_parser.py", line 48, in command
    return func(*args, **kwargs)
  File "/home/airflow/.local/lib/python3.6/site-packages/airflow/utils/cli.py", line 92, in wrapper
    return f(*args, **kwargs)
  File "/home/airflow/.local/lib/python3.6/site-packages/airflow/cli/commands/task_command.py", line 292, in task_run
    _run_task_by_selected_method(args, dag, ti)
  File "/home/airflow/.local/lib/python3.6/site-packages/airflow/cli/commands/task_command.py", line 107, in _run_task_by_selected_method
    _run_raw_task(args, ti)
  File "/home/airflow/.local/lib/python3.6/site-packages/airflow/cli/commands/task_command.py", line 184, in _run_raw_task
    error_file=args.error_file,
  File "/home/airflow/.local/lib/python3.6/site-packages/airflow/utils/session.py", line 70, in wrapper
    return func(*args, session=session, **kwargs)
  File "/home/airflow/.local/lib/python3.6/site-packages/airflow/models/taskinstance.py", line 1324, in _run_raw_task
    self._execute_task_with_callbacks(context)
  File "/home/airflow/.local/lib/python3.6/site-packages/airflow/models/taskinstance.py", line 1443, in _execute_task_with_callbacks
    result = self._execute_task(context, self.task)
  File "/home/airflow/.local/lib/python3.6/site-packages/airflow/models/taskinstance.py", line 1499, in _execute_task
    result = execute_callable(context=context)
  File "/home/airflow/.local/lib/python3.6/site-packages/airflow/operators/bash.py", line 188, in execute
    f'Bash command failed. The command returned a non-zero exit code {result.exit_code}.'
airflow.exceptions.AirflowException: Bash command failed. The command returned a non-zero exit code 1.
[2021-10-26 17:28:22,626] {local_task_job.py:154} INFO - Task exited with return code 1
[2021-10-26 17:28:22,676] {local_task_job.py:264} INFO - 0 downstream tasks scheduled from follow-on schedule check
[2021-10-26 17:30:00,280] {taskinstance.py:1035} INFO - Dependencies all met for <TaskInstance: scrapper.spider_star manual__2021-10-26T17:29:57.651606+00:00 [queued]>
[2021-10-26 17:30:00,316] {taskinstance.py:1035} INFO - Dependencies all met for <TaskInstance: scrapper.spider_star manual__2021-10-26T17:29:57.651606+00:00 [queued]>
[2021-10-26 17:30:00,318] {taskinstance.py:1241} INFO - 
--------------------------------------------------------------------------------
[2021-10-26 17:30:00,319] {taskinstance.py:1242} INFO - Starting attempt 1 of 2
[2021-10-26 17:30:00,320] {taskinstance.py:1243} INFO - 
--------------------------------------------------------------------------------
[2021-10-26 17:30:00,360] {taskinstance.py:1262} INFO - Executing <Task(BashOperator): spider_star> on 2021-10-26 17:29:57.651606+00:00
[2021-10-26 17:30:00,376] {standard_task_runner.py:52} INFO - Started process 13387 to run task
[2021-10-26 17:30:00,392] {standard_task_runner.py:76} INFO - Running: ['***', 'tasks', 'run', 'scrapper', 'spider_star', 'manual__2021-10-26T17:29:57.651606+00:00', '--job-id', '21', '--raw', '--subdir', 'DAGS_FOLDER/my_dag.py', '--cfg-path', '/tmp/tmprlo92fox', '--error-file', '/tmp/tmpl_a3hfrz']
[2021-10-26 17:30:00,396] {standard_task_runner.py:77} INFO - Job 21: Subtask spider_star
[2021-10-26 17:30:00,524] {logging_mixin.py:109} INFO - Running <TaskInstance: scrapper.spider_star manual__2021-10-26T17:29:57.651606+00:00 [running]> on host ebc91b274482
[2021-10-26 17:30:00,641] {taskinstance.py:1414} INFO - Exporting the following env vars:
AIRFLOW_CTX_DAG_EMAIL=octadelsueldo@gmail.com
AIRFLOW_CTX_DAG_OWNER=Octavio
AIRFLOW_CTX_DAG_ID=scrapper
AIRFLOW_CTX_TASK_ID=spider_star
AIRFLOW_CTX_EXECUTION_DATE=2021-10-26T17:29:57.651606+00:00
AIRFLOW_CTX_DAG_RUN_ID=manual__2021-10-26T17:29:57.651606+00:00
[2021-10-26 17:30:00,646] {subprocess.py:62} INFO - Tmp dir root location: 
 /tmp
[2021-10-26 17:30:00,648] {subprocess.py:74} INFO - Running command: ['bash', '-c', './dags/script/run_spider.sh ']
[2021-10-26 17:30:00,677] {subprocess.py:85} INFO - Output:
[2021-10-26 17:30:00,683] {subprocess.py:89} INFO - bash: ./dags/script/run_spider.sh: No such file or directory
[2021-10-26 17:30:00,690] {subprocess.py:93} INFO - Command exited with return code 127
[2021-10-26 17:30:00,699] {taskinstance.py:1686} ERROR - Task failed with exception
Traceback (most recent call last):
  File "/home/airflow/.local/lib/python3.6/site-packages/airflow/models/taskinstance.py", line 1324, in _run_raw_task
    self._execute_task_with_callbacks(context)
  File "/home/airflow/.local/lib/python3.6/site-packages/airflow/models/taskinstance.py", line 1443, in _execute_task_with_callbacks
    result = self._execute_task(context, self.task)
  File "/home/airflow/.local/lib/python3.6/site-packages/airflow/models/taskinstance.py", line 1499, in _execute_task
    result = execute_callable(context=context)
  File "/home/airflow/.local/lib/python3.6/site-packages/airflow/operators/bash.py", line 188, in execute
    f'Bash command failed. The command returned a non-zero exit code {result.exit_code}.'
airflow.exceptions.AirflowException: Bash command failed. The command returned a non-zero exit code 127.
[2021-10-26 17:30:00,737] {taskinstance.py:1280} INFO - Marking task as UP_FOR_RETRY. dag_id=scrapper, task_id=spider_star, execution_date=20211026T172957, start_date=20211026T173000, end_date=20211026T173000
[2021-10-26 17:30:00,754] {warnings.py:99} WARNING - /home/***/.local/lib/python3.6/site-packages/***/utils/email.py:102: PendingDeprecationWarning: Fetching SMTP credentials from configuration variables will be deprecated in a future release. Please set credentials using a connection instead.
  send_mime_email(e_from=smtp_mail_from, e_to=recipients, mime_msg=msg, conn_id=conn_id, dryrun=dryrun)

[2021-10-26 17:30:00,755] {configuration.py:381} WARNING - section/key [smtp/smtp_user] not found in config
[2021-10-26 17:30:00,757] {email.py:208} INFO - Email alerting: attempt 1
[2021-10-26 17:30:00,777] {configuration.py:381} WARNING - section/key [smtp/smtp_user] not found in config
[2021-10-26 17:30:00,779] {email.py:208} INFO - Email alerting: attempt 1
[2021-10-26 17:30:00,781] {taskinstance.py:1739} ERROR - Failed to send email to: ['octadelsueldo@gmail.com']
Traceback (most recent call last):
  File "/home/airflow/.local/lib/python3.6/site-packages/airflow/models/taskinstance.py", line 1324, in _run_raw_task
    self._execute_task_with_callbacks(context)
  File "/home/airflow/.local/lib/python3.6/site-packages/airflow/models/taskinstance.py", line 1443, in _execute_task_with_callbacks
    result = self._execute_task(context, self.task)
  File "/home/airflow/.local/lib/python3.6/site-packages/airflow/models/taskinstance.py", line 1499, in _execute_task
    result = execute_callable(context=context)
  File "/home/airflow/.local/lib/python3.6/site-packages/airflow/operators/bash.py", line 188, in execute
    f'Bash command failed. The command returned a non-zero exit code {result.exit_code}.'
airflow.exceptions.AirflowException: Bash command failed. The command returned a non-zero exit code 127.

During handling of the above exception, another exception occurred:

Traceback (most recent call last):
  File "/home/airflow/.local/lib/python3.6/site-packages/airflow/models/taskinstance.py", line 2189, in email_alert
    send_email(self.task.email, subject, html_content)
  File "/home/airflow/.local/lib/python3.6/site-packages/airflow/utils/email.py", line 66, in send_email
    **kwargs,
  File "/home/airflow/.local/lib/python3.6/site-packages/airflow/utils/email.py", line 102, in send_email_smtp
    send_mime_email(e_from=smtp_mail_from, e_to=recipients, mime_msg=msg, conn_id=conn_id, dryrun=dryrun)
  File "/home/airflow/.local/lib/python3.6/site-packages/airflow/utils/email.py", line 210, in send_mime_email
    conn = _get_smtp_connection(smtp_host, smtp_port, smtp_timeout, smtp_ssl)
  File "/home/airflow/.local/lib/python3.6/site-packages/airflow/utils/email.py", line 244, in _get_smtp_connection
    else smtplib.SMTP(host=host, port=port, timeout=timeout)
  File "/usr/local/lib/python3.6/smtplib.py", line 251, in __init__
    (code, msg) = self.connect(host, port)
  File "/usr/local/lib/python3.6/smtplib.py", line 336, in connect
    self.sock = self._get_socket(host, port, self.timeout)
  File "/usr/local/lib/python3.6/smtplib.py", line 307, in _get_socket
    self.source_address)
  File "/usr/local/lib/python3.6/socket.py", line 724, in create_connection
    raise err
  File "/usr/local/lib/python3.6/socket.py", line 713, in create_connection
    sock.connect(sa)
OSError: [Errno 99] Cannot assign requested address

During handling of the above exception, another exception occurred:

Traceback (most recent call last):
  File "/home/airflow/.local/lib/python3.6/site-packages/airflow/models/taskinstance.py", line 1737, in handle_failure
    self.email_alert(error)
  File "/home/airflow/.local/lib/python3.6/site-packages/airflow/models/taskinstance.py", line 2191, in email_alert
    send_email(self.task.email, subject, html_content_err)
  File "/home/airflow/.local/lib/python3.6/site-packages/airflow/utils/email.py", line 66, in send_email
    **kwargs,
  File "/home/airflow/.local/lib/python3.6/site-packages/airflow/utils/email.py", line 102, in send_email_smtp
    send_mime_email(e_from=smtp_mail_from, e_to=recipients, mime_msg=msg, conn_id=conn_id, dryrun=dryrun)
  File "/home/airflow/.local/lib/python3.6/site-packages/airflow/utils/email.py", line 210, in send_mime_email
    conn = _get_smtp_connection(smtp_host, smtp_port, smtp_timeout, smtp_ssl)
  File "/home/airflow/.local/lib/python3.6/site-packages/airflow/utils/email.py", line 244, in _get_smtp_connection
    else smtplib.SMTP(host=host, port=port, timeout=timeout)
  File "/usr/local/lib/python3.6/smtplib.py", line 251, in __init__
    (code, msg) = self.connect(host, port)
  File "/usr/local/lib/python3.6/smtplib.py", line 336, in connect
    self.sock = self._get_socket(host, port, self.timeout)
  File "/usr/local/lib/python3.6/smtplib.py", line 307, in _get_socket
    self.source_address)
  File "/usr/local/lib/python3.6/socket.py", line 724, in create_connection
    raise err
  File "/usr/local/lib/python3.6/socket.py", line 713, in create_connection
    sock.connect(sa)
OSError: [Errno 99] Cannot assign requested address
[2021-10-26 17:30:00,816] {standard_task_runner.py:91} ERROR - Failed to execute job 21 for task spider_star
Traceback (most recent call last):
  File "/home/airflow/.local/lib/python3.6/site-packages/airflow/task/task_runner/standard_task_runner.py", line 85, in _start_by_fork
    args.func(args, dag=self.dag)
  File "/home/airflow/.local/lib/python3.6/site-packages/airflow/cli/cli_parser.py", line 48, in command
    return func(*args, **kwargs)
  File "/home/airflow/.local/lib/python3.6/site-packages/airflow/utils/cli.py", line 92, in wrapper
    return f(*args, **kwargs)
  File "/home/airflow/.local/lib/python3.6/site-packages/airflow/cli/commands/task_command.py", line 292, in task_run
    _run_task_by_selected_method(args, dag, ti)
  File "/home/airflow/.local/lib/python3.6/site-packages/airflow/cli/commands/task_command.py", line 107, in _run_task_by_selected_method
    _run_raw_task(args, ti)
  File "/home/airflow/.local/lib/python3.6/site-packages/airflow/cli/commands/task_command.py", line 184, in _run_raw_task
    error_file=args.error_file,
  File "/home/airflow/.local/lib/python3.6/site-packages/airflow/utils/session.py", line 70, in wrapper
    return func(*args, session=session, **kwargs)
  File "/home/airflow/.local/lib/python3.6/site-packages/airflow/models/taskinstance.py", line 1324, in _run_raw_task
    self._execute_task_with_callbacks(context)
  File "/home/airflow/.local/lib/python3.6/site-packages/airflow/models/taskinstance.py", line 1443, in _execute_task_with_callbacks
    result = self._execute_task(context, self.task)
  File "/home/airflow/.local/lib/python3.6/site-packages/airflow/models/taskinstance.py", line 1499, in _execute_task
    result = execute_callable(context=context)
  File "/home/airflow/.local/lib/python3.6/site-packages/airflow/operators/bash.py", line 188, in execute
    f'Bash command failed. The command returned a non-zero exit code {result.exit_code}.'
airflow.exceptions.AirflowException: Bash command failed. The command returned a non-zero exit code 127.
[2021-10-26 17:30:00,874] {local_task_job.py:154} INFO - Task exited with return code 1
[2021-10-26 17:30:00,927] {local_task_job.py:264} INFO - 0 downstream tasks scheduled from follow-on schedule check
[2021-10-26 17:33:17,263] {taskinstance.py:1035} INFO - Dependencies all met for <TaskInstance: scrapper.spider_star manual__2021-10-26T17:33:13.761818+00:00 [queued]>
[2021-10-26 17:33:17,332] {taskinstance.py:1035} INFO - Dependencies all met for <TaskInstance: scrapper.spider_star manual__2021-10-26T17:33:13.761818+00:00 [queued]>
[2021-10-26 17:33:17,333] {taskinstance.py:1241} INFO - 
--------------------------------------------------------------------------------
[2021-10-26 17:33:17,334] {taskinstance.py:1242} INFO - Starting attempt 1 of 2
[2021-10-26 17:33:17,337] {taskinstance.py:1243} INFO - 
--------------------------------------------------------------------------------
[2021-10-26 17:33:17,424] {taskinstance.py:1262} INFO - Executing <Task(BashOperator): spider_star> on 2021-10-26 17:33:13.761818+00:00
[2021-10-26 17:33:17,550] {standard_task_runner.py:76} INFO - Running: ['***', 'tasks', 'run', 'scrapper', 'spider_star', 'manual__2021-10-26T17:33:13.761818+00:00', '--job-id', '23', '--raw', '--subdir', 'DAGS_FOLDER/my_dag.py', '--cfg-path', '/tmp/tmpvzwa1zyk', '--error-file', '/tmp/tmpi4dfzdzd']
[2021-10-26 17:33:17,456] {standard_task_runner.py:52} INFO - Started process 13535 to run task
[2021-10-26 17:33:17,569] {standard_task_runner.py:77} INFO - Job 23: Subtask spider_star
[2021-10-26 17:33:17,818] {logging_mixin.py:109} INFO - Running <TaskInstance: scrapper.spider_star manual__2021-10-26T17:33:13.761818+00:00 [running]> on host ebc91b274482
[2021-10-26 17:33:18,010] {taskinstance.py:1414} INFO - Exporting the following env vars:
AIRFLOW_CTX_DAG_EMAIL=octadelsueldo@gmail.com
AIRFLOW_CTX_DAG_OWNER=Octavio
AIRFLOW_CTX_DAG_ID=scrapper
AIRFLOW_CTX_TASK_ID=spider_star
AIRFLOW_CTX_EXECUTION_DATE=2021-10-26T17:33:13.761818+00:00
AIRFLOW_CTX_DAG_RUN_ID=manual__2021-10-26T17:33:13.761818+00:00
[2021-10-26 17:33:18,017] {subprocess.py:62} INFO - Tmp dir root location: 
 /tmp
[2021-10-26 17:33:18,021] {subprocess.py:74} INFO - Running command: ['bash', '-c', '${AIRFLOW_HOME}/***/dags/script/run_spider.sh ']
[2021-10-26 17:33:18,085] {subprocess.py:85} INFO - Output:
[2021-10-26 17:33:18,111] {subprocess.py:89} INFO - bash: /opt/***/***/dags/script/run_spider.sh: No such file or directory
[2021-10-26 17:33:18,113] {subprocess.py:93} INFO - Command exited with return code 127
[2021-10-26 17:33:18,125] {taskinstance.py:1686} ERROR - Task failed with exception
Traceback (most recent call last):
  File "/home/airflow/.local/lib/python3.6/site-packages/airflow/models/taskinstance.py", line 1324, in _run_raw_task
    self._execute_task_with_callbacks(context)
  File "/home/airflow/.local/lib/python3.6/site-packages/airflow/models/taskinstance.py", line 1443, in _execute_task_with_callbacks
    result = self._execute_task(context, self.task)
  File "/home/airflow/.local/lib/python3.6/site-packages/airflow/models/taskinstance.py", line 1499, in _execute_task
    result = execute_callable(context=context)
  File "/home/airflow/.local/lib/python3.6/site-packages/airflow/operators/bash.py", line 188, in execute
    f'Bash command failed. The command returned a non-zero exit code {result.exit_code}.'
airflow.exceptions.AirflowException: Bash command failed. The command returned a non-zero exit code 127.
[2021-10-26 17:33:18,205] {taskinstance.py:1280} INFO - Marking task as UP_FOR_RETRY. dag_id=scrapper, task_id=spider_star, execution_date=20211026T173313, start_date=20211026T173317, end_date=20211026T173318
[2021-10-26 17:33:18,328] {warnings.py:99} WARNING - /home/***/.local/lib/python3.6/site-packages/***/utils/email.py:102: PendingDeprecationWarning: Fetching SMTP credentials from configuration variables will be deprecated in a future release. Please set credentials using a connection instead.
  send_mime_email(e_from=smtp_mail_from, e_to=recipients, mime_msg=msg, conn_id=conn_id, dryrun=dryrun)

[2021-10-26 17:33:18,330] {configuration.py:381} WARNING - section/key [smtp/smtp_user] not found in config
[2021-10-26 17:33:18,331] {email.py:208} INFO - Email alerting: attempt 1
[2021-10-26 17:33:18,388] {configuration.py:381} WARNING - section/key [smtp/smtp_user] not found in config
[2021-10-26 17:33:18,389] {email.py:208} INFO - Email alerting: attempt 1
[2021-10-26 17:33:18,391] {taskinstance.py:1739} ERROR - Failed to send email to: ['octadelsueldo@gmail.com']
Traceback (most recent call last):
  File "/home/airflow/.local/lib/python3.6/site-packages/airflow/models/taskinstance.py", line 1324, in _run_raw_task
    self._execute_task_with_callbacks(context)
  File "/home/airflow/.local/lib/python3.6/site-packages/airflow/models/taskinstance.py", line 1443, in _execute_task_with_callbacks
    result = self._execute_task(context, self.task)
  File "/home/airflow/.local/lib/python3.6/site-packages/airflow/models/taskinstance.py", line 1499, in _execute_task
    result = execute_callable(context=context)
  File "/home/airflow/.local/lib/python3.6/site-packages/airflow/operators/bash.py", line 188, in execute
    f'Bash command failed. The command returned a non-zero exit code {result.exit_code}.'
airflow.exceptions.AirflowException: Bash command failed. The command returned a non-zero exit code 127.

During handling of the above exception, another exception occurred:

Traceback (most recent call last):
  File "/home/airflow/.local/lib/python3.6/site-packages/airflow/models/taskinstance.py", line 2189, in email_alert
    send_email(self.task.email, subject, html_content)
  File "/home/airflow/.local/lib/python3.6/site-packages/airflow/utils/email.py", line 66, in send_email
    **kwargs,
  File "/home/airflow/.local/lib/python3.6/site-packages/airflow/utils/email.py", line 102, in send_email_smtp
    send_mime_email(e_from=smtp_mail_from, e_to=recipients, mime_msg=msg, conn_id=conn_id, dryrun=dryrun)
  File "/home/airflow/.local/lib/python3.6/site-packages/airflow/utils/email.py", line 210, in send_mime_email
    conn = _get_smtp_connection(smtp_host, smtp_port, smtp_timeout, smtp_ssl)
  File "/home/airflow/.local/lib/python3.6/site-packages/airflow/utils/email.py", line 244, in _get_smtp_connection
    else smtplib.SMTP(host=host, port=port, timeout=timeout)
  File "/usr/local/lib/python3.6/smtplib.py", line 251, in __init__
    (code, msg) = self.connect(host, port)
  File "/usr/local/lib/python3.6/smtplib.py", line 336, in connect
    self.sock = self._get_socket(host, port, self.timeout)
  File "/usr/local/lib/python3.6/smtplib.py", line 307, in _get_socket
    self.source_address)
  File "/usr/local/lib/python3.6/socket.py", line 724, in create_connection
    raise err
  File "/usr/local/lib/python3.6/socket.py", line 713, in create_connection
    sock.connect(sa)
OSError: [Errno 99] Cannot assign requested address

During handling of the above exception, another exception occurred:

Traceback (most recent call last):
  File "/home/airflow/.local/lib/python3.6/site-packages/airflow/models/taskinstance.py", line 1737, in handle_failure
    self.email_alert(error)
  File "/home/airflow/.local/lib/python3.6/site-packages/airflow/models/taskinstance.py", line 2191, in email_alert
    send_email(self.task.email, subject, html_content_err)
  File "/home/airflow/.local/lib/python3.6/site-packages/airflow/utils/email.py", line 66, in send_email
    **kwargs,
  File "/home/airflow/.local/lib/python3.6/site-packages/airflow/utils/email.py", line 102, in send_email_smtp
    send_mime_email(e_from=smtp_mail_from, e_to=recipients, mime_msg=msg, conn_id=conn_id, dryrun=dryrun)
  File "/home/airflow/.local/lib/python3.6/site-packages/airflow/utils/email.py", line 210, in send_mime_email
    conn = _get_smtp_connection(smtp_host, smtp_port, smtp_timeout, smtp_ssl)
  File "/home/airflow/.local/lib/python3.6/site-packages/airflow/utils/email.py", line 244, in _get_smtp_connection
    else smtplib.SMTP(host=host, port=port, timeout=timeout)
  File "/usr/local/lib/python3.6/smtplib.py", line 251, in __init__
    (code, msg) = self.connect(host, port)
  File "/usr/local/lib/python3.6/smtplib.py", line 336, in connect
    self.sock = self._get_socket(host, port, self.timeout)
  File "/usr/local/lib/python3.6/smtplib.py", line 307, in _get_socket
    self.source_address)
  File "/usr/local/lib/python3.6/socket.py", line 724, in create_connection
    raise err
  File "/usr/local/lib/python3.6/socket.py", line 713, in create_connection
    sock.connect(sa)
OSError: [Errno 99] Cannot assign requested address
[2021-10-26 17:33:18,471] {standard_task_runner.py:91} ERROR - Failed to execute job 23 for task spider_star
Traceback (most recent call last):
  File "/home/airflow/.local/lib/python3.6/site-packages/airflow/task/task_runner/standard_task_runner.py", line 85, in _start_by_fork
    args.func(args, dag=self.dag)
  File "/home/airflow/.local/lib/python3.6/site-packages/airflow/cli/cli_parser.py", line 48, in command
    return func(*args, **kwargs)
  File "/home/airflow/.local/lib/python3.6/site-packages/airflow/utils/cli.py", line 92, in wrapper
    return f(*args, **kwargs)
  File "/home/airflow/.local/lib/python3.6/site-packages/airflow/cli/commands/task_command.py", line 292, in task_run
    _run_task_by_selected_method(args, dag, ti)
  File "/home/airflow/.local/lib/python3.6/site-packages/airflow/cli/commands/task_command.py", line 107, in _run_task_by_selected_method
    _run_raw_task(args, ti)
  File "/home/airflow/.local/lib/python3.6/site-packages/airflow/cli/commands/task_command.py", line 184, in _run_raw_task
    error_file=args.error_file,
  File "/home/airflow/.local/lib/python3.6/site-packages/airflow/utils/session.py", line 70, in wrapper
    return func(*args, session=session, **kwargs)
  File "/home/airflow/.local/lib/python3.6/site-packages/airflow/models/taskinstance.py", line 1324, in _run_raw_task
    self._execute_task_with_callbacks(context)
  File "/home/airflow/.local/lib/python3.6/site-packages/airflow/models/taskinstance.py", line 1443, in _execute_task_with_callbacks
    result = self._execute_task(context, self.task)
  File "/home/airflow/.local/lib/python3.6/site-packages/airflow/models/taskinstance.py", line 1499, in _execute_task
    result = execute_callable(context=context)
  File "/home/airflow/.local/lib/python3.6/site-packages/airflow/operators/bash.py", line 188, in execute
    f'Bash command failed. The command returned a non-zero exit code {result.exit_code}.'
airflow.exceptions.AirflowException: Bash command failed. The command returned a non-zero exit code 127.
[2021-10-26 17:33:18,573] {local_task_job.py:154} INFO - Task exited with return code 1
[2021-10-26 17:33:19,187] {local_task_job.py:264} INFO - 0 downstream tasks scheduled from follow-on schedule check
[2021-10-26 17:43:21,046] {taskinstance.py:1035} INFO - Dependencies all met for <TaskInstance: scrapper.spider_star manual__2021-10-26T17:43:18.731062+00:00 [queued]>
[2021-10-26 17:43:21,090] {taskinstance.py:1035} INFO - Dependencies all met for <TaskInstance: scrapper.spider_star manual__2021-10-26T17:43:18.731062+00:00 [queued]>
[2021-10-26 17:43:21,096] {taskinstance.py:1241} INFO - 
--------------------------------------------------------------------------------
[2021-10-26 17:43:21,098] {taskinstance.py:1242} INFO - Starting attempt 1 of 2
[2021-10-26 17:43:21,099] {taskinstance.py:1243} INFO - 
--------------------------------------------------------------------------------
[2021-10-26 17:43:21,131] {taskinstance.py:1262} INFO - Executing <Task(BashOperator): spider_star> on 2021-10-26 17:43:18.731062+00:00
[2021-10-26 17:43:21,148] {standard_task_runner.py:76} INFO - Running: ['***', 'tasks', 'run', 'scrapper', 'spider_star', 'manual__2021-10-26T17:43:18.731062+00:00', '--job-id', '27', '--raw', '--subdir', 'DAGS_FOLDER/my_dag.py', '--cfg-path', '/tmp/tmp1c8h706w', '--error-file', '/tmp/tmpm5lpjej3']
[2021-10-26 17:43:21,137] {standard_task_runner.py:52} INFO - Started process 13971 to run task
[2021-10-26 17:43:21,157] {standard_task_runner.py:77} INFO - Job 27: Subtask spider_star
[2021-10-26 17:43:21,231] {logging_mixin.py:109} INFO - Running <TaskInstance: scrapper.spider_star manual__2021-10-26T17:43:18.731062+00:00 [running]> on host ebc91b274482
[2021-10-26 17:43:21,311] {taskinstance.py:1414} INFO - Exporting the following env vars:
AIRFLOW_CTX_DAG_EMAIL=octadelsueldo@gmail.com
AIRFLOW_CTX_DAG_OWNER=Octavio
AIRFLOW_CTX_DAG_ID=scrapper
AIRFLOW_CTX_TASK_ID=spider_star
AIRFLOW_CTX_EXECUTION_DATE=2021-10-26T17:43:18.731062+00:00
AIRFLOW_CTX_DAG_RUN_ID=manual__2021-10-26T17:43:18.731062+00:00
[2021-10-26 17:43:21,319] {subprocess.py:62} INFO - Tmp dir root location: 
 /tmp
[2021-10-26 17:43:21,326] {subprocess.py:74} INFO - Running command: ['bash', '-c', 'cd ./***/dags/script;bash run_spider.sh ']
[2021-10-26 17:43:21,355] {subprocess.py:85} INFO - Output:
[2021-10-26 17:43:21,361] {subprocess.py:89} INFO - bash: line 0: cd: ./***/dags/script: No such file or directory
[2021-10-26 17:43:21,371] {subprocess.py:89} INFO - bash: run_spider.sh: No such file or directory
[2021-10-26 17:43:21,374] {subprocess.py:93} INFO - Command exited with return code 127
[2021-10-26 17:43:21,381] {taskinstance.py:1686} ERROR - Task failed with exception
Traceback (most recent call last):
  File "/home/airflow/.local/lib/python3.6/site-packages/airflow/models/taskinstance.py", line 1324, in _run_raw_task
    self._execute_task_with_callbacks(context)
  File "/home/airflow/.local/lib/python3.6/site-packages/airflow/models/taskinstance.py", line 1443, in _execute_task_with_callbacks
    result = self._execute_task(context, self.task)
  File "/home/airflow/.local/lib/python3.6/site-packages/airflow/models/taskinstance.py", line 1499, in _execute_task
    result = execute_callable(context=context)
  File "/home/airflow/.local/lib/python3.6/site-packages/airflow/operators/bash.py", line 188, in execute
    f'Bash command failed. The command returned a non-zero exit code {result.exit_code}.'
airflow.exceptions.AirflowException: Bash command failed. The command returned a non-zero exit code 127.
[2021-10-26 17:43:21,418] {taskinstance.py:1280} INFO - Marking task as UP_FOR_RETRY. dag_id=scrapper, task_id=spider_star, execution_date=20211026T174318, start_date=20211026T174321, end_date=20211026T174321
[2021-10-26 17:43:21,440] {warnings.py:99} WARNING - /home/***/.local/lib/python3.6/site-packages/***/utils/email.py:102: PendingDeprecationWarning: Fetching SMTP credentials from configuration variables will be deprecated in a future release. Please set credentials using a connection instead.
  send_mime_email(e_from=smtp_mail_from, e_to=recipients, mime_msg=msg, conn_id=conn_id, dryrun=dryrun)

[2021-10-26 17:43:21,442] {configuration.py:381} WARNING - section/key [smtp/smtp_user] not found in config
[2021-10-26 17:43:21,443] {email.py:208} INFO - Email alerting: attempt 1
[2021-10-26 17:43:21,455] {configuration.py:381} WARNING - section/key [smtp/smtp_user] not found in config
[2021-10-26 17:43:21,457] {email.py:208} INFO - Email alerting: attempt 1
[2021-10-26 17:43:21,460] {taskinstance.py:1739} ERROR - Failed to send email to: ['octadelsueldo@gmail.com']
Traceback (most recent call last):
  File "/home/airflow/.local/lib/python3.6/site-packages/airflow/models/taskinstance.py", line 1324, in _run_raw_task
    self._execute_task_with_callbacks(context)
  File "/home/airflow/.local/lib/python3.6/site-packages/airflow/models/taskinstance.py", line 1443, in _execute_task_with_callbacks
    result = self._execute_task(context, self.task)
  File "/home/airflow/.local/lib/python3.6/site-packages/airflow/models/taskinstance.py", line 1499, in _execute_task
    result = execute_callable(context=context)
  File "/home/airflow/.local/lib/python3.6/site-packages/airflow/operators/bash.py", line 188, in execute
    f'Bash command failed. The command returned a non-zero exit code {result.exit_code}.'
airflow.exceptions.AirflowException: Bash command failed. The command returned a non-zero exit code 127.

During handling of the above exception, another exception occurred:

Traceback (most recent call last):
  File "/home/airflow/.local/lib/python3.6/site-packages/airflow/models/taskinstance.py", line 2189, in email_alert
    send_email(self.task.email, subject, html_content)
  File "/home/airflow/.local/lib/python3.6/site-packages/airflow/utils/email.py", line 66, in send_email
    **kwargs,
  File "/home/airflow/.local/lib/python3.6/site-packages/airflow/utils/email.py", line 102, in send_email_smtp
    send_mime_email(e_from=smtp_mail_from, e_to=recipients, mime_msg=msg, conn_id=conn_id, dryrun=dryrun)
  File "/home/airflow/.local/lib/python3.6/site-packages/airflow/utils/email.py", line 210, in send_mime_email
    conn = _get_smtp_connection(smtp_host, smtp_port, smtp_timeout, smtp_ssl)
  File "/home/airflow/.local/lib/python3.6/site-packages/airflow/utils/email.py", line 244, in _get_smtp_connection
    else smtplib.SMTP(host=host, port=port, timeout=timeout)
  File "/usr/local/lib/python3.6/smtplib.py", line 251, in __init__
    (code, msg) = self.connect(host, port)
  File "/usr/local/lib/python3.6/smtplib.py", line 336, in connect
    self.sock = self._get_socket(host, port, self.timeout)
  File "/usr/local/lib/python3.6/smtplib.py", line 307, in _get_socket
    self.source_address)
  File "/usr/local/lib/python3.6/socket.py", line 724, in create_connection
    raise err
  File "/usr/local/lib/python3.6/socket.py", line 713, in create_connection
    sock.connect(sa)
OSError: [Errno 99] Cannot assign requested address

During handling of the above exception, another exception occurred:

Traceback (most recent call last):
  File "/home/airflow/.local/lib/python3.6/site-packages/airflow/models/taskinstance.py", line 1737, in handle_failure
    self.email_alert(error)
  File "/home/airflow/.local/lib/python3.6/site-packages/airflow/models/taskinstance.py", line 2191, in email_alert
    send_email(self.task.email, subject, html_content_err)
  File "/home/airflow/.local/lib/python3.6/site-packages/airflow/utils/email.py", line 66, in send_email
    **kwargs,
  File "/home/airflow/.local/lib/python3.6/site-packages/airflow/utils/email.py", line 102, in send_email_smtp
    send_mime_email(e_from=smtp_mail_from, e_to=recipients, mime_msg=msg, conn_id=conn_id, dryrun=dryrun)
  File "/home/airflow/.local/lib/python3.6/site-packages/airflow/utils/email.py", line 210, in send_mime_email
    conn = _get_smtp_connection(smtp_host, smtp_port, smtp_timeout, smtp_ssl)
  File "/home/airflow/.local/lib/python3.6/site-packages/airflow/utils/email.py", line 244, in _get_smtp_connection
    else smtplib.SMTP(host=host, port=port, timeout=timeout)
  File "/usr/local/lib/python3.6/smtplib.py", line 251, in __init__
    (code, msg) = self.connect(host, port)
  File "/usr/local/lib/python3.6/smtplib.py", line 336, in connect
    self.sock = self._get_socket(host, port, self.timeout)
  File "/usr/local/lib/python3.6/smtplib.py", line 307, in _get_socket
    self.source_address)
  File "/usr/local/lib/python3.6/socket.py", line 724, in create_connection
    raise err
  File "/usr/local/lib/python3.6/socket.py", line 713, in create_connection
    sock.connect(sa)
OSError: [Errno 99] Cannot assign requested address
[2021-10-26 17:43:21,491] {standard_task_runner.py:91} ERROR - Failed to execute job 27 for task spider_star
Traceback (most recent call last):
  File "/home/airflow/.local/lib/python3.6/site-packages/airflow/task/task_runner/standard_task_runner.py", line 85, in _start_by_fork
    args.func(args, dag=self.dag)
  File "/home/airflow/.local/lib/python3.6/site-packages/airflow/cli/cli_parser.py", line 48, in command
    return func(*args, **kwargs)
  File "/home/airflow/.local/lib/python3.6/site-packages/airflow/utils/cli.py", line 92, in wrapper
    return f(*args, **kwargs)
  File "/home/airflow/.local/lib/python3.6/site-packages/airflow/cli/commands/task_command.py", line 292, in task_run
    _run_task_by_selected_method(args, dag, ti)
  File "/home/airflow/.local/lib/python3.6/site-packages/airflow/cli/commands/task_command.py", line 107, in _run_task_by_selected_method
    _run_raw_task(args, ti)
  File "/home/airflow/.local/lib/python3.6/site-packages/airflow/cli/commands/task_command.py", line 184, in _run_raw_task
    error_file=args.error_file,
  File "/home/airflow/.local/lib/python3.6/site-packages/airflow/utils/session.py", line 70, in wrapper
    return func(*args, session=session, **kwargs)
  File "/home/airflow/.local/lib/python3.6/site-packages/airflow/models/taskinstance.py", line 1324, in _run_raw_task
    self._execute_task_with_callbacks(context)
  File "/home/airflow/.local/lib/python3.6/site-packages/airflow/models/taskinstance.py", line 1443, in _execute_task_with_callbacks
    result = self._execute_task(context, self.task)
  File "/home/airflow/.local/lib/python3.6/site-packages/airflow/models/taskinstance.py", line 1499, in _execute_task
    result = execute_callable(context=context)
  File "/home/airflow/.local/lib/python3.6/site-packages/airflow/operators/bash.py", line 188, in execute
    f'Bash command failed. The command returned a non-zero exit code {result.exit_code}.'
airflow.exceptions.AirflowException: Bash command failed. The command returned a non-zero exit code 127.
[2021-10-26 17:43:21,548] {local_task_job.py:154} INFO - Task exited with return code 1
[2021-10-26 17:43:21,638] {local_task_job.py:264} INFO - 0 downstream tasks scheduled from follow-on schedule check
[2021-10-26 17:50:15,866] {taskinstance.py:1035} INFO - Dependencies all met for <TaskInstance: scrapper.spider_star manual__2021-10-26T17:50:13.477837+00:00 [queued]>
[2021-10-26 17:50:15,900] {taskinstance.py:1035} INFO - Dependencies all met for <TaskInstance: scrapper.spider_star manual__2021-10-26T17:50:13.477837+00:00 [queued]>
[2021-10-26 17:50:15,902] {taskinstance.py:1241} INFO - 
--------------------------------------------------------------------------------
[2021-10-26 17:50:15,904] {taskinstance.py:1242} INFO - Starting attempt 1 of 2
[2021-10-26 17:50:15,906] {taskinstance.py:1243} INFO - 
--------------------------------------------------------------------------------
[2021-10-26 17:50:15,945] {taskinstance.py:1262} INFO - Executing <Task(BashOperator): spider_star> on 2021-10-26 17:50:13.477837+00:00
[2021-10-26 17:50:15,961] {standard_task_runner.py:52} INFO - Started process 14277 to run task
[2021-10-26 17:50:16,004] {standard_task_runner.py:76} INFO - Running: ['***', 'tasks', 'run', 'scrapper', 'spider_star', 'manual__2021-10-26T17:50:13.477837+00:00', '--job-id', '29', '--raw', '--subdir', 'DAGS_FOLDER/my_dag.py', '--cfg-path', '/tmp/tmp2q4u7507', '--error-file', '/tmp/tmpmb4jhq39']
[2021-10-26 17:50:16,024] {standard_task_runner.py:77} INFO - Job 29: Subtask spider_star
[2021-10-26 17:50:16,263] {logging_mixin.py:109} INFO - Running <TaskInstance: scrapper.spider_star manual__2021-10-26T17:50:13.477837+00:00 [running]> on host ebc91b274482
[2021-10-26 17:50:16,487] {taskinstance.py:1414} INFO - Exporting the following env vars:
AIRFLOW_CTX_DAG_EMAIL=octadelsueldo@gmail.com
AIRFLOW_CTX_DAG_OWNER=Octavio
AIRFLOW_CTX_DAG_ID=scrapper
AIRFLOW_CTX_TASK_ID=spider_star
AIRFLOW_CTX_EXECUTION_DATE=2021-10-26T17:50:13.477837+00:00
AIRFLOW_CTX_DAG_RUN_ID=manual__2021-10-26T17:50:13.477837+00:00
[2021-10-26 17:50:16,491] {subprocess.py:62} INFO - Tmp dir root location: 
 /tmp
[2021-10-26 17:50:16,496] {subprocess.py:74} INFO - Running command: ['bash', '-c', 'cd ./***/dags/script/run_spider.sh ']
[2021-10-26 17:50:16,527] {subprocess.py:85} INFO - Output:
[2021-10-26 17:50:16,531] {subprocess.py:89} INFO - bash: line 0: cd: ./***/dags/script/run_spider.sh: No such file or directory
[2021-10-26 17:50:16,534] {subprocess.py:93} INFO - Command exited with return code 1
[2021-10-26 17:50:16,551] {taskinstance.py:1686} ERROR - Task failed with exception
Traceback (most recent call last):
  File "/home/airflow/.local/lib/python3.6/site-packages/airflow/models/taskinstance.py", line 1324, in _run_raw_task
    self._execute_task_with_callbacks(context)
  File "/home/airflow/.local/lib/python3.6/site-packages/airflow/models/taskinstance.py", line 1443, in _execute_task_with_callbacks
    result = self._execute_task(context, self.task)
  File "/home/airflow/.local/lib/python3.6/site-packages/airflow/models/taskinstance.py", line 1499, in _execute_task
    result = execute_callable(context=context)
  File "/home/airflow/.local/lib/python3.6/site-packages/airflow/operators/bash.py", line 188, in execute
    f'Bash command failed. The command returned a non-zero exit code {result.exit_code}.'
airflow.exceptions.AirflowException: Bash command failed. The command returned a non-zero exit code 1.
[2021-10-26 17:50:16,599] {taskinstance.py:1280} INFO - Marking task as UP_FOR_RETRY. dag_id=scrapper, task_id=spider_star, execution_date=20211026T175013, start_date=20211026T175015, end_date=20211026T175016
[2021-10-26 17:50:16,680] {warnings.py:99} WARNING - /home/***/.local/lib/python3.6/site-packages/***/utils/email.py:102: PendingDeprecationWarning: Fetching SMTP credentials from configuration variables will be deprecated in a future release. Please set credentials using a connection instead.
  send_mime_email(e_from=smtp_mail_from, e_to=recipients, mime_msg=msg, conn_id=conn_id, dryrun=dryrun)

[2021-10-26 17:50:16,687] {configuration.py:381} WARNING - section/key [smtp/smtp_user] not found in config
[2021-10-26 17:50:16,688] {email.py:208} INFO - Email alerting: attempt 1
[2021-10-26 17:50:16,723] {configuration.py:381} WARNING - section/key [smtp/smtp_user] not found in config
[2021-10-26 17:50:16,725] {email.py:208} INFO - Email alerting: attempt 1
[2021-10-26 17:50:16,731] {taskinstance.py:1739} ERROR - Failed to send email to: ['octadelsueldo@gmail.com']
Traceback (most recent call last):
  File "/home/airflow/.local/lib/python3.6/site-packages/airflow/models/taskinstance.py", line 1324, in _run_raw_task
    self._execute_task_with_callbacks(context)
  File "/home/airflow/.local/lib/python3.6/site-packages/airflow/models/taskinstance.py", line 1443, in _execute_task_with_callbacks
    result = self._execute_task(context, self.task)
  File "/home/airflow/.local/lib/python3.6/site-packages/airflow/models/taskinstance.py", line 1499, in _execute_task
    result = execute_callable(context=context)
  File "/home/airflow/.local/lib/python3.6/site-packages/airflow/operators/bash.py", line 188, in execute
    f'Bash command failed. The command returned a non-zero exit code {result.exit_code}.'
airflow.exceptions.AirflowException: Bash command failed. The command returned a non-zero exit code 1.

During handling of the above exception, another exception occurred:

Traceback (most recent call last):
  File "/home/airflow/.local/lib/python3.6/site-packages/airflow/models/taskinstance.py", line 2189, in email_alert
    send_email(self.task.email, subject, html_content)
  File "/home/airflow/.local/lib/python3.6/site-packages/airflow/utils/email.py", line 66, in send_email
    **kwargs,
  File "/home/airflow/.local/lib/python3.6/site-packages/airflow/utils/email.py", line 102, in send_email_smtp
    send_mime_email(e_from=smtp_mail_from, e_to=recipients, mime_msg=msg, conn_id=conn_id, dryrun=dryrun)
  File "/home/airflow/.local/lib/python3.6/site-packages/airflow/utils/email.py", line 210, in send_mime_email
    conn = _get_smtp_connection(smtp_host, smtp_port, smtp_timeout, smtp_ssl)
  File "/home/airflow/.local/lib/python3.6/site-packages/airflow/utils/email.py", line 244, in _get_smtp_connection
    else smtplib.SMTP(host=host, port=port, timeout=timeout)
  File "/usr/local/lib/python3.6/smtplib.py", line 251, in __init__
    (code, msg) = self.connect(host, port)
  File "/usr/local/lib/python3.6/smtplib.py", line 336, in connect
    self.sock = self._get_socket(host, port, self.timeout)
  File "/usr/local/lib/python3.6/smtplib.py", line 307, in _get_socket
    self.source_address)
  File "/usr/local/lib/python3.6/socket.py", line 724, in create_connection
    raise err
  File "/usr/local/lib/python3.6/socket.py", line 713, in create_connection
    sock.connect(sa)
OSError: [Errno 99] Cannot assign requested address

During handling of the above exception, another exception occurred:

Traceback (most recent call last):
  File "/home/airflow/.local/lib/python3.6/site-packages/airflow/models/taskinstance.py", line 1737, in handle_failure
    self.email_alert(error)
  File "/home/airflow/.local/lib/python3.6/site-packages/airflow/models/taskinstance.py", line 2191, in email_alert
    send_email(self.task.email, subject, html_content_err)
  File "/home/airflow/.local/lib/python3.6/site-packages/airflow/utils/email.py", line 66, in send_email
    **kwargs,
  File "/home/airflow/.local/lib/python3.6/site-packages/airflow/utils/email.py", line 102, in send_email_smtp
    send_mime_email(e_from=smtp_mail_from, e_to=recipients, mime_msg=msg, conn_id=conn_id, dryrun=dryrun)
  File "/home/airflow/.local/lib/python3.6/site-packages/airflow/utils/email.py", line 210, in send_mime_email
    conn = _get_smtp_connection(smtp_host, smtp_port, smtp_timeout, smtp_ssl)
  File "/home/airflow/.local/lib/python3.6/site-packages/airflow/utils/email.py", line 244, in _get_smtp_connection
    else smtplib.SMTP(host=host, port=port, timeout=timeout)
  File "/usr/local/lib/python3.6/smtplib.py", line 251, in __init__
    (code, msg) = self.connect(host, port)
  File "/usr/local/lib/python3.6/smtplib.py", line 336, in connect
    self.sock = self._get_socket(host, port, self.timeout)
  File "/usr/local/lib/python3.6/smtplib.py", line 307, in _get_socket
    self.source_address)
  File "/usr/local/lib/python3.6/socket.py", line 724, in create_connection
    raise err
  File "/usr/local/lib/python3.6/socket.py", line 713, in create_connection
    sock.connect(sa)
OSError: [Errno 99] Cannot assign requested address
[2021-10-26 17:50:16,781] {standard_task_runner.py:91} ERROR - Failed to execute job 29 for task spider_star
Traceback (most recent call last):
  File "/home/airflow/.local/lib/python3.6/site-packages/airflow/task/task_runner/standard_task_runner.py", line 85, in _start_by_fork
    args.func(args, dag=self.dag)
  File "/home/airflow/.local/lib/python3.6/site-packages/airflow/cli/cli_parser.py", line 48, in command
    return func(*args, **kwargs)
  File "/home/airflow/.local/lib/python3.6/site-packages/airflow/utils/cli.py", line 92, in wrapper
    return f(*args, **kwargs)
  File "/home/airflow/.local/lib/python3.6/site-packages/airflow/cli/commands/task_command.py", line 292, in task_run
    _run_task_by_selected_method(args, dag, ti)
  File "/home/airflow/.local/lib/python3.6/site-packages/airflow/cli/commands/task_command.py", line 107, in _run_task_by_selected_method
    _run_raw_task(args, ti)
  File "/home/airflow/.local/lib/python3.6/site-packages/airflow/cli/commands/task_command.py", line 184, in _run_raw_task
    error_file=args.error_file,
  File "/home/airflow/.local/lib/python3.6/site-packages/airflow/utils/session.py", line 70, in wrapper
    return func(*args, session=session, **kwargs)
  File "/home/airflow/.local/lib/python3.6/site-packages/airflow/models/taskinstance.py", line 1324, in _run_raw_task
    self._execute_task_with_callbacks(context)
  File "/home/airflow/.local/lib/python3.6/site-packages/airflow/models/taskinstance.py", line 1443, in _execute_task_with_callbacks
    result = self._execute_task(context, self.task)
  File "/home/airflow/.local/lib/python3.6/site-packages/airflow/models/taskinstance.py", line 1499, in _execute_task
    result = execute_callable(context=context)
  File "/home/airflow/.local/lib/python3.6/site-packages/airflow/operators/bash.py", line 188, in execute
    f'Bash command failed. The command returned a non-zero exit code {result.exit_code}.'
airflow.exceptions.AirflowException: Bash command failed. The command returned a non-zero exit code 1.
[2021-10-26 17:50:16,834] {local_task_job.py:154} INFO - Task exited with return code 1
[2021-10-26 17:50:16,896] {local_task_job.py:264} INFO - 0 downstream tasks scheduled from follow-on schedule check
[2021-10-26 18:03:01,883] {taskinstance.py:1035} INFO - Dependencies all met for <TaskInstance: scrapper.spider_star manual__2021-10-26T18:02:58.521063+00:00 [queued]>
[2021-10-26 18:03:01,931] {taskinstance.py:1035} INFO - Dependencies all met for <TaskInstance: scrapper.spider_star manual__2021-10-26T18:02:58.521063+00:00 [queued]>
[2021-10-26 18:03:01,932] {taskinstance.py:1241} INFO - 
--------------------------------------------------------------------------------
[2021-10-26 18:03:01,933] {taskinstance.py:1242} INFO - Starting attempt 1 of 2
[2021-10-26 18:03:01,934] {taskinstance.py:1243} INFO - 
--------------------------------------------------------------------------------
[2021-10-26 18:03:01,961] {taskinstance.py:1262} INFO - Executing <Task(BashOperator): spider_star> on 2021-10-26 18:02:58.521063+00:00
[2021-10-26 18:03:01,977] {standard_task_runner.py:52} INFO - Started process 14868 to run task
[2021-10-26 18:03:01,984] {standard_task_runner.py:76} INFO - Running: ['***', 'tasks', 'run', 'scrapper', 'spider_star', 'manual__2021-10-26T18:02:58.521063+00:00', '--job-id', '31', '--raw', '--subdir', 'DAGS_FOLDER/my_dag.py', '--cfg-path', '/tmp/tmpv9fsc6_r', '--error-file', '/tmp/tmp1icn_8yw']
[2021-10-26 18:03:01,992] {standard_task_runner.py:77} INFO - Job 31: Subtask spider_star
[2021-10-26 18:03:02,178] {logging_mixin.py:109} INFO - Running <TaskInstance: scrapper.spider_star manual__2021-10-26T18:02:58.521063+00:00 [running]> on host ebc91b274482
[2021-10-26 18:03:02,393] {taskinstance.py:1414} INFO - Exporting the following env vars:
AIRFLOW_CTX_DAG_EMAIL=octadelsueldo@gmail.com
AIRFLOW_CTX_DAG_OWNER=Octavio
AIRFLOW_CTX_DAG_ID=scrapper
AIRFLOW_CTX_TASK_ID=spider_star
AIRFLOW_CTX_EXECUTION_DATE=2021-10-26T18:02:58.521063+00:00
AIRFLOW_CTX_DAG_RUN_ID=manual__2021-10-26T18:02:58.521063+00:00
[2021-10-26 18:03:02,396] {subprocess.py:62} INFO - Tmp dir root location: 
 /tmp
[2021-10-26 18:03:02,401] {subprocess.py:74} INFO - Running command: ['bash', '-c', 'cd /dags/script/run_spider.sh ']
[2021-10-26 18:03:02,428] {subprocess.py:85} INFO - Output:
[2021-10-26 18:03:02,444] {subprocess.py:89} INFO - bash: line 0: cd: /dags/script/run_spider.sh: No such file or directory
[2021-10-26 18:03:02,449] {subprocess.py:93} INFO - Command exited with return code 1
[2021-10-26 18:03:02,467] {taskinstance.py:1686} ERROR - Task failed with exception
Traceback (most recent call last):
  File "/home/airflow/.local/lib/python3.6/site-packages/airflow/models/taskinstance.py", line 1324, in _run_raw_task
    self._execute_task_with_callbacks(context)
  File "/home/airflow/.local/lib/python3.6/site-packages/airflow/models/taskinstance.py", line 1443, in _execute_task_with_callbacks
    result = self._execute_task(context, self.task)
  File "/home/airflow/.local/lib/python3.6/site-packages/airflow/models/taskinstance.py", line 1499, in _execute_task
    result = execute_callable(context=context)
  File "/home/airflow/.local/lib/python3.6/site-packages/airflow/operators/bash.py", line 188, in execute
    f'Bash command failed. The command returned a non-zero exit code {result.exit_code}.'
airflow.exceptions.AirflowException: Bash command failed. The command returned a non-zero exit code 1.
[2021-10-26 18:03:02,539] {taskinstance.py:1280} INFO - Marking task as UP_FOR_RETRY. dag_id=scrapper, task_id=spider_star, execution_date=20211026T180258, start_date=20211026T180301, end_date=20211026T180302
[2021-10-26 18:03:02,591] {warnings.py:99} WARNING - /home/***/.local/lib/python3.6/site-packages/***/utils/email.py:102: PendingDeprecationWarning: Fetching SMTP credentials from configuration variables will be deprecated in a future release. Please set credentials using a connection instead.
  send_mime_email(e_from=smtp_mail_from, e_to=recipients, mime_msg=msg, conn_id=conn_id, dryrun=dryrun)

[2021-10-26 18:03:02,597] {configuration.py:381} WARNING - section/key [smtp/smtp_user] not found in config
[2021-10-26 18:03:02,600] {email.py:208} INFO - Email alerting: attempt 1
[2021-10-26 18:03:02,657] {configuration.py:381} WARNING - section/key [smtp/smtp_user] not found in config
[2021-10-26 18:03:02,660] {email.py:208} INFO - Email alerting: attempt 1
[2021-10-26 18:03:02,667] {taskinstance.py:1739} ERROR - Failed to send email to: ['octadelsueldo@gmail.com']
Traceback (most recent call last):
  File "/home/airflow/.local/lib/python3.6/site-packages/airflow/models/taskinstance.py", line 1324, in _run_raw_task
    self._execute_task_with_callbacks(context)
  File "/home/airflow/.local/lib/python3.6/site-packages/airflow/models/taskinstance.py", line 1443, in _execute_task_with_callbacks
    result = self._execute_task(context, self.task)
  File "/home/airflow/.local/lib/python3.6/site-packages/airflow/models/taskinstance.py", line 1499, in _execute_task
    result = execute_callable(context=context)
  File "/home/airflow/.local/lib/python3.6/site-packages/airflow/operators/bash.py", line 188, in execute
    f'Bash command failed. The command returned a non-zero exit code {result.exit_code}.'
airflow.exceptions.AirflowException: Bash command failed. The command returned a non-zero exit code 1.

During handling of the above exception, another exception occurred:

Traceback (most recent call last):
  File "/home/airflow/.local/lib/python3.6/site-packages/airflow/models/taskinstance.py", line 2189, in email_alert
    send_email(self.task.email, subject, html_content)
  File "/home/airflow/.local/lib/python3.6/site-packages/airflow/utils/email.py", line 66, in send_email
    **kwargs,
  File "/home/airflow/.local/lib/python3.6/site-packages/airflow/utils/email.py", line 102, in send_email_smtp
    send_mime_email(e_from=smtp_mail_from, e_to=recipients, mime_msg=msg, conn_id=conn_id, dryrun=dryrun)
  File "/home/airflow/.local/lib/python3.6/site-packages/airflow/utils/email.py", line 210, in send_mime_email
    conn = _get_smtp_connection(smtp_host, smtp_port, smtp_timeout, smtp_ssl)
  File "/home/airflow/.local/lib/python3.6/site-packages/airflow/utils/email.py", line 244, in _get_smtp_connection
    else smtplib.SMTP(host=host, port=port, timeout=timeout)
  File "/usr/local/lib/python3.6/smtplib.py", line 251, in __init__
    (code, msg) = self.connect(host, port)
  File "/usr/local/lib/python3.6/smtplib.py", line 336, in connect
    self.sock = self._get_socket(host, port, self.timeout)
  File "/usr/local/lib/python3.6/smtplib.py", line 307, in _get_socket
    self.source_address)
  File "/usr/local/lib/python3.6/socket.py", line 724, in create_connection
    raise err
  File "/usr/local/lib/python3.6/socket.py", line 713, in create_connection
    sock.connect(sa)
OSError: [Errno 99] Cannot assign requested address

During handling of the above exception, another exception occurred:

Traceback (most recent call last):
  File "/home/airflow/.local/lib/python3.6/site-packages/airflow/models/taskinstance.py", line 1737, in handle_failure
    self.email_alert(error)
  File "/home/airflow/.local/lib/python3.6/site-packages/airflow/models/taskinstance.py", line 2191, in email_alert
    send_email(self.task.email, subject, html_content_err)
  File "/home/airflow/.local/lib/python3.6/site-packages/airflow/utils/email.py", line 66, in send_email
    **kwargs,
  File "/home/airflow/.local/lib/python3.6/site-packages/airflow/utils/email.py", line 102, in send_email_smtp
    send_mime_email(e_from=smtp_mail_from, e_to=recipients, mime_msg=msg, conn_id=conn_id, dryrun=dryrun)
  File "/home/airflow/.local/lib/python3.6/site-packages/airflow/utils/email.py", line 210, in send_mime_email
    conn = _get_smtp_connection(smtp_host, smtp_port, smtp_timeout, smtp_ssl)
  File "/home/airflow/.local/lib/python3.6/site-packages/airflow/utils/email.py", line 244, in _get_smtp_connection
    else smtplib.SMTP(host=host, port=port, timeout=timeout)
  File "/usr/local/lib/python3.6/smtplib.py", line 251, in __init__
    (code, msg) = self.connect(host, port)
  File "/usr/local/lib/python3.6/smtplib.py", line 336, in connect
    self.sock = self._get_socket(host, port, self.timeout)
  File "/usr/local/lib/python3.6/smtplib.py", line 307, in _get_socket
    self.source_address)
  File "/usr/local/lib/python3.6/socket.py", line 724, in create_connection
    raise err
  File "/usr/local/lib/python3.6/socket.py", line 713, in create_connection
    sock.connect(sa)
OSError: [Errno 99] Cannot assign requested address
[2021-10-26 18:03:02,773] {standard_task_runner.py:91} ERROR - Failed to execute job 31 for task spider_star
Traceback (most recent call last):
  File "/home/airflow/.local/lib/python3.6/site-packages/airflow/task/task_runner/standard_task_runner.py", line 85, in _start_by_fork
    args.func(args, dag=self.dag)
  File "/home/airflow/.local/lib/python3.6/site-packages/airflow/cli/cli_parser.py", line 48, in command
    return func(*args, **kwargs)
  File "/home/airflow/.local/lib/python3.6/site-packages/airflow/utils/cli.py", line 92, in wrapper
    return f(*args, **kwargs)
  File "/home/airflow/.local/lib/python3.6/site-packages/airflow/cli/commands/task_command.py", line 292, in task_run
    _run_task_by_selected_method(args, dag, ti)
  File "/home/airflow/.local/lib/python3.6/site-packages/airflow/cli/commands/task_command.py", line 107, in _run_task_by_selected_method
    _run_raw_task(args, ti)
  File "/home/airflow/.local/lib/python3.6/site-packages/airflow/cli/commands/task_command.py", line 184, in _run_raw_task
    error_file=args.error_file,
  File "/home/airflow/.local/lib/python3.6/site-packages/airflow/utils/session.py", line 70, in wrapper
    return func(*args, session=session, **kwargs)
  File "/home/airflow/.local/lib/python3.6/site-packages/airflow/models/taskinstance.py", line 1324, in _run_raw_task
    self._execute_task_with_callbacks(context)
  File "/home/airflow/.local/lib/python3.6/site-packages/airflow/models/taskinstance.py", line 1443, in _execute_task_with_callbacks
    result = self._execute_task(context, self.task)
  File "/home/airflow/.local/lib/python3.6/site-packages/airflow/models/taskinstance.py", line 1499, in _execute_task
    result = execute_callable(context=context)
  File "/home/airflow/.local/lib/python3.6/site-packages/airflow/operators/bash.py", line 188, in execute
    f'Bash command failed. The command returned a non-zero exit code {result.exit_code}.'
airflow.exceptions.AirflowException: Bash command failed. The command returned a non-zero exit code 1.
[2021-10-26 18:03:02,884] {local_task_job.py:154} INFO - Task exited with return code 1
[2021-10-26 18:03:02,984] {local_task_job.py:264} INFO - 0 downstream tasks scheduled from follow-on schedule check
[2021-10-26 18:07:27,516] {taskinstance.py:1035} INFO - Dependencies all met for <TaskInstance: scrapper.spider_star manual__2021-10-26T18:07:25.439643+00:00 [queued]>
[2021-10-26 18:07:27,562] {taskinstance.py:1035} INFO - Dependencies all met for <TaskInstance: scrapper.spider_star manual__2021-10-26T18:07:25.439643+00:00 [queued]>
[2021-10-26 18:07:27,565] {taskinstance.py:1241} INFO - 
--------------------------------------------------------------------------------
[2021-10-26 18:07:27,566] {taskinstance.py:1242} INFO - Starting attempt 1 of 2
[2021-10-26 18:07:27,571] {taskinstance.py:1243} INFO - 
--------------------------------------------------------------------------------
[2021-10-26 18:07:27,614] {taskinstance.py:1262} INFO - Executing <Task(BashOperator): spider_star> on 2021-10-26 18:07:25.439643+00:00
[2021-10-26 18:07:27,647] {standard_task_runner.py:76} INFO - Running: ['***', 'tasks', 'run', 'scrapper', 'spider_star', 'manual__2021-10-26T18:07:25.439643+00:00', '--job-id', '32', '--raw', '--subdir', 'DAGS_FOLDER/my_dag.py', '--cfg-path', '/tmp/tmp602ejy4e', '--error-file', '/tmp/tmpmd0e0c7n']
[2021-10-26 18:07:27,653] {standard_task_runner.py:77} INFO - Job 32: Subtask spider_star
[2021-10-26 18:07:27,626] {standard_task_runner.py:52} INFO - Started process 15037 to run task
[2021-10-26 18:07:27,798] {logging_mixin.py:109} INFO - Running <TaskInstance: scrapper.spider_star manual__2021-10-26T18:07:25.439643+00:00 [running]> on host ebc91b274482
[2021-10-26 18:07:27,912] {taskinstance.py:1414} INFO - Exporting the following env vars:
AIRFLOW_CTX_DAG_EMAIL=octadelsueldo@gmail.com
AIRFLOW_CTX_DAG_OWNER=Octavio
AIRFLOW_CTX_DAG_ID=scrapper
AIRFLOW_CTX_TASK_ID=spider_star
AIRFLOW_CTX_EXECUTION_DATE=2021-10-26T18:07:25.439643+00:00
AIRFLOW_CTX_DAG_RUN_ID=manual__2021-10-26T18:07:25.439643+00:00
[2021-10-26 18:07:27,916] {subprocess.py:62} INFO - Tmp dir root location: 
 /tmp
[2021-10-26 18:07:27,918] {subprocess.py:74} INFO - Running command: ['bash', '-c', '/dags/script/run_spider.sh ']
[2021-10-26 18:07:27,937] {subprocess.py:85} INFO - Output:
[2021-10-26 18:07:27,939] {subprocess.py:89} INFO - bash: /dags/script/run_spider.sh: No such file or directory
[2021-10-26 18:07:27,942] {subprocess.py:93} INFO - Command exited with return code 127
[2021-10-26 18:07:27,955] {taskinstance.py:1686} ERROR - Task failed with exception
Traceback (most recent call last):
  File "/home/airflow/.local/lib/python3.6/site-packages/airflow/models/taskinstance.py", line 1324, in _run_raw_task
    self._execute_task_with_callbacks(context)
  File "/home/airflow/.local/lib/python3.6/site-packages/airflow/models/taskinstance.py", line 1443, in _execute_task_with_callbacks
    result = self._execute_task(context, self.task)
  File "/home/airflow/.local/lib/python3.6/site-packages/airflow/models/taskinstance.py", line 1499, in _execute_task
    result = execute_callable(context=context)
  File "/home/airflow/.local/lib/python3.6/site-packages/airflow/operators/bash.py", line 188, in execute
    f'Bash command failed. The command returned a non-zero exit code {result.exit_code}.'
airflow.exceptions.AirflowException: Bash command failed. The command returned a non-zero exit code 127.
[2021-10-26 18:07:27,983] {taskinstance.py:1280} INFO - Marking task as UP_FOR_RETRY. dag_id=scrapper, task_id=spider_star, execution_date=20211026T180725, start_date=20211026T180727, end_date=20211026T180727
[2021-10-26 18:07:28,004] {warnings.py:99} WARNING - /home/***/.local/lib/python3.6/site-packages/***/utils/email.py:102: PendingDeprecationWarning: Fetching SMTP credentials from configuration variables will be deprecated in a future release. Please set credentials using a connection instead.
  send_mime_email(e_from=smtp_mail_from, e_to=recipients, mime_msg=msg, conn_id=conn_id, dryrun=dryrun)

[2021-10-26 18:07:28,006] {configuration.py:381} WARNING - section/key [smtp/smtp_user] not found in config
[2021-10-26 18:07:28,008] {email.py:208} INFO - Email alerting: attempt 1
[2021-10-26 18:07:28,024] {configuration.py:381} WARNING - section/key [smtp/smtp_user] not found in config
[2021-10-26 18:07:28,025] {email.py:208} INFO - Email alerting: attempt 1
[2021-10-26 18:07:28,026] {taskinstance.py:1739} ERROR - Failed to send email to: ['octadelsueldo@gmail.com']
Traceback (most recent call last):
  File "/home/airflow/.local/lib/python3.6/site-packages/airflow/models/taskinstance.py", line 1324, in _run_raw_task
    self._execute_task_with_callbacks(context)
  File "/home/airflow/.local/lib/python3.6/site-packages/airflow/models/taskinstance.py", line 1443, in _execute_task_with_callbacks
    result = self._execute_task(context, self.task)
  File "/home/airflow/.local/lib/python3.6/site-packages/airflow/models/taskinstance.py", line 1499, in _execute_task
    result = execute_callable(context=context)
  File "/home/airflow/.local/lib/python3.6/site-packages/airflow/operators/bash.py", line 188, in execute
    f'Bash command failed. The command returned a non-zero exit code {result.exit_code}.'
airflow.exceptions.AirflowException: Bash command failed. The command returned a non-zero exit code 127.

During handling of the above exception, another exception occurred:

Traceback (most recent call last):
  File "/home/airflow/.local/lib/python3.6/site-packages/airflow/models/taskinstance.py", line 2189, in email_alert
    send_email(self.task.email, subject, html_content)
  File "/home/airflow/.local/lib/python3.6/site-packages/airflow/utils/email.py", line 66, in send_email
    **kwargs,
  File "/home/airflow/.local/lib/python3.6/site-packages/airflow/utils/email.py", line 102, in send_email_smtp
    send_mime_email(e_from=smtp_mail_from, e_to=recipients, mime_msg=msg, conn_id=conn_id, dryrun=dryrun)
  File "/home/airflow/.local/lib/python3.6/site-packages/airflow/utils/email.py", line 210, in send_mime_email
    conn = _get_smtp_connection(smtp_host, smtp_port, smtp_timeout, smtp_ssl)
  File "/home/airflow/.local/lib/python3.6/site-packages/airflow/utils/email.py", line 244, in _get_smtp_connection
    else smtplib.SMTP(host=host, port=port, timeout=timeout)
  File "/usr/local/lib/python3.6/smtplib.py", line 251, in __init__
    (code, msg) = self.connect(host, port)
  File "/usr/local/lib/python3.6/smtplib.py", line 336, in connect
    self.sock = self._get_socket(host, port, self.timeout)
  File "/usr/local/lib/python3.6/smtplib.py", line 307, in _get_socket
    self.source_address)
  File "/usr/local/lib/python3.6/socket.py", line 724, in create_connection
    raise err
  File "/usr/local/lib/python3.6/socket.py", line 713, in create_connection
    sock.connect(sa)
OSError: [Errno 99] Cannot assign requested address

During handling of the above exception, another exception occurred:

Traceback (most recent call last):
  File "/home/airflow/.local/lib/python3.6/site-packages/airflow/models/taskinstance.py", line 1737, in handle_failure
    self.email_alert(error)
  File "/home/airflow/.local/lib/python3.6/site-packages/airflow/models/taskinstance.py", line 2191, in email_alert
    send_email(self.task.email, subject, html_content_err)
  File "/home/airflow/.local/lib/python3.6/site-packages/airflow/utils/email.py", line 66, in send_email
    **kwargs,
  File "/home/airflow/.local/lib/python3.6/site-packages/airflow/utils/email.py", line 102, in send_email_smtp
    send_mime_email(e_from=smtp_mail_from, e_to=recipients, mime_msg=msg, conn_id=conn_id, dryrun=dryrun)
  File "/home/airflow/.local/lib/python3.6/site-packages/airflow/utils/email.py", line 210, in send_mime_email
    conn = _get_smtp_connection(smtp_host, smtp_port, smtp_timeout, smtp_ssl)
  File "/home/airflow/.local/lib/python3.6/site-packages/airflow/utils/email.py", line 244, in _get_smtp_connection
    else smtplib.SMTP(host=host, port=port, timeout=timeout)
  File "/usr/local/lib/python3.6/smtplib.py", line 251, in __init__
    (code, msg) = self.connect(host, port)
  File "/usr/local/lib/python3.6/smtplib.py", line 336, in connect
    self.sock = self._get_socket(host, port, self.timeout)
  File "/usr/local/lib/python3.6/smtplib.py", line 307, in _get_socket
    self.source_address)
  File "/usr/local/lib/python3.6/socket.py", line 724, in create_connection
    raise err
  File "/usr/local/lib/python3.6/socket.py", line 713, in create_connection
    sock.connect(sa)
OSError: [Errno 99] Cannot assign requested address
[2021-10-26 18:07:28,046] {standard_task_runner.py:91} ERROR - Failed to execute job 32 for task spider_star
Traceback (most recent call last):
  File "/home/airflow/.local/lib/python3.6/site-packages/airflow/task/task_runner/standard_task_runner.py", line 85, in _start_by_fork
    args.func(args, dag=self.dag)
  File "/home/airflow/.local/lib/python3.6/site-packages/airflow/cli/cli_parser.py", line 48, in command
    return func(*args, **kwargs)
  File "/home/airflow/.local/lib/python3.6/site-packages/airflow/utils/cli.py", line 92, in wrapper
    return f(*args, **kwargs)
  File "/home/airflow/.local/lib/python3.6/site-packages/airflow/cli/commands/task_command.py", line 292, in task_run
    _run_task_by_selected_method(args, dag, ti)
  File "/home/airflow/.local/lib/python3.6/site-packages/airflow/cli/commands/task_command.py", line 107, in _run_task_by_selected_method
    _run_raw_task(args, ti)
  File "/home/airflow/.local/lib/python3.6/site-packages/airflow/cli/commands/task_command.py", line 184, in _run_raw_task
    error_file=args.error_file,
  File "/home/airflow/.local/lib/python3.6/site-packages/airflow/utils/session.py", line 70, in wrapper
    return func(*args, session=session, **kwargs)
  File "/home/airflow/.local/lib/python3.6/site-packages/airflow/models/taskinstance.py", line 1324, in _run_raw_task
    self._execute_task_with_callbacks(context)
  File "/home/airflow/.local/lib/python3.6/site-packages/airflow/models/taskinstance.py", line 1443, in _execute_task_with_callbacks
    result = self._execute_task(context, self.task)
  File "/home/airflow/.local/lib/python3.6/site-packages/airflow/models/taskinstance.py", line 1499, in _execute_task
    result = execute_callable(context=context)
  File "/home/airflow/.local/lib/python3.6/site-packages/airflow/operators/bash.py", line 188, in execute
    f'Bash command failed. The command returned a non-zero exit code {result.exit_code}.'
airflow.exceptions.AirflowException: Bash command failed. The command returned a non-zero exit code 127.
[2021-10-26 18:07:28,076] {local_task_job.py:154} INFO - Task exited with return code 1
[2021-10-26 18:07:28,124] {local_task_job.py:264} INFO - 0 downstream tasks scheduled from follow-on schedule check
