[2021-10-26 00:05:05,602] {taskinstance.py:1035} INFO - Dependencies all met for <TaskInstance: scrapper.spider_star scheduled__2021-10-25T00:00:00+00:00 [queued]>
[2021-10-26 00:05:05,649] {taskinstance.py:1035} INFO - Dependencies all met for <TaskInstance: scrapper.spider_star scheduled__2021-10-25T00:00:00+00:00 [queued]>
[2021-10-26 00:05:05,651] {taskinstance.py:1241} INFO - 
--------------------------------------------------------------------------------
[2021-10-26 00:05:05,652] {taskinstance.py:1242} INFO - Starting attempt 2 of 2
[2021-10-26 00:05:05,653] {taskinstance.py:1243} INFO - 
--------------------------------------------------------------------------------
[2021-10-26 00:05:05,735] {taskinstance.py:1262} INFO - Executing <Task(BashOperator): spider_star> on 2021-10-25 00:00:00+00:00
[2021-10-26 00:05:05,806] {standard_task_runner.py:76} INFO - Running: ['***', 'tasks', 'run', 'scrapper', 'spider_star', 'scheduled__2021-10-25T00:00:00+00:00', '--job-id', '16', '--raw', '--subdir', 'DAGS_FOLDER/my_dag.py', '--cfg-path', '/tmp/tmpntyktxzh', '--error-file', '/tmp/tmph48x1lp3']
[2021-10-26 00:05:05,811] {standard_task_runner.py:77} INFO - Job 16: Subtask spider_star
[2021-10-26 00:05:05,753] {standard_task_runner.py:52} INFO - Started process 6946 to run task
[2021-10-26 00:05:06,155] {logging_mixin.py:109} INFO - Running <TaskInstance: scrapper.spider_star scheduled__2021-10-25T00:00:00+00:00 [running]> on host ebc91b274482
[2021-10-26 00:05:06,667] {taskinstance.py:1414} INFO - Exporting the following env vars:
AIRFLOW_CTX_DAG_EMAIL=octadelsueldo@gmail.com
AIRFLOW_CTX_DAG_OWNER=Octavio
AIRFLOW_CTX_DAG_ID=scrapper
AIRFLOW_CTX_TASK_ID=spider_star
AIRFLOW_CTX_EXECUTION_DATE=2021-10-25T00:00:00+00:00
AIRFLOW_CTX_DAG_RUN_ID=scheduled__2021-10-25T00:00:00+00:00
[2021-10-26 00:05:06,677] {subprocess.py:62} INFO - Tmp dir root location: 
 /tmp
[2021-10-26 00:05:06,688] {subprocess.py:74} INFO - Running command: ['bash', '-c', './opt/***/dags/script/run_spider.sh ']
[2021-10-26 00:05:06,763] {subprocess.py:85} INFO - Output:
[2021-10-26 00:05:06,789] {subprocess.py:89} INFO - bash: ./opt/***/dags/script/run_spider.sh: No such file or directory
[2021-10-26 00:05:06,804] {subprocess.py:93} INFO - Command exited with return code 127
[2021-10-26 00:05:06,849] {taskinstance.py:1686} ERROR - Task failed with exception
Traceback (most recent call last):
  File "/home/airflow/.local/lib/python3.6/site-packages/airflow/models/taskinstance.py", line 1324, in _run_raw_task
    self._execute_task_with_callbacks(context)
  File "/home/airflow/.local/lib/python3.6/site-packages/airflow/models/taskinstance.py", line 1443, in _execute_task_with_callbacks
    result = self._execute_task(context, self.task)
  File "/home/airflow/.local/lib/python3.6/site-packages/airflow/models/taskinstance.py", line 1499, in _execute_task
    result = execute_callable(context=context)
  File "/home/airflow/.local/lib/python3.6/site-packages/airflow/operators/bash.py", line 188, in execute
    f'Bash command failed. The command returned a non-zero exit code {result.exit_code}.'
airflow.exceptions.AirflowException: Bash command failed. The command returned a non-zero exit code 127.
[2021-10-26 00:05:06,928] {taskinstance.py:1280} INFO - Marking task as FAILED. dag_id=scrapper, task_id=spider_star, execution_date=20211025T000000, start_date=20211026T000505, end_date=20211026T000506
[2021-10-26 00:05:07,023] {warnings.py:99} WARNING - /home/***/.local/lib/python3.6/site-packages/***/utils/email.py:102: PendingDeprecationWarning: Fetching SMTP credentials from configuration variables will be deprecated in a future release. Please set credentials using a connection instead.
  send_mime_email(e_from=smtp_mail_from, e_to=recipients, mime_msg=msg, conn_id=conn_id, dryrun=dryrun)

[2021-10-26 00:05:07,028] {configuration.py:381} WARNING - section/key [smtp/smtp_user] not found in config
[2021-10-26 00:05:07,031] {email.py:208} INFO - Email alerting: attempt 1
[2021-10-26 00:05:07,077] {configuration.py:381} WARNING - section/key [smtp/smtp_user] not found in config
[2021-10-26 00:05:07,085] {email.py:208} INFO - Email alerting: attempt 1
[2021-10-26 00:05:07,090] {taskinstance.py:1739} ERROR - Failed to send email to: ['octadelsueldo@gmail.com']
Traceback (most recent call last):
  File "/home/airflow/.local/lib/python3.6/site-packages/airflow/models/taskinstance.py", line 1324, in _run_raw_task
    self._execute_task_with_callbacks(context)
  File "/home/airflow/.local/lib/python3.6/site-packages/airflow/models/taskinstance.py", line 1443, in _execute_task_with_callbacks
    result = self._execute_task(context, self.task)
  File "/home/airflow/.local/lib/python3.6/site-packages/airflow/models/taskinstance.py", line 1499, in _execute_task
    result = execute_callable(context=context)
  File "/home/airflow/.local/lib/python3.6/site-packages/airflow/operators/bash.py", line 188, in execute
    f'Bash command failed. The command returned a non-zero exit code {result.exit_code}.'
airflow.exceptions.AirflowException: Bash command failed. The command returned a non-zero exit code 127.

During handling of the above exception, another exception occurred:

Traceback (most recent call last):
  File "/home/airflow/.local/lib/python3.6/site-packages/airflow/models/taskinstance.py", line 2189, in email_alert
    send_email(self.task.email, subject, html_content)
  File "/home/airflow/.local/lib/python3.6/site-packages/airflow/utils/email.py", line 66, in send_email
    **kwargs,
  File "/home/airflow/.local/lib/python3.6/site-packages/airflow/utils/email.py", line 102, in send_email_smtp
    send_mime_email(e_from=smtp_mail_from, e_to=recipients, mime_msg=msg, conn_id=conn_id, dryrun=dryrun)
  File "/home/airflow/.local/lib/python3.6/site-packages/airflow/utils/email.py", line 210, in send_mime_email
    conn = _get_smtp_connection(smtp_host, smtp_port, smtp_timeout, smtp_ssl)
  File "/home/airflow/.local/lib/python3.6/site-packages/airflow/utils/email.py", line 244, in _get_smtp_connection
    else smtplib.SMTP(host=host, port=port, timeout=timeout)
  File "/usr/local/lib/python3.6/smtplib.py", line 251, in __init__
    (code, msg) = self.connect(host, port)
  File "/usr/local/lib/python3.6/smtplib.py", line 336, in connect
    self.sock = self._get_socket(host, port, self.timeout)
  File "/usr/local/lib/python3.6/smtplib.py", line 307, in _get_socket
    self.source_address)
  File "/usr/local/lib/python3.6/socket.py", line 724, in create_connection
    raise err
  File "/usr/local/lib/python3.6/socket.py", line 713, in create_connection
    sock.connect(sa)
OSError: [Errno 99] Cannot assign requested address

During handling of the above exception, another exception occurred:

Traceback (most recent call last):
  File "/home/airflow/.local/lib/python3.6/site-packages/airflow/models/taskinstance.py", line 1737, in handle_failure
    self.email_alert(error)
  File "/home/airflow/.local/lib/python3.6/site-packages/airflow/models/taskinstance.py", line 2191, in email_alert
    send_email(self.task.email, subject, html_content_err)
  File "/home/airflow/.local/lib/python3.6/site-packages/airflow/utils/email.py", line 66, in send_email
    **kwargs,
  File "/home/airflow/.local/lib/python3.6/site-packages/airflow/utils/email.py", line 102, in send_email_smtp
    send_mime_email(e_from=smtp_mail_from, e_to=recipients, mime_msg=msg, conn_id=conn_id, dryrun=dryrun)
  File "/home/airflow/.local/lib/python3.6/site-packages/airflow/utils/email.py", line 210, in send_mime_email
    conn = _get_smtp_connection(smtp_host, smtp_port, smtp_timeout, smtp_ssl)
  File "/home/airflow/.local/lib/python3.6/site-packages/airflow/utils/email.py", line 244, in _get_smtp_connection
    else smtplib.SMTP(host=host, port=port, timeout=timeout)
  File "/usr/local/lib/python3.6/smtplib.py", line 251, in __init__
    (code, msg) = self.connect(host, port)
  File "/usr/local/lib/python3.6/smtplib.py", line 336, in connect
    self.sock = self._get_socket(host, port, self.timeout)
  File "/usr/local/lib/python3.6/smtplib.py", line 307, in _get_socket
    self.source_address)
  File "/usr/local/lib/python3.6/socket.py", line 724, in create_connection
    raise err
  File "/usr/local/lib/python3.6/socket.py", line 713, in create_connection
    sock.connect(sa)
OSError: [Errno 99] Cannot assign requested address
[2021-10-26 00:05:07,227] {standard_task_runner.py:91} ERROR - Failed to execute job 16 for task spider_star
Traceback (most recent call last):
  File "/home/airflow/.local/lib/python3.6/site-packages/airflow/task/task_runner/standard_task_runner.py", line 85, in _start_by_fork
    args.func(args, dag=self.dag)
  File "/home/airflow/.local/lib/python3.6/site-packages/airflow/cli/cli_parser.py", line 48, in command
    return func(*args, **kwargs)
  File "/home/airflow/.local/lib/python3.6/site-packages/airflow/utils/cli.py", line 92, in wrapper
    return f(*args, **kwargs)
  File "/home/airflow/.local/lib/python3.6/site-packages/airflow/cli/commands/task_command.py", line 292, in task_run
    _run_task_by_selected_method(args, dag, ti)
  File "/home/airflow/.local/lib/python3.6/site-packages/airflow/cli/commands/task_command.py", line 107, in _run_task_by_selected_method
    _run_raw_task(args, ti)
  File "/home/airflow/.local/lib/python3.6/site-packages/airflow/cli/commands/task_command.py", line 184, in _run_raw_task
    error_file=args.error_file,
  File "/home/airflow/.local/lib/python3.6/site-packages/airflow/utils/session.py", line 70, in wrapper
    return func(*args, session=session, **kwargs)
  File "/home/airflow/.local/lib/python3.6/site-packages/airflow/models/taskinstance.py", line 1324, in _run_raw_task
    self._execute_task_with_callbacks(context)
  File "/home/airflow/.local/lib/python3.6/site-packages/airflow/models/taskinstance.py", line 1443, in _execute_task_with_callbacks
    result = self._execute_task(context, self.task)
  File "/home/airflow/.local/lib/python3.6/site-packages/airflow/models/taskinstance.py", line 1499, in _execute_task
    result = execute_callable(context=context)
  File "/home/airflow/.local/lib/python3.6/site-packages/airflow/operators/bash.py", line 188, in execute
    f'Bash command failed. The command returned a non-zero exit code {result.exit_code}.'
airflow.exceptions.AirflowException: Bash command failed. The command returned a non-zero exit code 127.
[2021-10-26 00:05:07,294] {local_task_job.py:154} INFO - Task exited with return code 1
[2021-10-26 00:05:07,438] {local_task_job.py:264} INFO - 0 downstream tasks scheduled from follow-on schedule check
[2021-10-26 17:28:45,377] {taskinstance.py:1035} INFO - Dependencies all met for <TaskInstance: scrapper.spider_star manual__2021-10-26T17:23:39.166007+00:00 [queued]>
[2021-10-26 17:28:45,407] {taskinstance.py:1035} INFO - Dependencies all met for <TaskInstance: scrapper.spider_star manual__2021-10-26T17:23:39.166007+00:00 [queued]>
[2021-10-26 17:28:45,408] {taskinstance.py:1241} INFO - 
--------------------------------------------------------------------------------
[2021-10-26 17:28:45,409] {taskinstance.py:1242} INFO - Starting attempt 2 of 2
[2021-10-26 17:28:45,410] {taskinstance.py:1243} INFO - 
--------------------------------------------------------------------------------
[2021-10-26 17:28:45,431] {taskinstance.py:1262} INFO - Executing <Task(BashOperator): spider_star> on 2021-10-26 17:23:39.166007+00:00
[2021-10-26 17:28:45,476] {standard_task_runner.py:76} INFO - Running: ['***', 'tasks', 'run', 'scrapper', 'spider_star', 'manual__2021-10-26T17:23:39.166007+00:00', '--job-id', '20', '--raw', '--subdir', 'DAGS_FOLDER/my_dag.py', '--cfg-path', '/tmp/tmp2eolx3s3', '--error-file', '/tmp/tmpm0rtxgrj']
[2021-10-26 17:28:45,438] {standard_task_runner.py:52} INFO - Started process 13334 to run task
[2021-10-26 17:28:45,483] {standard_task_runner.py:77} INFO - Job 20: Subtask spider_star
[2021-10-26 17:28:45,603] {logging_mixin.py:109} INFO - Running <TaskInstance: scrapper.spider_star manual__2021-10-26T17:23:39.166007+00:00 [running]> on host ebc91b274482
[2021-10-26 17:28:45,764] {taskinstance.py:1414} INFO - Exporting the following env vars:
AIRFLOW_CTX_DAG_EMAIL=octadelsueldo@gmail.com
AIRFLOW_CTX_DAG_OWNER=Octavio
AIRFLOW_CTX_DAG_ID=scrapper
AIRFLOW_CTX_TASK_ID=spider_star
AIRFLOW_CTX_EXECUTION_DATE=2021-10-26T17:23:39.166007+00:00
AIRFLOW_CTX_DAG_RUN_ID=manual__2021-10-26T17:23:39.166007+00:00
[2021-10-26 17:28:45,768] {subprocess.py:62} INFO - Tmp dir root location: 
 /tmp
[2021-10-26 17:28:45,770] {subprocess.py:74} INFO - Running command: ['bash', '-c', 'cd ./***/dags/script/run_spider.sh ']
[2021-10-26 17:28:45,814] {subprocess.py:85} INFO - Output:
[2021-10-26 17:28:45,817] {subprocess.py:89} INFO - bash: line 0: cd: ./***/dags/script/run_spider.sh: No such file or directory
[2021-10-26 17:28:45,822] {subprocess.py:93} INFO - Command exited with return code 1
[2021-10-26 17:28:45,828] {taskinstance.py:1686} ERROR - Task failed with exception
Traceback (most recent call last):
  File "/home/airflow/.local/lib/python3.6/site-packages/airflow/models/taskinstance.py", line 1324, in _run_raw_task
    self._execute_task_with_callbacks(context)
  File "/home/airflow/.local/lib/python3.6/site-packages/airflow/models/taskinstance.py", line 1443, in _execute_task_with_callbacks
    result = self._execute_task(context, self.task)
  File "/home/airflow/.local/lib/python3.6/site-packages/airflow/models/taskinstance.py", line 1499, in _execute_task
    result = execute_callable(context=context)
  File "/home/airflow/.local/lib/python3.6/site-packages/airflow/operators/bash.py", line 188, in execute
    f'Bash command failed. The command returned a non-zero exit code {result.exit_code}.'
airflow.exceptions.AirflowException: Bash command failed. The command returned a non-zero exit code 1.
[2021-10-26 17:28:45,863] {taskinstance.py:1280} INFO - Marking task as FAILED. dag_id=scrapper, task_id=spider_star, execution_date=20211026T172339, start_date=20211026T172845, end_date=20211026T172845
[2021-10-26 17:28:45,903] {warnings.py:99} WARNING - /home/***/.local/lib/python3.6/site-packages/***/utils/email.py:102: PendingDeprecationWarning: Fetching SMTP credentials from configuration variables will be deprecated in a future release. Please set credentials using a connection instead.
  send_mime_email(e_from=smtp_mail_from, e_to=recipients, mime_msg=msg, conn_id=conn_id, dryrun=dryrun)

[2021-10-26 17:28:45,905] {configuration.py:381} WARNING - section/key [smtp/smtp_user] not found in config
[2021-10-26 17:28:45,906] {email.py:208} INFO - Email alerting: attempt 1
[2021-10-26 17:28:45,960] {configuration.py:381} WARNING - section/key [smtp/smtp_user] not found in config
[2021-10-26 17:28:45,961] {email.py:208} INFO - Email alerting: attempt 1
[2021-10-26 17:28:45,966] {taskinstance.py:1739} ERROR - Failed to send email to: ['octadelsueldo@gmail.com']
Traceback (most recent call last):
  File "/home/airflow/.local/lib/python3.6/site-packages/airflow/models/taskinstance.py", line 1324, in _run_raw_task
    self._execute_task_with_callbacks(context)
  File "/home/airflow/.local/lib/python3.6/site-packages/airflow/models/taskinstance.py", line 1443, in _execute_task_with_callbacks
    result = self._execute_task(context, self.task)
  File "/home/airflow/.local/lib/python3.6/site-packages/airflow/models/taskinstance.py", line 1499, in _execute_task
    result = execute_callable(context=context)
  File "/home/airflow/.local/lib/python3.6/site-packages/airflow/operators/bash.py", line 188, in execute
    f'Bash command failed. The command returned a non-zero exit code {result.exit_code}.'
airflow.exceptions.AirflowException: Bash command failed. The command returned a non-zero exit code 1.

During handling of the above exception, another exception occurred:

Traceback (most recent call last):
  File "/home/airflow/.local/lib/python3.6/site-packages/airflow/models/taskinstance.py", line 2189, in email_alert
    send_email(self.task.email, subject, html_content)
  File "/home/airflow/.local/lib/python3.6/site-packages/airflow/utils/email.py", line 66, in send_email
    **kwargs,
  File "/home/airflow/.local/lib/python3.6/site-packages/airflow/utils/email.py", line 102, in send_email_smtp
    send_mime_email(e_from=smtp_mail_from, e_to=recipients, mime_msg=msg, conn_id=conn_id, dryrun=dryrun)
  File "/home/airflow/.local/lib/python3.6/site-packages/airflow/utils/email.py", line 210, in send_mime_email
    conn = _get_smtp_connection(smtp_host, smtp_port, smtp_timeout, smtp_ssl)
  File "/home/airflow/.local/lib/python3.6/site-packages/airflow/utils/email.py", line 244, in _get_smtp_connection
    else smtplib.SMTP(host=host, port=port, timeout=timeout)
  File "/usr/local/lib/python3.6/smtplib.py", line 251, in __init__
    (code, msg) = self.connect(host, port)
  File "/usr/local/lib/python3.6/smtplib.py", line 336, in connect
    self.sock = self._get_socket(host, port, self.timeout)
  File "/usr/local/lib/python3.6/smtplib.py", line 307, in _get_socket
    self.source_address)
  File "/usr/local/lib/python3.6/socket.py", line 724, in create_connection
    raise err
  File "/usr/local/lib/python3.6/socket.py", line 713, in create_connection
    sock.connect(sa)
OSError: [Errno 99] Cannot assign requested address

During handling of the above exception, another exception occurred:

Traceback (most recent call last):
  File "/home/airflow/.local/lib/python3.6/site-packages/airflow/models/taskinstance.py", line 1737, in handle_failure
    self.email_alert(error)
  File "/home/airflow/.local/lib/python3.6/site-packages/airflow/models/taskinstance.py", line 2191, in email_alert
    send_email(self.task.email, subject, html_content_err)
  File "/home/airflow/.local/lib/python3.6/site-packages/airflow/utils/email.py", line 66, in send_email
    **kwargs,
  File "/home/airflow/.local/lib/python3.6/site-packages/airflow/utils/email.py", line 102, in send_email_smtp
    send_mime_email(e_from=smtp_mail_from, e_to=recipients, mime_msg=msg, conn_id=conn_id, dryrun=dryrun)
  File "/home/airflow/.local/lib/python3.6/site-packages/airflow/utils/email.py", line 210, in send_mime_email
    conn = _get_smtp_connection(smtp_host, smtp_port, smtp_timeout, smtp_ssl)
  File "/home/airflow/.local/lib/python3.6/site-packages/airflow/utils/email.py", line 244, in _get_smtp_connection
    else smtplib.SMTP(host=host, port=port, timeout=timeout)
  File "/usr/local/lib/python3.6/smtplib.py", line 251, in __init__
    (code, msg) = self.connect(host, port)
  File "/usr/local/lib/python3.6/smtplib.py", line 336, in connect
    self.sock = self._get_socket(host, port, self.timeout)
  File "/usr/local/lib/python3.6/smtplib.py", line 307, in _get_socket
    self.source_address)
  File "/usr/local/lib/python3.6/socket.py", line 724, in create_connection
    raise err
  File "/usr/local/lib/python3.6/socket.py", line 713, in create_connection
    sock.connect(sa)
OSError: [Errno 99] Cannot assign requested address
[2021-10-26 17:28:46,021] {standard_task_runner.py:91} ERROR - Failed to execute job 20 for task spider_star
Traceback (most recent call last):
  File "/home/airflow/.local/lib/python3.6/site-packages/airflow/task/task_runner/standard_task_runner.py", line 85, in _start_by_fork
    args.func(args, dag=self.dag)
  File "/home/airflow/.local/lib/python3.6/site-packages/airflow/cli/cli_parser.py", line 48, in command
    return func(*args, **kwargs)
  File "/home/airflow/.local/lib/python3.6/site-packages/airflow/utils/cli.py", line 92, in wrapper
    return f(*args, **kwargs)
  File "/home/airflow/.local/lib/python3.6/site-packages/airflow/cli/commands/task_command.py", line 292, in task_run
    _run_task_by_selected_method(args, dag, ti)
  File "/home/airflow/.local/lib/python3.6/site-packages/airflow/cli/commands/task_command.py", line 107, in _run_task_by_selected_method
    _run_raw_task(args, ti)
  File "/home/airflow/.local/lib/python3.6/site-packages/airflow/cli/commands/task_command.py", line 184, in _run_raw_task
    error_file=args.error_file,
  File "/home/airflow/.local/lib/python3.6/site-packages/airflow/utils/session.py", line 70, in wrapper
    return func(*args, session=session, **kwargs)
  File "/home/airflow/.local/lib/python3.6/site-packages/airflow/models/taskinstance.py", line 1324, in _run_raw_task
    self._execute_task_with_callbacks(context)
  File "/home/airflow/.local/lib/python3.6/site-packages/airflow/models/taskinstance.py", line 1443, in _execute_task_with_callbacks
    result = self._execute_task(context, self.task)
  File "/home/airflow/.local/lib/python3.6/site-packages/airflow/models/taskinstance.py", line 1499, in _execute_task
    result = execute_callable(context=context)
  File "/home/airflow/.local/lib/python3.6/site-packages/airflow/operators/bash.py", line 188, in execute
    f'Bash command failed. The command returned a non-zero exit code {result.exit_code}.'
airflow.exceptions.AirflowException: Bash command failed. The command returned a non-zero exit code 1.
[2021-10-26 17:28:46,097] {local_task_job.py:154} INFO - Task exited with return code 1
[2021-10-26 17:28:46,166] {local_task_job.py:264} INFO - 0 downstream tasks scheduled from follow-on schedule check
[2021-10-26 17:31:38,700] {taskinstance.py:1035} INFO - Dependencies all met for <TaskInstance: scrapper.spider_star manual__2021-10-26T17:26:33.849951+00:00 [queued]>
[2021-10-26 17:31:38,776] {taskinstance.py:1035} INFO - Dependencies all met for <TaskInstance: scrapper.spider_star manual__2021-10-26T17:26:33.849951+00:00 [queued]>
[2021-10-26 17:31:38,777] {taskinstance.py:1241} INFO - 
--------------------------------------------------------------------------------
[2021-10-26 17:31:38,779] {taskinstance.py:1242} INFO - Starting attempt 2 of 2
[2021-10-26 17:31:38,780] {taskinstance.py:1243} INFO - 
--------------------------------------------------------------------------------
[2021-10-26 17:31:38,818] {taskinstance.py:1262} INFO - Executing <Task(BashOperator): spider_star> on 2021-10-26 17:26:33.849951+00:00
[2021-10-26 17:31:38,836] {standard_task_runner.py:76} INFO - Running: ['***', 'tasks', 'run', 'scrapper', 'spider_star', 'manual__2021-10-26T17:26:33.849951+00:00', '--job-id', '22', '--raw', '--subdir', 'DAGS_FOLDER/my_dag.py', '--cfg-path', '/tmp/tmpkierjwbd', '--error-file', '/tmp/tmp7g3q1e2c']
[2021-10-26 17:31:38,841] {standard_task_runner.py:77} INFO - Job 22: Subtask spider_star
[2021-10-26 17:31:38,831] {standard_task_runner.py:52} INFO - Started process 13456 to run task
[2021-10-26 17:31:38,977] {logging_mixin.py:109} INFO - Running <TaskInstance: scrapper.spider_star manual__2021-10-26T17:26:33.849951+00:00 [running]> on host ebc91b274482
[2021-10-26 17:31:39,043] {taskinstance.py:1414} INFO - Exporting the following env vars:
AIRFLOW_CTX_DAG_EMAIL=octadelsueldo@gmail.com
AIRFLOW_CTX_DAG_OWNER=Octavio
AIRFLOW_CTX_DAG_ID=scrapper
AIRFLOW_CTX_TASK_ID=spider_star
AIRFLOW_CTX_EXECUTION_DATE=2021-10-26T17:26:33.849951+00:00
AIRFLOW_CTX_DAG_RUN_ID=manual__2021-10-26T17:26:33.849951+00:00
[2021-10-26 17:31:39,045] {subprocess.py:62} INFO - Tmp dir root location: 
 /tmp
[2021-10-26 17:31:39,047] {subprocess.py:74} INFO - Running command: ['bash', '-c', './dags/script/run_spider.sh ']
[2021-10-26 17:31:39,066] {subprocess.py:85} INFO - Output:
[2021-10-26 17:31:39,068] {subprocess.py:89} INFO - bash: ./dags/script/run_spider.sh: No such file or directory
[2021-10-26 17:31:39,069] {subprocess.py:93} INFO - Command exited with return code 127
[2021-10-26 17:31:39,073] {taskinstance.py:1686} ERROR - Task failed with exception
Traceback (most recent call last):
  File "/home/airflow/.local/lib/python3.6/site-packages/airflow/models/taskinstance.py", line 1324, in _run_raw_task
    self._execute_task_with_callbacks(context)
  File "/home/airflow/.local/lib/python3.6/site-packages/airflow/models/taskinstance.py", line 1443, in _execute_task_with_callbacks
    result = self._execute_task(context, self.task)
  File "/home/airflow/.local/lib/python3.6/site-packages/airflow/models/taskinstance.py", line 1499, in _execute_task
    result = execute_callable(context=context)
  File "/home/airflow/.local/lib/python3.6/site-packages/airflow/operators/bash.py", line 188, in execute
    f'Bash command failed. The command returned a non-zero exit code {result.exit_code}.'
airflow.exceptions.AirflowException: Bash command failed. The command returned a non-zero exit code 127.
[2021-10-26 17:31:39,089] {taskinstance.py:1280} INFO - Marking task as FAILED. dag_id=scrapper, task_id=spider_star, execution_date=20211026T172633, start_date=20211026T173138, end_date=20211026T173139
[2021-10-26 17:31:39,119] {warnings.py:99} WARNING - /home/***/.local/lib/python3.6/site-packages/***/utils/email.py:102: PendingDeprecationWarning: Fetching SMTP credentials from configuration variables will be deprecated in a future release. Please set credentials using a connection instead.
  send_mime_email(e_from=smtp_mail_from, e_to=recipients, mime_msg=msg, conn_id=conn_id, dryrun=dryrun)

[2021-10-26 17:31:39,120] {configuration.py:381} WARNING - section/key [smtp/smtp_user] not found in config
[2021-10-26 17:31:39,121] {email.py:208} INFO - Email alerting: attempt 1
[2021-10-26 17:31:39,141] {configuration.py:381} WARNING - section/key [smtp/smtp_user] not found in config
[2021-10-26 17:31:39,144] {email.py:208} INFO - Email alerting: attempt 1
[2021-10-26 17:31:39,145] {taskinstance.py:1739} ERROR - Failed to send email to: ['octadelsueldo@gmail.com']
Traceback (most recent call last):
  File "/home/airflow/.local/lib/python3.6/site-packages/airflow/models/taskinstance.py", line 1324, in _run_raw_task
    self._execute_task_with_callbacks(context)
  File "/home/airflow/.local/lib/python3.6/site-packages/airflow/models/taskinstance.py", line 1443, in _execute_task_with_callbacks
    result = self._execute_task(context, self.task)
  File "/home/airflow/.local/lib/python3.6/site-packages/airflow/models/taskinstance.py", line 1499, in _execute_task
    result = execute_callable(context=context)
  File "/home/airflow/.local/lib/python3.6/site-packages/airflow/operators/bash.py", line 188, in execute
    f'Bash command failed. The command returned a non-zero exit code {result.exit_code}.'
airflow.exceptions.AirflowException: Bash command failed. The command returned a non-zero exit code 127.

During handling of the above exception, another exception occurred:

Traceback (most recent call last):
  File "/home/airflow/.local/lib/python3.6/site-packages/airflow/models/taskinstance.py", line 2189, in email_alert
    send_email(self.task.email, subject, html_content)
  File "/home/airflow/.local/lib/python3.6/site-packages/airflow/utils/email.py", line 66, in send_email
    **kwargs,
  File "/home/airflow/.local/lib/python3.6/site-packages/airflow/utils/email.py", line 102, in send_email_smtp
    send_mime_email(e_from=smtp_mail_from, e_to=recipients, mime_msg=msg, conn_id=conn_id, dryrun=dryrun)
  File "/home/airflow/.local/lib/python3.6/site-packages/airflow/utils/email.py", line 210, in send_mime_email
    conn = _get_smtp_connection(smtp_host, smtp_port, smtp_timeout, smtp_ssl)
  File "/home/airflow/.local/lib/python3.6/site-packages/airflow/utils/email.py", line 244, in _get_smtp_connection
    else smtplib.SMTP(host=host, port=port, timeout=timeout)
  File "/usr/local/lib/python3.6/smtplib.py", line 251, in __init__
    (code, msg) = self.connect(host, port)
  File "/usr/local/lib/python3.6/smtplib.py", line 336, in connect
    self.sock = self._get_socket(host, port, self.timeout)
  File "/usr/local/lib/python3.6/smtplib.py", line 307, in _get_socket
    self.source_address)
  File "/usr/local/lib/python3.6/socket.py", line 724, in create_connection
    raise err
  File "/usr/local/lib/python3.6/socket.py", line 713, in create_connection
    sock.connect(sa)
OSError: [Errno 99] Cannot assign requested address

During handling of the above exception, another exception occurred:

Traceback (most recent call last):
  File "/home/airflow/.local/lib/python3.6/site-packages/airflow/models/taskinstance.py", line 1737, in handle_failure
    self.email_alert(error)
  File "/home/airflow/.local/lib/python3.6/site-packages/airflow/models/taskinstance.py", line 2191, in email_alert
    send_email(self.task.email, subject, html_content_err)
  File "/home/airflow/.local/lib/python3.6/site-packages/airflow/utils/email.py", line 66, in send_email
    **kwargs,
  File "/home/airflow/.local/lib/python3.6/site-packages/airflow/utils/email.py", line 102, in send_email_smtp
    send_mime_email(e_from=smtp_mail_from, e_to=recipients, mime_msg=msg, conn_id=conn_id, dryrun=dryrun)
  File "/home/airflow/.local/lib/python3.6/site-packages/airflow/utils/email.py", line 210, in send_mime_email
    conn = _get_smtp_connection(smtp_host, smtp_port, smtp_timeout, smtp_ssl)
  File "/home/airflow/.local/lib/python3.6/site-packages/airflow/utils/email.py", line 244, in _get_smtp_connection
    else smtplib.SMTP(host=host, port=port, timeout=timeout)
  File "/usr/local/lib/python3.6/smtplib.py", line 251, in __init__
    (code, msg) = self.connect(host, port)
  File "/usr/local/lib/python3.6/smtplib.py", line 336, in connect
    self.sock = self._get_socket(host, port, self.timeout)
  File "/usr/local/lib/python3.6/smtplib.py", line 307, in _get_socket
    self.source_address)
  File "/usr/local/lib/python3.6/socket.py", line 724, in create_connection
    raise err
  File "/usr/local/lib/python3.6/socket.py", line 713, in create_connection
    sock.connect(sa)
OSError: [Errno 99] Cannot assign requested address
[2021-10-26 17:31:39,170] {standard_task_runner.py:91} ERROR - Failed to execute job 22 for task spider_star
Traceback (most recent call last):
  File "/home/airflow/.local/lib/python3.6/site-packages/airflow/task/task_runner/standard_task_runner.py", line 85, in _start_by_fork
    args.func(args, dag=self.dag)
  File "/home/airflow/.local/lib/python3.6/site-packages/airflow/cli/cli_parser.py", line 48, in command
    return func(*args, **kwargs)
  File "/home/airflow/.local/lib/python3.6/site-packages/airflow/utils/cli.py", line 92, in wrapper
    return f(*args, **kwargs)
  File "/home/airflow/.local/lib/python3.6/site-packages/airflow/cli/commands/task_command.py", line 292, in task_run
    _run_task_by_selected_method(args, dag, ti)
  File "/home/airflow/.local/lib/python3.6/site-packages/airflow/cli/commands/task_command.py", line 107, in _run_task_by_selected_method
    _run_raw_task(args, ti)
  File "/home/airflow/.local/lib/python3.6/site-packages/airflow/cli/commands/task_command.py", line 184, in _run_raw_task
    error_file=args.error_file,
  File "/home/airflow/.local/lib/python3.6/site-packages/airflow/utils/session.py", line 70, in wrapper
    return func(*args, session=session, **kwargs)
  File "/home/airflow/.local/lib/python3.6/site-packages/airflow/models/taskinstance.py", line 1324, in _run_raw_task
    self._execute_task_with_callbacks(context)
  File "/home/airflow/.local/lib/python3.6/site-packages/airflow/models/taskinstance.py", line 1443, in _execute_task_with_callbacks
    result = self._execute_task(context, self.task)
  File "/home/airflow/.local/lib/python3.6/site-packages/airflow/models/taskinstance.py", line 1499, in _execute_task
    result = execute_callable(context=context)
  File "/home/airflow/.local/lib/python3.6/site-packages/airflow/operators/bash.py", line 188, in execute
    f'Bash command failed. The command returned a non-zero exit code {result.exit_code}.'
airflow.exceptions.AirflowException: Bash command failed. The command returned a non-zero exit code 127.
[2021-10-26 17:31:39,200] {local_task_job.py:154} INFO - Task exited with return code 1
[2021-10-26 17:31:39,236] {local_task_job.py:264} INFO - 0 downstream tasks scheduled from follow-on schedule check
[2021-10-26 17:33:24,659] {taskinstance.py:1035} INFO - Dependencies all met for <TaskInstance: scrapper.spider_star manual__2021-10-26T17:28:18.961756+00:00 [queued]>
[2021-10-26 17:33:24,742] {taskinstance.py:1035} INFO - Dependencies all met for <TaskInstance: scrapper.spider_star manual__2021-10-26T17:28:18.961756+00:00 [queued]>
[2021-10-26 17:33:24,744] {taskinstance.py:1241} INFO - 
--------------------------------------------------------------------------------
[2021-10-26 17:33:24,746] {taskinstance.py:1242} INFO - Starting attempt 2 of 2
[2021-10-26 17:33:24,768] {taskinstance.py:1243} INFO - 
--------------------------------------------------------------------------------
[2021-10-26 17:33:24,855] {taskinstance.py:1262} INFO - Executing <Task(BashOperator): spider_star> on 2021-10-26 17:28:18.961756+00:00
[2021-10-26 17:33:24,901] {standard_task_runner.py:76} INFO - Running: ['***', 'tasks', 'run', 'scrapper', 'spider_star', 'manual__2021-10-26T17:28:18.961756+00:00', '--job-id', '24', '--raw', '--subdir', 'DAGS_FOLDER/my_dag.py', '--cfg-path', '/tmp/tmpbd90ctrc', '--error-file', '/tmp/tmpk0pf9p3i']
[2021-10-26 17:33:24,909] {standard_task_runner.py:77} INFO - Job 24: Subtask spider_star
[2021-10-26 17:33:24,871] {standard_task_runner.py:52} INFO - Started process 13538 to run task
[2021-10-26 17:33:25,118] {logging_mixin.py:109} INFO - Running <TaskInstance: scrapper.spider_star manual__2021-10-26T17:28:18.961756+00:00 [running]> on host ebc91b274482
[2021-10-26 17:33:25,367] {taskinstance.py:1414} INFO - Exporting the following env vars:
AIRFLOW_CTX_DAG_EMAIL=octadelsueldo@gmail.com
AIRFLOW_CTX_DAG_OWNER=Octavio
AIRFLOW_CTX_DAG_ID=scrapper
AIRFLOW_CTX_TASK_ID=spider_star
AIRFLOW_CTX_EXECUTION_DATE=2021-10-26T17:28:18.961756+00:00
AIRFLOW_CTX_DAG_RUN_ID=manual__2021-10-26T17:28:18.961756+00:00
[2021-10-26 17:33:25,373] {subprocess.py:62} INFO - Tmp dir root location: 
 /tmp
[2021-10-26 17:33:25,380] {subprocess.py:74} INFO - Running command: ['bash', '-c', '${AIRFLOW_HOME}/***/dags/script/run_spider.sh ']
[2021-10-26 17:33:25,426] {subprocess.py:85} INFO - Output:
[2021-10-26 17:33:25,434] {subprocess.py:89} INFO - bash: /opt/***/***/dags/script/run_spider.sh: No such file or directory
[2021-10-26 17:33:25,437] {subprocess.py:93} INFO - Command exited with return code 127
[2021-10-26 17:33:25,452] {taskinstance.py:1686} ERROR - Task failed with exception
Traceback (most recent call last):
  File "/home/airflow/.local/lib/python3.6/site-packages/airflow/models/taskinstance.py", line 1324, in _run_raw_task
    self._execute_task_with_callbacks(context)
  File "/home/airflow/.local/lib/python3.6/site-packages/airflow/models/taskinstance.py", line 1443, in _execute_task_with_callbacks
    result = self._execute_task(context, self.task)
  File "/home/airflow/.local/lib/python3.6/site-packages/airflow/models/taskinstance.py", line 1499, in _execute_task
    result = execute_callable(context=context)
  File "/home/airflow/.local/lib/python3.6/site-packages/airflow/operators/bash.py", line 188, in execute
    f'Bash command failed. The command returned a non-zero exit code {result.exit_code}.'
airflow.exceptions.AirflowException: Bash command failed. The command returned a non-zero exit code 127.
[2021-10-26 17:33:25,513] {taskinstance.py:1280} INFO - Marking task as FAILED. dag_id=scrapper, task_id=spider_star, execution_date=20211026T172818, start_date=20211026T173324, end_date=20211026T173325
[2021-10-26 17:33:25,547] {warnings.py:99} WARNING - /home/***/.local/lib/python3.6/site-packages/***/utils/email.py:102: PendingDeprecationWarning: Fetching SMTP credentials from configuration variables will be deprecated in a future release. Please set credentials using a connection instead.
  send_mime_email(e_from=smtp_mail_from, e_to=recipients, mime_msg=msg, conn_id=conn_id, dryrun=dryrun)

[2021-10-26 17:33:25,550] {configuration.py:381} WARNING - section/key [smtp/smtp_user] not found in config
[2021-10-26 17:33:25,555] {email.py:208} INFO - Email alerting: attempt 1
[2021-10-26 17:33:25,578] {configuration.py:381} WARNING - section/key [smtp/smtp_user] not found in config
[2021-10-26 17:33:25,581] {email.py:208} INFO - Email alerting: attempt 1
[2021-10-26 17:33:25,584] {taskinstance.py:1739} ERROR - Failed to send email to: ['octadelsueldo@gmail.com']
Traceback (most recent call last):
  File "/home/airflow/.local/lib/python3.6/site-packages/airflow/models/taskinstance.py", line 1324, in _run_raw_task
    self._execute_task_with_callbacks(context)
  File "/home/airflow/.local/lib/python3.6/site-packages/airflow/models/taskinstance.py", line 1443, in _execute_task_with_callbacks
    result = self._execute_task(context, self.task)
  File "/home/airflow/.local/lib/python3.6/site-packages/airflow/models/taskinstance.py", line 1499, in _execute_task
    result = execute_callable(context=context)
  File "/home/airflow/.local/lib/python3.6/site-packages/airflow/operators/bash.py", line 188, in execute
    f'Bash command failed. The command returned a non-zero exit code {result.exit_code}.'
airflow.exceptions.AirflowException: Bash command failed. The command returned a non-zero exit code 127.

During handling of the above exception, another exception occurred:

Traceback (most recent call last):
  File "/home/airflow/.local/lib/python3.6/site-packages/airflow/models/taskinstance.py", line 2189, in email_alert
    send_email(self.task.email, subject, html_content)
  File "/home/airflow/.local/lib/python3.6/site-packages/airflow/utils/email.py", line 66, in send_email
    **kwargs,
  File "/home/airflow/.local/lib/python3.6/site-packages/airflow/utils/email.py", line 102, in send_email_smtp
    send_mime_email(e_from=smtp_mail_from, e_to=recipients, mime_msg=msg, conn_id=conn_id, dryrun=dryrun)
  File "/home/airflow/.local/lib/python3.6/site-packages/airflow/utils/email.py", line 210, in send_mime_email
    conn = _get_smtp_connection(smtp_host, smtp_port, smtp_timeout, smtp_ssl)
  File "/home/airflow/.local/lib/python3.6/site-packages/airflow/utils/email.py", line 244, in _get_smtp_connection
    else smtplib.SMTP(host=host, port=port, timeout=timeout)
  File "/usr/local/lib/python3.6/smtplib.py", line 251, in __init__
    (code, msg) = self.connect(host, port)
  File "/usr/local/lib/python3.6/smtplib.py", line 336, in connect
    self.sock = self._get_socket(host, port, self.timeout)
  File "/usr/local/lib/python3.6/smtplib.py", line 307, in _get_socket
    self.source_address)
  File "/usr/local/lib/python3.6/socket.py", line 724, in create_connection
    raise err
  File "/usr/local/lib/python3.6/socket.py", line 713, in create_connection
    sock.connect(sa)
OSError: [Errno 99] Cannot assign requested address

During handling of the above exception, another exception occurred:

Traceback (most recent call last):
  File "/home/airflow/.local/lib/python3.6/site-packages/airflow/models/taskinstance.py", line 1737, in handle_failure
    self.email_alert(error)
  File "/home/airflow/.local/lib/python3.6/site-packages/airflow/models/taskinstance.py", line 2191, in email_alert
    send_email(self.task.email, subject, html_content_err)
  File "/home/airflow/.local/lib/python3.6/site-packages/airflow/utils/email.py", line 66, in send_email
    **kwargs,
  File "/home/airflow/.local/lib/python3.6/site-packages/airflow/utils/email.py", line 102, in send_email_smtp
    send_mime_email(e_from=smtp_mail_from, e_to=recipients, mime_msg=msg, conn_id=conn_id, dryrun=dryrun)
  File "/home/airflow/.local/lib/python3.6/site-packages/airflow/utils/email.py", line 210, in send_mime_email
    conn = _get_smtp_connection(smtp_host, smtp_port, smtp_timeout, smtp_ssl)
  File "/home/airflow/.local/lib/python3.6/site-packages/airflow/utils/email.py", line 244, in _get_smtp_connection
    else smtplib.SMTP(host=host, port=port, timeout=timeout)
  File "/usr/local/lib/python3.6/smtplib.py", line 251, in __init__
    (code, msg) = self.connect(host, port)
  File "/usr/local/lib/python3.6/smtplib.py", line 336, in connect
    self.sock = self._get_socket(host, port, self.timeout)
  File "/usr/local/lib/python3.6/smtplib.py", line 307, in _get_socket
    self.source_address)
  File "/usr/local/lib/python3.6/socket.py", line 724, in create_connection
    raise err
  File "/usr/local/lib/python3.6/socket.py", line 713, in create_connection
    sock.connect(sa)
OSError: [Errno 99] Cannot assign requested address
[2021-10-26 17:33:25,629] {standard_task_runner.py:91} ERROR - Failed to execute job 24 for task spider_star
Traceback (most recent call last):
  File "/home/airflow/.local/lib/python3.6/site-packages/airflow/task/task_runner/standard_task_runner.py", line 85, in _start_by_fork
    args.func(args, dag=self.dag)
  File "/home/airflow/.local/lib/python3.6/site-packages/airflow/cli/cli_parser.py", line 48, in command
    return func(*args, **kwargs)
  File "/home/airflow/.local/lib/python3.6/site-packages/airflow/utils/cli.py", line 92, in wrapper
    return f(*args, **kwargs)
  File "/home/airflow/.local/lib/python3.6/site-packages/airflow/cli/commands/task_command.py", line 292, in task_run
    _run_task_by_selected_method(args, dag, ti)
  File "/home/airflow/.local/lib/python3.6/site-packages/airflow/cli/commands/task_command.py", line 107, in _run_task_by_selected_method
    _run_raw_task(args, ti)
  File "/home/airflow/.local/lib/python3.6/site-packages/airflow/cli/commands/task_command.py", line 184, in _run_raw_task
    error_file=args.error_file,
  File "/home/airflow/.local/lib/python3.6/site-packages/airflow/utils/session.py", line 70, in wrapper
    return func(*args, session=session, **kwargs)
  File "/home/airflow/.local/lib/python3.6/site-packages/airflow/models/taskinstance.py", line 1324, in _run_raw_task
    self._execute_task_with_callbacks(context)
  File "/home/airflow/.local/lib/python3.6/site-packages/airflow/models/taskinstance.py", line 1443, in _execute_task_with_callbacks
    result = self._execute_task(context, self.task)
  File "/home/airflow/.local/lib/python3.6/site-packages/airflow/models/taskinstance.py", line 1499, in _execute_task
    result = execute_callable(context=context)
  File "/home/airflow/.local/lib/python3.6/site-packages/airflow/operators/bash.py", line 188, in execute
    f'Bash command failed. The command returned a non-zero exit code {result.exit_code}.'
airflow.exceptions.AirflowException: Bash command failed. The command returned a non-zero exit code 127.
[2021-10-26 17:33:25,690] {local_task_job.py:154} INFO - Task exited with return code 1
[2021-10-26 17:33:25,757] {local_task_job.py:264} INFO - 0 downstream tasks scheduled from follow-on schedule check
[2021-10-26 17:35:02,984] {taskinstance.py:1035} INFO - Dependencies all met for <TaskInstance: scrapper.spider_star manual__2021-10-26T17:29:57.651606+00:00 [queued]>
[2021-10-26 17:35:03,024] {taskinstance.py:1035} INFO - Dependencies all met for <TaskInstance: scrapper.spider_star manual__2021-10-26T17:29:57.651606+00:00 [queued]>
[2021-10-26 17:35:03,025] {taskinstance.py:1241} INFO - 
--------------------------------------------------------------------------------
[2021-10-26 17:35:03,027] {taskinstance.py:1242} INFO - Starting attempt 2 of 2
[2021-10-26 17:35:03,028] {taskinstance.py:1243} INFO - 
--------------------------------------------------------------------------------
[2021-10-26 17:35:03,051] {taskinstance.py:1262} INFO - Executing <Task(BashOperator): spider_star> on 2021-10-26 17:29:57.651606+00:00
[2021-10-26 17:35:03,099] {standard_task_runner.py:76} INFO - Running: ['***', 'tasks', 'run', 'scrapper', 'spider_star', 'manual__2021-10-26T17:29:57.651606+00:00', '--job-id', '25', '--raw', '--subdir', 'DAGS_FOLDER/my_dag.py', '--cfg-path', '/tmp/tmpue34t7dv', '--error-file', '/tmp/tmpn3_siuvg']
[2021-10-26 17:35:03,112] {standard_task_runner.py:77} INFO - Job 25: Subtask spider_star
[2021-10-26 17:35:03,065] {standard_task_runner.py:52} INFO - Started process 13606 to run task
[2021-10-26 17:35:03,630] {logging_mixin.py:109} INFO - Running <TaskInstance: scrapper.spider_star manual__2021-10-26T17:29:57.651606+00:00 [running]> on host ebc91b274482
[2021-10-26 17:35:03,762] {taskinstance.py:1414} INFO - Exporting the following env vars:
AIRFLOW_CTX_DAG_EMAIL=octadelsueldo@gmail.com
AIRFLOW_CTX_DAG_OWNER=Octavio
AIRFLOW_CTX_DAG_ID=scrapper
AIRFLOW_CTX_TASK_ID=spider_star
AIRFLOW_CTX_EXECUTION_DATE=2021-10-26T17:29:57.651606+00:00
AIRFLOW_CTX_DAG_RUN_ID=manual__2021-10-26T17:29:57.651606+00:00
[2021-10-26 17:35:03,765] {subprocess.py:62} INFO - Tmp dir root location: 
 /tmp
[2021-10-26 17:35:03,769] {subprocess.py:74} INFO - Running command: ['bash', '-c', '${AIRFLOW_HOME}/***/dags/script/run_spider.sh ']
[2021-10-26 17:35:03,798] {subprocess.py:85} INFO - Output:
[2021-10-26 17:35:03,808] {subprocess.py:89} INFO - bash: /opt/***/***/dags/script/run_spider.sh: No such file or directory
[2021-10-26 17:35:03,817] {subprocess.py:93} INFO - Command exited with return code 127
[2021-10-26 17:35:03,838] {taskinstance.py:1686} ERROR - Task failed with exception
Traceback (most recent call last):
  File "/home/airflow/.local/lib/python3.6/site-packages/airflow/models/taskinstance.py", line 1324, in _run_raw_task
    self._execute_task_with_callbacks(context)
  File "/home/airflow/.local/lib/python3.6/site-packages/airflow/models/taskinstance.py", line 1443, in _execute_task_with_callbacks
    result = self._execute_task(context, self.task)
  File "/home/airflow/.local/lib/python3.6/site-packages/airflow/models/taskinstance.py", line 1499, in _execute_task
    result = execute_callable(context=context)
  File "/home/airflow/.local/lib/python3.6/site-packages/airflow/operators/bash.py", line 188, in execute
    f'Bash command failed. The command returned a non-zero exit code {result.exit_code}.'
airflow.exceptions.AirflowException: Bash command failed. The command returned a non-zero exit code 127.
[2021-10-26 17:35:03,892] {taskinstance.py:1280} INFO - Marking task as FAILED. dag_id=scrapper, task_id=spider_star, execution_date=20211026T172957, start_date=20211026T173502, end_date=20211026T173503
[2021-10-26 17:35:04,027] {warnings.py:99} WARNING - /home/***/.local/lib/python3.6/site-packages/***/utils/email.py:102: PendingDeprecationWarning: Fetching SMTP credentials from configuration variables will be deprecated in a future release. Please set credentials using a connection instead.
  send_mime_email(e_from=smtp_mail_from, e_to=recipients, mime_msg=msg, conn_id=conn_id, dryrun=dryrun)

[2021-10-26 17:35:04,030] {configuration.py:381} WARNING - section/key [smtp/smtp_user] not found in config
[2021-10-26 17:35:04,032] {email.py:208} INFO - Email alerting: attempt 1
[2021-10-26 17:35:04,069] {configuration.py:381} WARNING - section/key [smtp/smtp_user] not found in config
[2021-10-26 17:35:04,076] {email.py:208} INFO - Email alerting: attempt 1
[2021-10-26 17:35:04,080] {taskinstance.py:1739} ERROR - Failed to send email to: ['octadelsueldo@gmail.com']
Traceback (most recent call last):
  File "/home/airflow/.local/lib/python3.6/site-packages/airflow/models/taskinstance.py", line 1324, in _run_raw_task
    self._execute_task_with_callbacks(context)
  File "/home/airflow/.local/lib/python3.6/site-packages/airflow/models/taskinstance.py", line 1443, in _execute_task_with_callbacks
    result = self._execute_task(context, self.task)
  File "/home/airflow/.local/lib/python3.6/site-packages/airflow/models/taskinstance.py", line 1499, in _execute_task
    result = execute_callable(context=context)
  File "/home/airflow/.local/lib/python3.6/site-packages/airflow/operators/bash.py", line 188, in execute
    f'Bash command failed. The command returned a non-zero exit code {result.exit_code}.'
airflow.exceptions.AirflowException: Bash command failed. The command returned a non-zero exit code 127.

During handling of the above exception, another exception occurred:

Traceback (most recent call last):
  File "/home/airflow/.local/lib/python3.6/site-packages/airflow/models/taskinstance.py", line 2189, in email_alert
    send_email(self.task.email, subject, html_content)
  File "/home/airflow/.local/lib/python3.6/site-packages/airflow/utils/email.py", line 66, in send_email
    **kwargs,
  File "/home/airflow/.local/lib/python3.6/site-packages/airflow/utils/email.py", line 102, in send_email_smtp
    send_mime_email(e_from=smtp_mail_from, e_to=recipients, mime_msg=msg, conn_id=conn_id, dryrun=dryrun)
  File "/home/airflow/.local/lib/python3.6/site-packages/airflow/utils/email.py", line 210, in send_mime_email
    conn = _get_smtp_connection(smtp_host, smtp_port, smtp_timeout, smtp_ssl)
  File "/home/airflow/.local/lib/python3.6/site-packages/airflow/utils/email.py", line 244, in _get_smtp_connection
    else smtplib.SMTP(host=host, port=port, timeout=timeout)
  File "/usr/local/lib/python3.6/smtplib.py", line 251, in __init__
    (code, msg) = self.connect(host, port)
  File "/usr/local/lib/python3.6/smtplib.py", line 336, in connect
    self.sock = self._get_socket(host, port, self.timeout)
  File "/usr/local/lib/python3.6/smtplib.py", line 307, in _get_socket
    self.source_address)
  File "/usr/local/lib/python3.6/socket.py", line 724, in create_connection
    raise err
  File "/usr/local/lib/python3.6/socket.py", line 713, in create_connection
    sock.connect(sa)
OSError: [Errno 99] Cannot assign requested address

During handling of the above exception, another exception occurred:

Traceback (most recent call last):
  File "/home/airflow/.local/lib/python3.6/site-packages/airflow/models/taskinstance.py", line 1737, in handle_failure
    self.email_alert(error)
  File "/home/airflow/.local/lib/python3.6/site-packages/airflow/models/taskinstance.py", line 2191, in email_alert
    send_email(self.task.email, subject, html_content_err)
  File "/home/airflow/.local/lib/python3.6/site-packages/airflow/utils/email.py", line 66, in send_email
    **kwargs,
  File "/home/airflow/.local/lib/python3.6/site-packages/airflow/utils/email.py", line 102, in send_email_smtp
    send_mime_email(e_from=smtp_mail_from, e_to=recipients, mime_msg=msg, conn_id=conn_id, dryrun=dryrun)
  File "/home/airflow/.local/lib/python3.6/site-packages/airflow/utils/email.py", line 210, in send_mime_email
    conn = _get_smtp_connection(smtp_host, smtp_port, smtp_timeout, smtp_ssl)
  File "/home/airflow/.local/lib/python3.6/site-packages/airflow/utils/email.py", line 244, in _get_smtp_connection
    else smtplib.SMTP(host=host, port=port, timeout=timeout)
  File "/usr/local/lib/python3.6/smtplib.py", line 251, in __init__
    (code, msg) = self.connect(host, port)
  File "/usr/local/lib/python3.6/smtplib.py", line 336, in connect
    self.sock = self._get_socket(host, port, self.timeout)
  File "/usr/local/lib/python3.6/smtplib.py", line 307, in _get_socket
    self.source_address)
  File "/usr/local/lib/python3.6/socket.py", line 724, in create_connection
    raise err
  File "/usr/local/lib/python3.6/socket.py", line 713, in create_connection
    sock.connect(sa)
OSError: [Errno 99] Cannot assign requested address
[2021-10-26 17:35:04,151] {standard_task_runner.py:91} ERROR - Failed to execute job 25 for task spider_star
Traceback (most recent call last):
  File "/home/airflow/.local/lib/python3.6/site-packages/airflow/task/task_runner/standard_task_runner.py", line 85, in _start_by_fork
    args.func(args, dag=self.dag)
  File "/home/airflow/.local/lib/python3.6/site-packages/airflow/cli/cli_parser.py", line 48, in command
    return func(*args, **kwargs)
  File "/home/airflow/.local/lib/python3.6/site-packages/airflow/utils/cli.py", line 92, in wrapper
    return f(*args, **kwargs)
  File "/home/airflow/.local/lib/python3.6/site-packages/airflow/cli/commands/task_command.py", line 292, in task_run
    _run_task_by_selected_method(args, dag, ti)
  File "/home/airflow/.local/lib/python3.6/site-packages/airflow/cli/commands/task_command.py", line 107, in _run_task_by_selected_method
    _run_raw_task(args, ti)
  File "/home/airflow/.local/lib/python3.6/site-packages/airflow/cli/commands/task_command.py", line 184, in _run_raw_task
    error_file=args.error_file,
  File "/home/airflow/.local/lib/python3.6/site-packages/airflow/utils/session.py", line 70, in wrapper
    return func(*args, session=session, **kwargs)
  File "/home/airflow/.local/lib/python3.6/site-packages/airflow/models/taskinstance.py", line 1324, in _run_raw_task
    self._execute_task_with_callbacks(context)
  File "/home/airflow/.local/lib/python3.6/site-packages/airflow/models/taskinstance.py", line 1443, in _execute_task_with_callbacks
    result = self._execute_task(context, self.task)
  File "/home/airflow/.local/lib/python3.6/site-packages/airflow/models/taskinstance.py", line 1499, in _execute_task
    result = execute_callable(context=context)
  File "/home/airflow/.local/lib/python3.6/site-packages/airflow/operators/bash.py", line 188, in execute
    f'Bash command failed. The command returned a non-zero exit code {result.exit_code}.'
airflow.exceptions.AirflowException: Bash command failed. The command returned a non-zero exit code 127.
[2021-10-26 17:35:04,220] {local_task_job.py:154} INFO - Task exited with return code 1
[2021-10-26 17:35:04,402] {local_task_job.py:264} INFO - 0 downstream tasks scheduled from follow-on schedule check
[2021-10-26 17:38:20,295] {taskinstance.py:1035} INFO - Dependencies all met for <TaskInstance: scrapper.spider_star manual__2021-10-26T17:33:13.761818+00:00 [queued]>
[2021-10-26 17:38:20,407] {taskinstance.py:1035} INFO - Dependencies all met for <TaskInstance: scrapper.spider_star manual__2021-10-26T17:33:13.761818+00:00 [queued]>
[2021-10-26 17:38:20,408] {taskinstance.py:1241} INFO - 
--------------------------------------------------------------------------------
[2021-10-26 17:38:20,410] {taskinstance.py:1242} INFO - Starting attempt 2 of 2
[2021-10-26 17:38:20,413] {taskinstance.py:1243} INFO - 
--------------------------------------------------------------------------------
[2021-10-26 17:38:20,463] {taskinstance.py:1262} INFO - Executing <Task(BashOperator): spider_star> on 2021-10-26 17:33:13.761818+00:00
[2021-10-26 17:38:20,510] {standard_task_runner.py:76} INFO - Running: ['***', 'tasks', 'run', 'scrapper', 'spider_star', 'manual__2021-10-26T17:33:13.761818+00:00', '--job-id', '26', '--raw', '--subdir', 'DAGS_FOLDER/my_dag.py', '--cfg-path', '/tmp/tmpf_rbsj9b', '--error-file', '/tmp/tmpmrhgvqwq']
[2021-10-26 17:38:20,516] {standard_task_runner.py:77} INFO - Job 26: Subtask spider_star
[2021-10-26 17:38:20,478] {standard_task_runner.py:52} INFO - Started process 13750 to run task
[2021-10-26 17:38:20,717] {logging_mixin.py:109} INFO - Running <TaskInstance: scrapper.spider_star manual__2021-10-26T17:33:13.761818+00:00 [running]> on host ebc91b274482
[2021-10-26 17:38:20,889] {taskinstance.py:1414} INFO - Exporting the following env vars:
AIRFLOW_CTX_DAG_EMAIL=octadelsueldo@gmail.com
AIRFLOW_CTX_DAG_OWNER=Octavio
AIRFLOW_CTX_DAG_ID=scrapper
AIRFLOW_CTX_TASK_ID=spider_star
AIRFLOW_CTX_EXECUTION_DATE=2021-10-26T17:33:13.761818+00:00
AIRFLOW_CTX_DAG_RUN_ID=manual__2021-10-26T17:33:13.761818+00:00
[2021-10-26 17:38:20,899] {subprocess.py:62} INFO - Tmp dir root location: 
 /tmp
[2021-10-26 17:38:20,904] {subprocess.py:74} INFO - Running command: ['bash', '-c', '${AIRFLOW_HOME}/***/dags/script/run_spider.sh ']
[2021-10-26 17:38:20,968] {subprocess.py:85} INFO - Output:
[2021-10-26 17:38:20,973] {subprocess.py:89} INFO - bash: /opt/***/***/dags/script/run_spider.sh: No such file or directory
[2021-10-26 17:38:20,977] {subprocess.py:93} INFO - Command exited with return code 127
[2021-10-26 17:38:20,995] {taskinstance.py:1686} ERROR - Task failed with exception
Traceback (most recent call last):
  File "/home/airflow/.local/lib/python3.6/site-packages/airflow/models/taskinstance.py", line 1324, in _run_raw_task
    self._execute_task_with_callbacks(context)
  File "/home/airflow/.local/lib/python3.6/site-packages/airflow/models/taskinstance.py", line 1443, in _execute_task_with_callbacks
    result = self._execute_task(context, self.task)
  File "/home/airflow/.local/lib/python3.6/site-packages/airflow/models/taskinstance.py", line 1499, in _execute_task
    result = execute_callable(context=context)
  File "/home/airflow/.local/lib/python3.6/site-packages/airflow/operators/bash.py", line 188, in execute
    f'Bash command failed. The command returned a non-zero exit code {result.exit_code}.'
airflow.exceptions.AirflowException: Bash command failed. The command returned a non-zero exit code 127.
[2021-10-26 17:38:21,048] {taskinstance.py:1280} INFO - Marking task as FAILED. dag_id=scrapper, task_id=spider_star, execution_date=20211026T173313, start_date=20211026T173820, end_date=20211026T173821
[2021-10-26 17:38:21,112] {warnings.py:99} WARNING - /home/***/.local/lib/python3.6/site-packages/***/utils/email.py:102: PendingDeprecationWarning: Fetching SMTP credentials from configuration variables will be deprecated in a future release. Please set credentials using a connection instead.
  send_mime_email(e_from=smtp_mail_from, e_to=recipients, mime_msg=msg, conn_id=conn_id, dryrun=dryrun)

[2021-10-26 17:38:21,113] {configuration.py:381} WARNING - section/key [smtp/smtp_user] not found in config
[2021-10-26 17:38:21,116] {email.py:208} INFO - Email alerting: attempt 1
[2021-10-26 17:38:21,144] {configuration.py:381} WARNING - section/key [smtp/smtp_user] not found in config
[2021-10-26 17:38:21,145] {email.py:208} INFO - Email alerting: attempt 1
[2021-10-26 17:38:21,148] {taskinstance.py:1739} ERROR - Failed to send email to: ['octadelsueldo@gmail.com']
Traceback (most recent call last):
  File "/home/airflow/.local/lib/python3.6/site-packages/airflow/models/taskinstance.py", line 1324, in _run_raw_task
    self._execute_task_with_callbacks(context)
  File "/home/airflow/.local/lib/python3.6/site-packages/airflow/models/taskinstance.py", line 1443, in _execute_task_with_callbacks
    result = self._execute_task(context, self.task)
  File "/home/airflow/.local/lib/python3.6/site-packages/airflow/models/taskinstance.py", line 1499, in _execute_task
    result = execute_callable(context=context)
  File "/home/airflow/.local/lib/python3.6/site-packages/airflow/operators/bash.py", line 188, in execute
    f'Bash command failed. The command returned a non-zero exit code {result.exit_code}.'
airflow.exceptions.AirflowException: Bash command failed. The command returned a non-zero exit code 127.

During handling of the above exception, another exception occurred:

Traceback (most recent call last):
  File "/home/airflow/.local/lib/python3.6/site-packages/airflow/models/taskinstance.py", line 2189, in email_alert
    send_email(self.task.email, subject, html_content)
  File "/home/airflow/.local/lib/python3.6/site-packages/airflow/utils/email.py", line 66, in send_email
    **kwargs,
  File "/home/airflow/.local/lib/python3.6/site-packages/airflow/utils/email.py", line 102, in send_email_smtp
    send_mime_email(e_from=smtp_mail_from, e_to=recipients, mime_msg=msg, conn_id=conn_id, dryrun=dryrun)
  File "/home/airflow/.local/lib/python3.6/site-packages/airflow/utils/email.py", line 210, in send_mime_email
    conn = _get_smtp_connection(smtp_host, smtp_port, smtp_timeout, smtp_ssl)
  File "/home/airflow/.local/lib/python3.6/site-packages/airflow/utils/email.py", line 244, in _get_smtp_connection
    else smtplib.SMTP(host=host, port=port, timeout=timeout)
  File "/usr/local/lib/python3.6/smtplib.py", line 251, in __init__
    (code, msg) = self.connect(host, port)
  File "/usr/local/lib/python3.6/smtplib.py", line 336, in connect
    self.sock = self._get_socket(host, port, self.timeout)
  File "/usr/local/lib/python3.6/smtplib.py", line 307, in _get_socket
    self.source_address)
  File "/usr/local/lib/python3.6/socket.py", line 724, in create_connection
    raise err
  File "/usr/local/lib/python3.6/socket.py", line 713, in create_connection
    sock.connect(sa)
OSError: [Errno 99] Cannot assign requested address

During handling of the above exception, another exception occurred:

Traceback (most recent call last):
  File "/home/airflow/.local/lib/python3.6/site-packages/airflow/models/taskinstance.py", line 1737, in handle_failure
    self.email_alert(error)
  File "/home/airflow/.local/lib/python3.6/site-packages/airflow/models/taskinstance.py", line 2191, in email_alert
    send_email(self.task.email, subject, html_content_err)
  File "/home/airflow/.local/lib/python3.6/site-packages/airflow/utils/email.py", line 66, in send_email
    **kwargs,
  File "/home/airflow/.local/lib/python3.6/site-packages/airflow/utils/email.py", line 102, in send_email_smtp
    send_mime_email(e_from=smtp_mail_from, e_to=recipients, mime_msg=msg, conn_id=conn_id, dryrun=dryrun)
  File "/home/airflow/.local/lib/python3.6/site-packages/airflow/utils/email.py", line 210, in send_mime_email
    conn = _get_smtp_connection(smtp_host, smtp_port, smtp_timeout, smtp_ssl)
  File "/home/airflow/.local/lib/python3.6/site-packages/airflow/utils/email.py", line 244, in _get_smtp_connection
    else smtplib.SMTP(host=host, port=port, timeout=timeout)
  File "/usr/local/lib/python3.6/smtplib.py", line 251, in __init__
    (code, msg) = self.connect(host, port)
  File "/usr/local/lib/python3.6/smtplib.py", line 336, in connect
    self.sock = self._get_socket(host, port, self.timeout)
  File "/usr/local/lib/python3.6/smtplib.py", line 307, in _get_socket
    self.source_address)
  File "/usr/local/lib/python3.6/socket.py", line 724, in create_connection
    raise err
  File "/usr/local/lib/python3.6/socket.py", line 713, in create_connection
    sock.connect(sa)
OSError: [Errno 99] Cannot assign requested address
[2021-10-26 17:38:21,184] {standard_task_runner.py:91} ERROR - Failed to execute job 26 for task spider_star
Traceback (most recent call last):
  File "/home/airflow/.local/lib/python3.6/site-packages/airflow/task/task_runner/standard_task_runner.py", line 85, in _start_by_fork
    args.func(args, dag=self.dag)
  File "/home/airflow/.local/lib/python3.6/site-packages/airflow/cli/cli_parser.py", line 48, in command
    return func(*args, **kwargs)
  File "/home/airflow/.local/lib/python3.6/site-packages/airflow/utils/cli.py", line 92, in wrapper
    return f(*args, **kwargs)
  File "/home/airflow/.local/lib/python3.6/site-packages/airflow/cli/commands/task_command.py", line 292, in task_run
    _run_task_by_selected_method(args, dag, ti)
  File "/home/airflow/.local/lib/python3.6/site-packages/airflow/cli/commands/task_command.py", line 107, in _run_task_by_selected_method
    _run_raw_task(args, ti)
  File "/home/airflow/.local/lib/python3.6/site-packages/airflow/cli/commands/task_command.py", line 184, in _run_raw_task
    error_file=args.error_file,
  File "/home/airflow/.local/lib/python3.6/site-packages/airflow/utils/session.py", line 70, in wrapper
    return func(*args, session=session, **kwargs)
  File "/home/airflow/.local/lib/python3.6/site-packages/airflow/models/taskinstance.py", line 1324, in _run_raw_task
    self._execute_task_with_callbacks(context)
  File "/home/airflow/.local/lib/python3.6/site-packages/airflow/models/taskinstance.py", line 1443, in _execute_task_with_callbacks
    result = self._execute_task(context, self.task)
  File "/home/airflow/.local/lib/python3.6/site-packages/airflow/models/taskinstance.py", line 1499, in _execute_task
    result = execute_callable(context=context)
  File "/home/airflow/.local/lib/python3.6/site-packages/airflow/operators/bash.py", line 188, in execute
    f'Bash command failed. The command returned a non-zero exit code {result.exit_code}.'
airflow.exceptions.AirflowException: Bash command failed. The command returned a non-zero exit code 127.
[2021-10-26 17:38:21,243] {local_task_job.py:154} INFO - Task exited with return code 1
[2021-10-26 17:38:21,341] {local_task_job.py:264} INFO - 0 downstream tasks scheduled from follow-on schedule check
[2021-10-26 17:48:22,162] {taskinstance.py:1035} INFO - Dependencies all met for <TaskInstance: scrapper.spider_star manual__2021-10-26T17:43:18.731062+00:00 [queued]>
[2021-10-26 17:48:22,187] {taskinstance.py:1035} INFO - Dependencies all met for <TaskInstance: scrapper.spider_star manual__2021-10-26T17:43:18.731062+00:00 [queued]>
[2021-10-26 17:48:22,188] {taskinstance.py:1241} INFO - 
--------------------------------------------------------------------------------
[2021-10-26 17:48:22,189] {taskinstance.py:1242} INFO - Starting attempt 2 of 2
[2021-10-26 17:48:22,191] {taskinstance.py:1243} INFO - 
--------------------------------------------------------------------------------
[2021-10-26 17:48:22,211] {taskinstance.py:1262} INFO - Executing <Task(BashOperator): spider_star> on 2021-10-26 17:43:18.731062+00:00
[2021-10-26 17:48:22,221] {standard_task_runner.py:52} INFO - Started process 14197 to run task
[2021-10-26 17:48:22,225] {standard_task_runner.py:76} INFO - Running: ['***', 'tasks', 'run', 'scrapper', 'spider_star', 'manual__2021-10-26T17:43:18.731062+00:00', '--job-id', '28', '--raw', '--subdir', 'DAGS_FOLDER/my_dag.py', '--cfg-path', '/tmp/tmpj969tva5', '--error-file', '/tmp/tmp1dkhu22e']
[2021-10-26 17:48:22,237] {standard_task_runner.py:77} INFO - Job 28: Subtask spider_star
[2021-10-26 17:48:22,299] {logging_mixin.py:109} INFO - Running <TaskInstance: scrapper.spider_star manual__2021-10-26T17:43:18.731062+00:00 [running]> on host ebc91b274482
[2021-10-26 17:48:22,356] {taskinstance.py:1414} INFO - Exporting the following env vars:
AIRFLOW_CTX_DAG_EMAIL=octadelsueldo@gmail.com
AIRFLOW_CTX_DAG_OWNER=Octavio
AIRFLOW_CTX_DAG_ID=scrapper
AIRFLOW_CTX_TASK_ID=spider_star
AIRFLOW_CTX_EXECUTION_DATE=2021-10-26T17:43:18.731062+00:00
AIRFLOW_CTX_DAG_RUN_ID=manual__2021-10-26T17:43:18.731062+00:00
[2021-10-26 17:48:22,359] {subprocess.py:62} INFO - Tmp dir root location: 
 /tmp
[2021-10-26 17:48:22,361] {subprocess.py:74} INFO - Running command: ['bash', '-c', 'cd ./***/dags/script;bash run_spider.sh ']
[2021-10-26 17:48:22,374] {subprocess.py:85} INFO - Output:
[2021-10-26 17:48:22,376] {subprocess.py:89} INFO - bash: line 0: cd: ./***/dags/script: No such file or directory
[2021-10-26 17:48:22,379] {subprocess.py:89} INFO - bash: run_spider.sh: No such file or directory
[2021-10-26 17:48:22,380] {subprocess.py:93} INFO - Command exited with return code 127
[2021-10-26 17:48:22,384] {taskinstance.py:1686} ERROR - Task failed with exception
Traceback (most recent call last):
  File "/home/airflow/.local/lib/python3.6/site-packages/airflow/models/taskinstance.py", line 1324, in _run_raw_task
    self._execute_task_with_callbacks(context)
  File "/home/airflow/.local/lib/python3.6/site-packages/airflow/models/taskinstance.py", line 1443, in _execute_task_with_callbacks
    result = self._execute_task(context, self.task)
  File "/home/airflow/.local/lib/python3.6/site-packages/airflow/models/taskinstance.py", line 1499, in _execute_task
    result = execute_callable(context=context)
  File "/home/airflow/.local/lib/python3.6/site-packages/airflow/operators/bash.py", line 188, in execute
    f'Bash command failed. The command returned a non-zero exit code {result.exit_code}.'
airflow.exceptions.AirflowException: Bash command failed. The command returned a non-zero exit code 127.
[2021-10-26 17:48:22,411] {taskinstance.py:1280} INFO - Marking task as FAILED. dag_id=scrapper, task_id=spider_star, execution_date=20211026T174318, start_date=20211026T174822, end_date=20211026T174822
[2021-10-26 17:48:22,428] {warnings.py:99} WARNING - /home/***/.local/lib/python3.6/site-packages/***/utils/email.py:102: PendingDeprecationWarning: Fetching SMTP credentials from configuration variables will be deprecated in a future release. Please set credentials using a connection instead.
  send_mime_email(e_from=smtp_mail_from, e_to=recipients, mime_msg=msg, conn_id=conn_id, dryrun=dryrun)

[2021-10-26 17:48:22,430] {configuration.py:381} WARNING - section/key [smtp/smtp_user] not found in config
[2021-10-26 17:48:22,432] {email.py:208} INFO - Email alerting: attempt 1
[2021-10-26 17:48:22,446] {configuration.py:381} WARNING - section/key [smtp/smtp_user] not found in config
[2021-10-26 17:48:22,447] {email.py:208} INFO - Email alerting: attempt 1
[2021-10-26 17:48:22,448] {taskinstance.py:1739} ERROR - Failed to send email to: ['octadelsueldo@gmail.com']
Traceback (most recent call last):
  File "/home/airflow/.local/lib/python3.6/site-packages/airflow/models/taskinstance.py", line 1324, in _run_raw_task
    self._execute_task_with_callbacks(context)
  File "/home/airflow/.local/lib/python3.6/site-packages/airflow/models/taskinstance.py", line 1443, in _execute_task_with_callbacks
    result = self._execute_task(context, self.task)
  File "/home/airflow/.local/lib/python3.6/site-packages/airflow/models/taskinstance.py", line 1499, in _execute_task
    result = execute_callable(context=context)
  File "/home/airflow/.local/lib/python3.6/site-packages/airflow/operators/bash.py", line 188, in execute
    f'Bash command failed. The command returned a non-zero exit code {result.exit_code}.'
airflow.exceptions.AirflowException: Bash command failed. The command returned a non-zero exit code 127.

During handling of the above exception, another exception occurred:

Traceback (most recent call last):
  File "/home/airflow/.local/lib/python3.6/site-packages/airflow/models/taskinstance.py", line 2189, in email_alert
    send_email(self.task.email, subject, html_content)
  File "/home/airflow/.local/lib/python3.6/site-packages/airflow/utils/email.py", line 66, in send_email
    **kwargs,
  File "/home/airflow/.local/lib/python3.6/site-packages/airflow/utils/email.py", line 102, in send_email_smtp
    send_mime_email(e_from=smtp_mail_from, e_to=recipients, mime_msg=msg, conn_id=conn_id, dryrun=dryrun)
  File "/home/airflow/.local/lib/python3.6/site-packages/airflow/utils/email.py", line 210, in send_mime_email
    conn = _get_smtp_connection(smtp_host, smtp_port, smtp_timeout, smtp_ssl)
  File "/home/airflow/.local/lib/python3.6/site-packages/airflow/utils/email.py", line 244, in _get_smtp_connection
    else smtplib.SMTP(host=host, port=port, timeout=timeout)
  File "/usr/local/lib/python3.6/smtplib.py", line 251, in __init__
    (code, msg) = self.connect(host, port)
  File "/usr/local/lib/python3.6/smtplib.py", line 336, in connect
    self.sock = self._get_socket(host, port, self.timeout)
  File "/usr/local/lib/python3.6/smtplib.py", line 307, in _get_socket
    self.source_address)
  File "/usr/local/lib/python3.6/socket.py", line 724, in create_connection
    raise err
  File "/usr/local/lib/python3.6/socket.py", line 713, in create_connection
    sock.connect(sa)
OSError: [Errno 99] Cannot assign requested address

During handling of the above exception, another exception occurred:

Traceback (most recent call last):
  File "/home/airflow/.local/lib/python3.6/site-packages/airflow/models/taskinstance.py", line 1737, in handle_failure
    self.email_alert(error)
  File "/home/airflow/.local/lib/python3.6/site-packages/airflow/models/taskinstance.py", line 2191, in email_alert
    send_email(self.task.email, subject, html_content_err)
  File "/home/airflow/.local/lib/python3.6/site-packages/airflow/utils/email.py", line 66, in send_email
    **kwargs,
  File "/home/airflow/.local/lib/python3.6/site-packages/airflow/utils/email.py", line 102, in send_email_smtp
    send_mime_email(e_from=smtp_mail_from, e_to=recipients, mime_msg=msg, conn_id=conn_id, dryrun=dryrun)
  File "/home/airflow/.local/lib/python3.6/site-packages/airflow/utils/email.py", line 210, in send_mime_email
    conn = _get_smtp_connection(smtp_host, smtp_port, smtp_timeout, smtp_ssl)
  File "/home/airflow/.local/lib/python3.6/site-packages/airflow/utils/email.py", line 244, in _get_smtp_connection
    else smtplib.SMTP(host=host, port=port, timeout=timeout)
  File "/usr/local/lib/python3.6/smtplib.py", line 251, in __init__
    (code, msg) = self.connect(host, port)
  File "/usr/local/lib/python3.6/smtplib.py", line 336, in connect
    self.sock = self._get_socket(host, port, self.timeout)
  File "/usr/local/lib/python3.6/smtplib.py", line 307, in _get_socket
    self.source_address)
  File "/usr/local/lib/python3.6/socket.py", line 724, in create_connection
    raise err
  File "/usr/local/lib/python3.6/socket.py", line 713, in create_connection
    sock.connect(sa)
OSError: [Errno 99] Cannot assign requested address
[2021-10-26 17:48:22,468] {standard_task_runner.py:91} ERROR - Failed to execute job 28 for task spider_star
Traceback (most recent call last):
  File "/home/airflow/.local/lib/python3.6/site-packages/airflow/task/task_runner/standard_task_runner.py", line 85, in _start_by_fork
    args.func(args, dag=self.dag)
  File "/home/airflow/.local/lib/python3.6/site-packages/airflow/cli/cli_parser.py", line 48, in command
    return func(*args, **kwargs)
  File "/home/airflow/.local/lib/python3.6/site-packages/airflow/utils/cli.py", line 92, in wrapper
    return f(*args, **kwargs)
  File "/home/airflow/.local/lib/python3.6/site-packages/airflow/cli/commands/task_command.py", line 292, in task_run
    _run_task_by_selected_method(args, dag, ti)
  File "/home/airflow/.local/lib/python3.6/site-packages/airflow/cli/commands/task_command.py", line 107, in _run_task_by_selected_method
    _run_raw_task(args, ti)
  File "/home/airflow/.local/lib/python3.6/site-packages/airflow/cli/commands/task_command.py", line 184, in _run_raw_task
    error_file=args.error_file,
  File "/home/airflow/.local/lib/python3.6/site-packages/airflow/utils/session.py", line 70, in wrapper
    return func(*args, session=session, **kwargs)
  File "/home/airflow/.local/lib/python3.6/site-packages/airflow/models/taskinstance.py", line 1324, in _run_raw_task
    self._execute_task_with_callbacks(context)
  File "/home/airflow/.local/lib/python3.6/site-packages/airflow/models/taskinstance.py", line 1443, in _execute_task_with_callbacks
    result = self._execute_task(context, self.task)
  File "/home/airflow/.local/lib/python3.6/site-packages/airflow/models/taskinstance.py", line 1499, in _execute_task
    result = execute_callable(context=context)
  File "/home/airflow/.local/lib/python3.6/site-packages/airflow/operators/bash.py", line 188, in execute
    f'Bash command failed. The command returned a non-zero exit code {result.exit_code}.'
airflow.exceptions.AirflowException: Bash command failed. The command returned a non-zero exit code 127.
[2021-10-26 17:48:22,491] {local_task_job.py:154} INFO - Task exited with return code 1
[2021-10-26 17:48:22,533] {local_task_job.py:264} INFO - 0 downstream tasks scheduled from follow-on schedule check
[2021-10-26 17:55:19,478] {taskinstance.py:1035} INFO - Dependencies all met for <TaskInstance: scrapper.spider_star manual__2021-10-26T17:50:13.477837+00:00 [queued]>
[2021-10-26 17:55:19,553] {taskinstance.py:1035} INFO - Dependencies all met for <TaskInstance: scrapper.spider_star manual__2021-10-26T17:50:13.477837+00:00 [queued]>
[2021-10-26 17:55:19,555] {taskinstance.py:1241} INFO - 
--------------------------------------------------------------------------------
[2021-10-26 17:55:19,557] {taskinstance.py:1242} INFO - Starting attempt 2 of 2
[2021-10-26 17:55:19,558] {taskinstance.py:1243} INFO - 
--------------------------------------------------------------------------------
[2021-10-26 17:55:19,628] {taskinstance.py:1262} INFO - Executing <Task(BashOperator): spider_star> on 2021-10-26 17:50:13.477837+00:00
[2021-10-26 17:55:19,674] {standard_task_runner.py:76} INFO - Running: ['***', 'tasks', 'run', 'scrapper', 'spider_star', 'manual__2021-10-26T17:50:13.477837+00:00', '--job-id', '30', '--raw', '--subdir', 'DAGS_FOLDER/my_dag.py', '--cfg-path', '/tmp/tmpr55oybek', '--error-file', '/tmp/tmp9igww3ho']
[2021-10-26 17:55:19,677] {standard_task_runner.py:77} INFO - Job 30: Subtask spider_star
[2021-10-26 17:55:19,648] {standard_task_runner.py:52} INFO - Started process 14509 to run task
[2021-10-26 17:55:19,842] {logging_mixin.py:109} INFO - Running <TaskInstance: scrapper.spider_star manual__2021-10-26T17:50:13.477837+00:00 [running]> on host ebc91b274482
[2021-10-26 17:55:20,014] {taskinstance.py:1414} INFO - Exporting the following env vars:
AIRFLOW_CTX_DAG_EMAIL=octadelsueldo@gmail.com
AIRFLOW_CTX_DAG_OWNER=Octavio
AIRFLOW_CTX_DAG_ID=scrapper
AIRFLOW_CTX_TASK_ID=spider_star
AIRFLOW_CTX_EXECUTION_DATE=2021-10-26T17:50:13.477837+00:00
AIRFLOW_CTX_DAG_RUN_ID=manual__2021-10-26T17:50:13.477837+00:00
[2021-10-26 17:55:20,019] {subprocess.py:62} INFO - Tmp dir root location: 
 /tmp
[2021-10-26 17:55:20,024] {subprocess.py:74} INFO - Running command: ['bash', '-c', 'cd opt/***/dags/script/run_spider.sh ']
[2021-10-26 17:55:20,085] {subprocess.py:85} INFO - Output:
[2021-10-26 17:55:20,091] {subprocess.py:89} INFO - bash: line 0: cd: opt/***/dags/script/run_spider.sh: No such file or directory
[2021-10-26 17:55:20,095] {subprocess.py:93} INFO - Command exited with return code 1
[2021-10-26 17:55:20,116] {taskinstance.py:1686} ERROR - Task failed with exception
Traceback (most recent call last):
  File "/home/airflow/.local/lib/python3.6/site-packages/airflow/models/taskinstance.py", line 1324, in _run_raw_task
    self._execute_task_with_callbacks(context)
  File "/home/airflow/.local/lib/python3.6/site-packages/airflow/models/taskinstance.py", line 1443, in _execute_task_with_callbacks
    result = self._execute_task(context, self.task)
  File "/home/airflow/.local/lib/python3.6/site-packages/airflow/models/taskinstance.py", line 1499, in _execute_task
    result = execute_callable(context=context)
  File "/home/airflow/.local/lib/python3.6/site-packages/airflow/operators/bash.py", line 188, in execute
    f'Bash command failed. The command returned a non-zero exit code {result.exit_code}.'
airflow.exceptions.AirflowException: Bash command failed. The command returned a non-zero exit code 1.
[2021-10-26 17:55:20,167] {taskinstance.py:1280} INFO - Marking task as FAILED. dag_id=scrapper, task_id=spider_star, execution_date=20211026T175013, start_date=20211026T175519, end_date=20211026T175520
[2021-10-26 17:55:20,206] {warnings.py:99} WARNING - /home/***/.local/lib/python3.6/site-packages/***/utils/email.py:102: PendingDeprecationWarning: Fetching SMTP credentials from configuration variables will be deprecated in a future release. Please set credentials using a connection instead.
  send_mime_email(e_from=smtp_mail_from, e_to=recipients, mime_msg=msg, conn_id=conn_id, dryrun=dryrun)

[2021-10-26 17:55:20,207] {configuration.py:381} WARNING - section/key [smtp/smtp_user] not found in config
[2021-10-26 17:55:20,208] {email.py:208} INFO - Email alerting: attempt 1
[2021-10-26 17:55:20,233] {configuration.py:381} WARNING - section/key [smtp/smtp_user] not found in config
[2021-10-26 17:55:20,234] {email.py:208} INFO - Email alerting: attempt 1
[2021-10-26 17:55:20,236] {taskinstance.py:1739} ERROR - Failed to send email to: ['octadelsueldo@gmail.com']
Traceback (most recent call last):
  File "/home/airflow/.local/lib/python3.6/site-packages/airflow/models/taskinstance.py", line 1324, in _run_raw_task
    self._execute_task_with_callbacks(context)
  File "/home/airflow/.local/lib/python3.6/site-packages/airflow/models/taskinstance.py", line 1443, in _execute_task_with_callbacks
    result = self._execute_task(context, self.task)
  File "/home/airflow/.local/lib/python3.6/site-packages/airflow/models/taskinstance.py", line 1499, in _execute_task
    result = execute_callable(context=context)
  File "/home/airflow/.local/lib/python3.6/site-packages/airflow/operators/bash.py", line 188, in execute
    f'Bash command failed. The command returned a non-zero exit code {result.exit_code}.'
airflow.exceptions.AirflowException: Bash command failed. The command returned a non-zero exit code 1.

During handling of the above exception, another exception occurred:

Traceback (most recent call last):
  File "/home/airflow/.local/lib/python3.6/site-packages/airflow/models/taskinstance.py", line 2189, in email_alert
    send_email(self.task.email, subject, html_content)
  File "/home/airflow/.local/lib/python3.6/site-packages/airflow/utils/email.py", line 66, in send_email
    **kwargs,
  File "/home/airflow/.local/lib/python3.6/site-packages/airflow/utils/email.py", line 102, in send_email_smtp
    send_mime_email(e_from=smtp_mail_from, e_to=recipients, mime_msg=msg, conn_id=conn_id, dryrun=dryrun)
  File "/home/airflow/.local/lib/python3.6/site-packages/airflow/utils/email.py", line 210, in send_mime_email
    conn = _get_smtp_connection(smtp_host, smtp_port, smtp_timeout, smtp_ssl)
  File "/home/airflow/.local/lib/python3.6/site-packages/airflow/utils/email.py", line 244, in _get_smtp_connection
    else smtplib.SMTP(host=host, port=port, timeout=timeout)
  File "/usr/local/lib/python3.6/smtplib.py", line 251, in __init__
    (code, msg) = self.connect(host, port)
  File "/usr/local/lib/python3.6/smtplib.py", line 336, in connect
    self.sock = self._get_socket(host, port, self.timeout)
  File "/usr/local/lib/python3.6/smtplib.py", line 307, in _get_socket
    self.source_address)
  File "/usr/local/lib/python3.6/socket.py", line 724, in create_connection
    raise err
  File "/usr/local/lib/python3.6/socket.py", line 713, in create_connection
    sock.connect(sa)
OSError: [Errno 99] Cannot assign requested address

During handling of the above exception, another exception occurred:

Traceback (most recent call last):
  File "/home/airflow/.local/lib/python3.6/site-packages/airflow/models/taskinstance.py", line 1737, in handle_failure
    self.email_alert(error)
  File "/home/airflow/.local/lib/python3.6/site-packages/airflow/models/taskinstance.py", line 2191, in email_alert
    send_email(self.task.email, subject, html_content_err)
  File "/home/airflow/.local/lib/python3.6/site-packages/airflow/utils/email.py", line 66, in send_email
    **kwargs,
  File "/home/airflow/.local/lib/python3.6/site-packages/airflow/utils/email.py", line 102, in send_email_smtp
    send_mime_email(e_from=smtp_mail_from, e_to=recipients, mime_msg=msg, conn_id=conn_id, dryrun=dryrun)
  File "/home/airflow/.local/lib/python3.6/site-packages/airflow/utils/email.py", line 210, in send_mime_email
    conn = _get_smtp_connection(smtp_host, smtp_port, smtp_timeout, smtp_ssl)
  File "/home/airflow/.local/lib/python3.6/site-packages/airflow/utils/email.py", line 244, in _get_smtp_connection
    else smtplib.SMTP(host=host, port=port, timeout=timeout)
  File "/usr/local/lib/python3.6/smtplib.py", line 251, in __init__
    (code, msg) = self.connect(host, port)
  File "/usr/local/lib/python3.6/smtplib.py", line 336, in connect
    self.sock = self._get_socket(host, port, self.timeout)
  File "/usr/local/lib/python3.6/smtplib.py", line 307, in _get_socket
    self.source_address)
  File "/usr/local/lib/python3.6/socket.py", line 724, in create_connection
    raise err
  File "/usr/local/lib/python3.6/socket.py", line 713, in create_connection
    sock.connect(sa)
OSError: [Errno 99] Cannot assign requested address
[2021-10-26 17:55:20,284] {standard_task_runner.py:91} ERROR - Failed to execute job 30 for task spider_star
Traceback (most recent call last):
  File "/home/airflow/.local/lib/python3.6/site-packages/airflow/task/task_runner/standard_task_runner.py", line 85, in _start_by_fork
    args.func(args, dag=self.dag)
  File "/home/airflow/.local/lib/python3.6/site-packages/airflow/cli/cli_parser.py", line 48, in command
    return func(*args, **kwargs)
  File "/home/airflow/.local/lib/python3.6/site-packages/airflow/utils/cli.py", line 92, in wrapper
    return f(*args, **kwargs)
  File "/home/airflow/.local/lib/python3.6/site-packages/airflow/cli/commands/task_command.py", line 292, in task_run
    _run_task_by_selected_method(args, dag, ti)
  File "/home/airflow/.local/lib/python3.6/site-packages/airflow/cli/commands/task_command.py", line 107, in _run_task_by_selected_method
    _run_raw_task(args, ti)
  File "/home/airflow/.local/lib/python3.6/site-packages/airflow/cli/commands/task_command.py", line 184, in _run_raw_task
    error_file=args.error_file,
  File "/home/airflow/.local/lib/python3.6/site-packages/airflow/utils/session.py", line 70, in wrapper
    return func(*args, session=session, **kwargs)
  File "/home/airflow/.local/lib/python3.6/site-packages/airflow/models/taskinstance.py", line 1324, in _run_raw_task
    self._execute_task_with_callbacks(context)
  File "/home/airflow/.local/lib/python3.6/site-packages/airflow/models/taskinstance.py", line 1443, in _execute_task_with_callbacks
    result = self._execute_task(context, self.task)
  File "/home/airflow/.local/lib/python3.6/site-packages/airflow/models/taskinstance.py", line 1499, in _execute_task
    result = execute_callable(context=context)
  File "/home/airflow/.local/lib/python3.6/site-packages/airflow/operators/bash.py", line 188, in execute
    f'Bash command failed. The command returned a non-zero exit code {result.exit_code}.'
airflow.exceptions.AirflowException: Bash command failed. The command returned a non-zero exit code 1.
[2021-10-26 17:55:20,365] {local_task_job.py:154} INFO - Task exited with return code 1
[2021-10-26 17:55:20,485] {local_task_job.py:264} INFO - 0 downstream tasks scheduled from follow-on schedule check
[2021-10-26 18:08:03,836] {taskinstance.py:1035} INFO - Dependencies all met for <TaskInstance: scrapper.spider_star manual__2021-10-26T18:02:58.521063+00:00 [queued]>
[2021-10-26 18:08:03,882] {taskinstance.py:1035} INFO - Dependencies all met for <TaskInstance: scrapper.spider_star manual__2021-10-26T18:02:58.521063+00:00 [queued]>
[2021-10-26 18:08:03,883] {taskinstance.py:1241} INFO - 
--------------------------------------------------------------------------------
[2021-10-26 18:08:03,885] {taskinstance.py:1242} INFO - Starting attempt 2 of 2
[2021-10-26 18:08:03,886] {taskinstance.py:1243} INFO - 
--------------------------------------------------------------------------------
[2021-10-26 18:08:03,917] {taskinstance.py:1262} INFO - Executing <Task(BashOperator): spider_star> on 2021-10-26 18:02:58.521063+00:00
[2021-10-26 18:08:03,940] {standard_task_runner.py:76} INFO - Running: ['***', 'tasks', 'run', 'scrapper', 'spider_star', 'manual__2021-10-26T18:02:58.521063+00:00', '--job-id', '33', '--raw', '--subdir', 'DAGS_FOLDER/my_dag.py', '--cfg-path', '/tmp/tmpj4zosoj0', '--error-file', '/tmp/tmps610z468']
[2021-10-26 18:08:03,952] {standard_task_runner.py:77} INFO - Job 33: Subtask spider_star
[2021-10-26 18:08:03,933] {standard_task_runner.py:52} INFO - Started process 15076 to run task
[2021-10-26 18:08:04,054] {logging_mixin.py:109} INFO - Running <TaskInstance: scrapper.spider_star manual__2021-10-26T18:02:58.521063+00:00 [running]> on host ebc91b274482
[2021-10-26 18:08:04,175] {taskinstance.py:1414} INFO - Exporting the following env vars:
AIRFLOW_CTX_DAG_EMAIL=octadelsueldo@gmail.com
AIRFLOW_CTX_DAG_OWNER=Octavio
AIRFLOW_CTX_DAG_ID=scrapper
AIRFLOW_CTX_TASK_ID=spider_star
AIRFLOW_CTX_EXECUTION_DATE=2021-10-26T18:02:58.521063+00:00
AIRFLOW_CTX_DAG_RUN_ID=manual__2021-10-26T18:02:58.521063+00:00
[2021-10-26 18:08:04,179] {subprocess.py:62} INFO - Tmp dir root location: 
 /tmp
[2021-10-26 18:08:04,183] {subprocess.py:74} INFO - Running command: ['bash', '-c', '/dags/script/run_spider.sh ']
[2021-10-26 18:08:04,227] {subprocess.py:85} INFO - Output:
[2021-10-26 18:08:04,233] {subprocess.py:89} INFO - bash: /dags/script/run_spider.sh: No such file or directory
[2021-10-26 18:08:04,236] {subprocess.py:93} INFO - Command exited with return code 127
[2021-10-26 18:08:04,249] {taskinstance.py:1686} ERROR - Task failed with exception
Traceback (most recent call last):
  File "/home/airflow/.local/lib/python3.6/site-packages/airflow/models/taskinstance.py", line 1324, in _run_raw_task
    self._execute_task_with_callbacks(context)
  File "/home/airflow/.local/lib/python3.6/site-packages/airflow/models/taskinstance.py", line 1443, in _execute_task_with_callbacks
    result = self._execute_task(context, self.task)
  File "/home/airflow/.local/lib/python3.6/site-packages/airflow/models/taskinstance.py", line 1499, in _execute_task
    result = execute_callable(context=context)
  File "/home/airflow/.local/lib/python3.6/site-packages/airflow/operators/bash.py", line 188, in execute
    f'Bash command failed. The command returned a non-zero exit code {result.exit_code}.'
airflow.exceptions.AirflowException: Bash command failed. The command returned a non-zero exit code 127.
[2021-10-26 18:08:04,286] {taskinstance.py:1280} INFO - Marking task as FAILED. dag_id=scrapper, task_id=spider_star, execution_date=20211026T180258, start_date=20211026T180803, end_date=20211026T180804
[2021-10-26 18:08:04,314] {warnings.py:99} WARNING - /home/***/.local/lib/python3.6/site-packages/***/utils/email.py:102: PendingDeprecationWarning: Fetching SMTP credentials from configuration variables will be deprecated in a future release. Please set credentials using a connection instead.
  send_mime_email(e_from=smtp_mail_from, e_to=recipients, mime_msg=msg, conn_id=conn_id, dryrun=dryrun)

[2021-10-26 18:08:04,319] {configuration.py:381} WARNING - section/key [smtp/smtp_user] not found in config
[2021-10-26 18:08:04,322] {email.py:208} INFO - Email alerting: attempt 1
[2021-10-26 18:08:04,349] {configuration.py:381} WARNING - section/key [smtp/smtp_user] not found in config
[2021-10-26 18:08:04,350] {email.py:208} INFO - Email alerting: attempt 1
[2021-10-26 18:08:04,353] {taskinstance.py:1739} ERROR - Failed to send email to: ['octadelsueldo@gmail.com']
Traceback (most recent call last):
  File "/home/airflow/.local/lib/python3.6/site-packages/airflow/models/taskinstance.py", line 1324, in _run_raw_task
    self._execute_task_with_callbacks(context)
  File "/home/airflow/.local/lib/python3.6/site-packages/airflow/models/taskinstance.py", line 1443, in _execute_task_with_callbacks
    result = self._execute_task(context, self.task)
  File "/home/airflow/.local/lib/python3.6/site-packages/airflow/models/taskinstance.py", line 1499, in _execute_task
    result = execute_callable(context=context)
  File "/home/airflow/.local/lib/python3.6/site-packages/airflow/operators/bash.py", line 188, in execute
    f'Bash command failed. The command returned a non-zero exit code {result.exit_code}.'
airflow.exceptions.AirflowException: Bash command failed. The command returned a non-zero exit code 127.

During handling of the above exception, another exception occurred:

Traceback (most recent call last):
  File "/home/airflow/.local/lib/python3.6/site-packages/airflow/models/taskinstance.py", line 2189, in email_alert
    send_email(self.task.email, subject, html_content)
  File "/home/airflow/.local/lib/python3.6/site-packages/airflow/utils/email.py", line 66, in send_email
    **kwargs,
  File "/home/airflow/.local/lib/python3.6/site-packages/airflow/utils/email.py", line 102, in send_email_smtp
    send_mime_email(e_from=smtp_mail_from, e_to=recipients, mime_msg=msg, conn_id=conn_id, dryrun=dryrun)
  File "/home/airflow/.local/lib/python3.6/site-packages/airflow/utils/email.py", line 210, in send_mime_email
    conn = _get_smtp_connection(smtp_host, smtp_port, smtp_timeout, smtp_ssl)
  File "/home/airflow/.local/lib/python3.6/site-packages/airflow/utils/email.py", line 244, in _get_smtp_connection
    else smtplib.SMTP(host=host, port=port, timeout=timeout)
  File "/usr/local/lib/python3.6/smtplib.py", line 251, in __init__
    (code, msg) = self.connect(host, port)
  File "/usr/local/lib/python3.6/smtplib.py", line 336, in connect
    self.sock = self._get_socket(host, port, self.timeout)
  File "/usr/local/lib/python3.6/smtplib.py", line 307, in _get_socket
    self.source_address)
  File "/usr/local/lib/python3.6/socket.py", line 724, in create_connection
    raise err
  File "/usr/local/lib/python3.6/socket.py", line 713, in create_connection
    sock.connect(sa)
OSError: [Errno 99] Cannot assign requested address

During handling of the above exception, another exception occurred:

Traceback (most recent call last):
  File "/home/airflow/.local/lib/python3.6/site-packages/airflow/models/taskinstance.py", line 1737, in handle_failure
    self.email_alert(error)
  File "/home/airflow/.local/lib/python3.6/site-packages/airflow/models/taskinstance.py", line 2191, in email_alert
    send_email(self.task.email, subject, html_content_err)
  File "/home/airflow/.local/lib/python3.6/site-packages/airflow/utils/email.py", line 66, in send_email
    **kwargs,
  File "/home/airflow/.local/lib/python3.6/site-packages/airflow/utils/email.py", line 102, in send_email_smtp
    send_mime_email(e_from=smtp_mail_from, e_to=recipients, mime_msg=msg, conn_id=conn_id, dryrun=dryrun)
  File "/home/airflow/.local/lib/python3.6/site-packages/airflow/utils/email.py", line 210, in send_mime_email
    conn = _get_smtp_connection(smtp_host, smtp_port, smtp_timeout, smtp_ssl)
  File "/home/airflow/.local/lib/python3.6/site-packages/airflow/utils/email.py", line 244, in _get_smtp_connection
    else smtplib.SMTP(host=host, port=port, timeout=timeout)
  File "/usr/local/lib/python3.6/smtplib.py", line 251, in __init__
    (code, msg) = self.connect(host, port)
  File "/usr/local/lib/python3.6/smtplib.py", line 336, in connect
    self.sock = self._get_socket(host, port, self.timeout)
  File "/usr/local/lib/python3.6/smtplib.py", line 307, in _get_socket
    self.source_address)
  File "/usr/local/lib/python3.6/socket.py", line 724, in create_connection
    raise err
  File "/usr/local/lib/python3.6/socket.py", line 713, in create_connection
    sock.connect(sa)
OSError: [Errno 99] Cannot assign requested address
[2021-10-26 18:08:04,384] {standard_task_runner.py:91} ERROR - Failed to execute job 33 for task spider_star
Traceback (most recent call last):
  File "/home/airflow/.local/lib/python3.6/site-packages/airflow/task/task_runner/standard_task_runner.py", line 85, in _start_by_fork
    args.func(args, dag=self.dag)
  File "/home/airflow/.local/lib/python3.6/site-packages/airflow/cli/cli_parser.py", line 48, in command
    return func(*args, **kwargs)
  File "/home/airflow/.local/lib/python3.6/site-packages/airflow/utils/cli.py", line 92, in wrapper
    return f(*args, **kwargs)
  File "/home/airflow/.local/lib/python3.6/site-packages/airflow/cli/commands/task_command.py", line 292, in task_run
    _run_task_by_selected_method(args, dag, ti)
  File "/home/airflow/.local/lib/python3.6/site-packages/airflow/cli/commands/task_command.py", line 107, in _run_task_by_selected_method
    _run_raw_task(args, ti)
  File "/home/airflow/.local/lib/python3.6/site-packages/airflow/cli/commands/task_command.py", line 184, in _run_raw_task
    error_file=args.error_file,
  File "/home/airflow/.local/lib/python3.6/site-packages/airflow/utils/session.py", line 70, in wrapper
    return func(*args, session=session, **kwargs)
  File "/home/airflow/.local/lib/python3.6/site-packages/airflow/models/taskinstance.py", line 1324, in _run_raw_task
    self._execute_task_with_callbacks(context)
  File "/home/airflow/.local/lib/python3.6/site-packages/airflow/models/taskinstance.py", line 1443, in _execute_task_with_callbacks
    result = self._execute_task(context, self.task)
  File "/home/airflow/.local/lib/python3.6/site-packages/airflow/models/taskinstance.py", line 1499, in _execute_task
    result = execute_callable(context=context)
  File "/home/airflow/.local/lib/python3.6/site-packages/airflow/operators/bash.py", line 188, in execute
    f'Bash command failed. The command returned a non-zero exit code {result.exit_code}.'
airflow.exceptions.AirflowException: Bash command failed. The command returned a non-zero exit code 127.
[2021-10-26 18:08:04,439] {local_task_job.py:154} INFO - Task exited with return code 1
[2021-10-26 18:08:04,496] {local_task_job.py:264} INFO - 0 downstream tasks scheduled from follow-on schedule check
[2021-10-26 18:12:29,133] {taskinstance.py:1035} INFO - Dependencies all met for <TaskInstance: scrapper.spider_star manual__2021-10-26T18:07:25.439643+00:00 [queued]>
[2021-10-26 18:12:29,169] {taskinstance.py:1035} INFO - Dependencies all met for <TaskInstance: scrapper.spider_star manual__2021-10-26T18:07:25.439643+00:00 [queued]>
[2021-10-26 18:12:29,170] {taskinstance.py:1241} INFO - 
--------------------------------------------------------------------------------
[2021-10-26 18:12:29,172] {taskinstance.py:1242} INFO - Starting attempt 2 of 2
[2021-10-26 18:12:29,173] {taskinstance.py:1243} INFO - 
--------------------------------------------------------------------------------
[2021-10-26 18:12:29,196] {taskinstance.py:1262} INFO - Executing <Task(BashOperator): spider_star> on 2021-10-26 18:07:25.439643+00:00
[2021-10-26 18:12:29,215] {standard_task_runner.py:76} INFO - Running: ['***', 'tasks', 'run', 'scrapper', 'spider_star', 'manual__2021-10-26T18:07:25.439643+00:00', '--job-id', '34', '--raw', '--subdir', 'DAGS_FOLDER/my_dag.py', '--cfg-path', '/tmp/tmp8lt3npsv', '--error-file', '/tmp/tmpdk5k2cdf']
[2021-10-26 18:12:29,204] {standard_task_runner.py:52} INFO - Started process 15273 to run task
[2021-10-26 18:12:29,219] {standard_task_runner.py:77} INFO - Job 34: Subtask spider_star
[2021-10-26 18:12:29,339] {logging_mixin.py:109} INFO - Running <TaskInstance: scrapper.spider_star manual__2021-10-26T18:07:25.439643+00:00 [running]> on host ebc91b274482
[2021-10-26 18:12:29,450] {taskinstance.py:1414} INFO - Exporting the following env vars:
AIRFLOW_CTX_DAG_EMAIL=octadelsueldo@gmail.com
AIRFLOW_CTX_DAG_OWNER=Octavio
AIRFLOW_CTX_DAG_ID=scrapper
AIRFLOW_CTX_TASK_ID=spider_star
AIRFLOW_CTX_EXECUTION_DATE=2021-10-26T18:07:25.439643+00:00
AIRFLOW_CTX_DAG_RUN_ID=manual__2021-10-26T18:07:25.439643+00:00
[2021-10-26 18:12:29,453] {subprocess.py:62} INFO - Tmp dir root location: 
 /tmp
[2021-10-26 18:12:29,455] {subprocess.py:74} INFO - Running command: ['bash', '-c', '/dags/script/run_spider.sh ']
[2021-10-26 18:12:29,498] {subprocess.py:85} INFO - Output:
[2021-10-26 18:12:29,512] {subprocess.py:89} INFO - bash: /dags/script/run_spider.sh: No such file or directory
[2021-10-26 18:12:29,514] {subprocess.py:93} INFO - Command exited with return code 127
[2021-10-26 18:12:29,521] {taskinstance.py:1686} ERROR - Task failed with exception
Traceback (most recent call last):
  File "/home/airflow/.local/lib/python3.6/site-packages/airflow/models/taskinstance.py", line 1324, in _run_raw_task
    self._execute_task_with_callbacks(context)
  File "/home/airflow/.local/lib/python3.6/site-packages/airflow/models/taskinstance.py", line 1443, in _execute_task_with_callbacks
    result = self._execute_task(context, self.task)
  File "/home/airflow/.local/lib/python3.6/site-packages/airflow/models/taskinstance.py", line 1499, in _execute_task
    result = execute_callable(context=context)
  File "/home/airflow/.local/lib/python3.6/site-packages/airflow/operators/bash.py", line 188, in execute
    f'Bash command failed. The command returned a non-zero exit code {result.exit_code}.'
airflow.exceptions.AirflowException: Bash command failed. The command returned a non-zero exit code 127.
[2021-10-26 18:12:29,563] {taskinstance.py:1280} INFO - Marking task as FAILED. dag_id=scrapper, task_id=spider_star, execution_date=20211026T180725, start_date=20211026T181229, end_date=20211026T181229
[2021-10-26 18:12:29,598] {warnings.py:99} WARNING - /home/***/.local/lib/python3.6/site-packages/***/utils/email.py:102: PendingDeprecationWarning: Fetching SMTP credentials from configuration variables will be deprecated in a future release. Please set credentials using a connection instead.
  send_mime_email(e_from=smtp_mail_from, e_to=recipients, mime_msg=msg, conn_id=conn_id, dryrun=dryrun)

[2021-10-26 18:12:29,601] {configuration.py:381} WARNING - section/key [smtp/smtp_user] not found in config
[2021-10-26 18:12:29,602] {email.py:208} INFO - Email alerting: attempt 1
[2021-10-26 18:12:29,632] {configuration.py:381} WARNING - section/key [smtp/smtp_user] not found in config
[2021-10-26 18:12:29,634] {email.py:208} INFO - Email alerting: attempt 1
[2021-10-26 18:12:29,643] {taskinstance.py:1739} ERROR - Failed to send email to: ['octadelsueldo@gmail.com']
Traceback (most recent call last):
  File "/home/airflow/.local/lib/python3.6/site-packages/airflow/models/taskinstance.py", line 1324, in _run_raw_task
    self._execute_task_with_callbacks(context)
  File "/home/airflow/.local/lib/python3.6/site-packages/airflow/models/taskinstance.py", line 1443, in _execute_task_with_callbacks
    result = self._execute_task(context, self.task)
  File "/home/airflow/.local/lib/python3.6/site-packages/airflow/models/taskinstance.py", line 1499, in _execute_task
    result = execute_callable(context=context)
  File "/home/airflow/.local/lib/python3.6/site-packages/airflow/operators/bash.py", line 188, in execute
    f'Bash command failed. The command returned a non-zero exit code {result.exit_code}.'
airflow.exceptions.AirflowException: Bash command failed. The command returned a non-zero exit code 127.

During handling of the above exception, another exception occurred:

Traceback (most recent call last):
  File "/home/airflow/.local/lib/python3.6/site-packages/airflow/models/taskinstance.py", line 2189, in email_alert
    send_email(self.task.email, subject, html_content)
  File "/home/airflow/.local/lib/python3.6/site-packages/airflow/utils/email.py", line 66, in send_email
    **kwargs,
  File "/home/airflow/.local/lib/python3.6/site-packages/airflow/utils/email.py", line 102, in send_email_smtp
    send_mime_email(e_from=smtp_mail_from, e_to=recipients, mime_msg=msg, conn_id=conn_id, dryrun=dryrun)
  File "/home/airflow/.local/lib/python3.6/site-packages/airflow/utils/email.py", line 210, in send_mime_email
    conn = _get_smtp_connection(smtp_host, smtp_port, smtp_timeout, smtp_ssl)
  File "/home/airflow/.local/lib/python3.6/site-packages/airflow/utils/email.py", line 244, in _get_smtp_connection
    else smtplib.SMTP(host=host, port=port, timeout=timeout)
  File "/usr/local/lib/python3.6/smtplib.py", line 251, in __init__
    (code, msg) = self.connect(host, port)
  File "/usr/local/lib/python3.6/smtplib.py", line 336, in connect
    self.sock = self._get_socket(host, port, self.timeout)
  File "/usr/local/lib/python3.6/smtplib.py", line 307, in _get_socket
    self.source_address)
  File "/usr/local/lib/python3.6/socket.py", line 724, in create_connection
    raise err
  File "/usr/local/lib/python3.6/socket.py", line 713, in create_connection
    sock.connect(sa)
OSError: [Errno 99] Cannot assign requested address

During handling of the above exception, another exception occurred:

Traceback (most recent call last):
  File "/home/airflow/.local/lib/python3.6/site-packages/airflow/models/taskinstance.py", line 1737, in handle_failure
    self.email_alert(error)
  File "/home/airflow/.local/lib/python3.6/site-packages/airflow/models/taskinstance.py", line 2191, in email_alert
    send_email(self.task.email, subject, html_content_err)
  File "/home/airflow/.local/lib/python3.6/site-packages/airflow/utils/email.py", line 66, in send_email
    **kwargs,
  File "/home/airflow/.local/lib/python3.6/site-packages/airflow/utils/email.py", line 102, in send_email_smtp
    send_mime_email(e_from=smtp_mail_from, e_to=recipients, mime_msg=msg, conn_id=conn_id, dryrun=dryrun)
  File "/home/airflow/.local/lib/python3.6/site-packages/airflow/utils/email.py", line 210, in send_mime_email
    conn = _get_smtp_connection(smtp_host, smtp_port, smtp_timeout, smtp_ssl)
  File "/home/airflow/.local/lib/python3.6/site-packages/airflow/utils/email.py", line 244, in _get_smtp_connection
    else smtplib.SMTP(host=host, port=port, timeout=timeout)
  File "/usr/local/lib/python3.6/smtplib.py", line 251, in __init__
    (code, msg) = self.connect(host, port)
  File "/usr/local/lib/python3.6/smtplib.py", line 336, in connect
    self.sock = self._get_socket(host, port, self.timeout)
  File "/usr/local/lib/python3.6/smtplib.py", line 307, in _get_socket
    self.source_address)
  File "/usr/local/lib/python3.6/socket.py", line 724, in create_connection
    raise err
  File "/usr/local/lib/python3.6/socket.py", line 713, in create_connection
    sock.connect(sa)
OSError: [Errno 99] Cannot assign requested address
[2021-10-26 18:12:29,676] {standard_task_runner.py:91} ERROR - Failed to execute job 34 for task spider_star
Traceback (most recent call last):
  File "/home/airflow/.local/lib/python3.6/site-packages/airflow/task/task_runner/standard_task_runner.py", line 85, in _start_by_fork
    args.func(args, dag=self.dag)
  File "/home/airflow/.local/lib/python3.6/site-packages/airflow/cli/cli_parser.py", line 48, in command
    return func(*args, **kwargs)
  File "/home/airflow/.local/lib/python3.6/site-packages/airflow/utils/cli.py", line 92, in wrapper
    return f(*args, **kwargs)
  File "/home/airflow/.local/lib/python3.6/site-packages/airflow/cli/commands/task_command.py", line 292, in task_run
    _run_task_by_selected_method(args, dag, ti)
  File "/home/airflow/.local/lib/python3.6/site-packages/airflow/cli/commands/task_command.py", line 107, in _run_task_by_selected_method
    _run_raw_task(args, ti)
  File "/home/airflow/.local/lib/python3.6/site-packages/airflow/cli/commands/task_command.py", line 184, in _run_raw_task
    error_file=args.error_file,
  File "/home/airflow/.local/lib/python3.6/site-packages/airflow/utils/session.py", line 70, in wrapper
    return func(*args, session=session, **kwargs)
  File "/home/airflow/.local/lib/python3.6/site-packages/airflow/models/taskinstance.py", line 1324, in _run_raw_task
    self._execute_task_with_callbacks(context)
  File "/home/airflow/.local/lib/python3.6/site-packages/airflow/models/taskinstance.py", line 1443, in _execute_task_with_callbacks
    result = self._execute_task(context, self.task)
  File "/home/airflow/.local/lib/python3.6/site-packages/airflow/models/taskinstance.py", line 1499, in _execute_task
    result = execute_callable(context=context)
  File "/home/airflow/.local/lib/python3.6/site-packages/airflow/operators/bash.py", line 188, in execute
    f'Bash command failed. The command returned a non-zero exit code {result.exit_code}.'
airflow.exceptions.AirflowException: Bash command failed. The command returned a non-zero exit code 127.
[2021-10-26 18:12:29,728] {local_task_job.py:154} INFO - Task exited with return code 1
[2021-10-26 18:12:29,816] {local_task_job.py:264} INFO - 0 downstream tasks scheduled from follow-on schedule check
